Workbook

Sheet ELS
B1: !U001,!GA1588,!MOBBEL | F1: 목록외 작성금지 | H1: KIA-실 고객사 확인 수정 | K1: ULSAN, INCHEON 실 반입코드 변경!! | O1: 목록외 작성금지 | P1: 리퍼 ,위험물 위험물리퍼 | V1: 공휴일, 위험물,중량 | Z1: 목록외 작성금지 | AC1: 20 | AF1: KR10 | AH1: 입력X | AJ1: GLAPS 포트 | AL1: 5010001 | BN1: 1 | BV1: GLAPS 코드 | BW1: 직반입 이트란스IF 또는 수기입력 ,ODCY보관은 보관소 또는 I/F | CA1: 공휴일-10 위험물-30
B2: 배차 요청일 | C2: 운송사 | D2: 배차시간 | E2: 구분(오전,오후) | F2: 포장장 | G2: 실출하지 | H2: 고객사 | I2: 선사 | J2: 사이즈 | K2: 반입지 | L2: 국가(도착항) | M2: 비고 | N2: 차량넘버 | O2: 반출지 | P2: 컨테이너 종류 (위험물,리퍼) | Q2: 20 | R2: 40 | S2: 40HC | T2: ContainerNo. | U2: SealNumber1 | V2: 할증 | W2: 편성넘버 | X2: 부킹 | Y2: 반입일 (ODCY/터미널) | Z2: ODCY(세방) 반입터미널 | AA2: ODCY 세부명칭 | AC2: 오더구분 | AD2: 선사코드 | AE2: 선사명 | AF2: 화주사 코드 | AG2: 화주사명 | AH2: 반출지(출발)코드 | AI2: 작업지(하차지)코드 | AJ2: 반입지(도착)코드 | AK2: 운송경로 코드 | AL2: 운송서비스 코드 | AM2: 운송서비스명 | AN2: 배차요청일자 | AO2: 배차요청시간 | AP2: 운송사 코드 | AQ2: 운송사명 | AR2: 부킹번호 | AS2: B/L | AT2: 컨테이너 번호 | AU2: MRN | AV2: POL | AW2: POD | AX2: 최종목적지 | AY2: ETA | AZ2: ETD | BA2: DOC | BB2: CGO | BC2: 실화주사 코드 | BD2: 실화주사명 | BE2: 포워더 코드 | BF2: 포워더명 | BG2: 선사항차 | BH2: 모선코드 | BI2: 반출기한 | BJ2: 모선항차 | BK2: 모선명 | BL2: 선적지 | BM2: 컨테이너 규격 | BN2: 컨테이너 수량 | BO2: 터미널 | BP2: 양하터미널 | BQ2: 반출예약 | BR2: 냉동 여부 | BS2: 위험물 여부 | BT2: FREE TIME | BU2: 공컨반납기한 | BV2: 반출CY | BW2: 반입CY | BX2: ODCY업체코드 | BY2: 선픽업 | BZ2: 컨사이니 | CA2: 할증 1 | CB2: 할증 2 | CC2: 할증 3 | CD2: 할증 4 | CE2: 할증 5 | CF2: 오더등록자명 | CG2: 오더등록자연락처 | CH2: 오더등록업체코드 | CI2: 오더등록자이메일 | CJ2: 통지사항 | CK2: 차량번호 | CL2: 실출하지
B3: =IF(GLAPS자동계산!C2="","",GLAPS자동계산!C2) -> 46177 | C3: =IF(GLAPS자동계산!D2="","",GLAPS자동계산!D2) -> ELS솔루션 | D3: =IF(GLAPS자동계산!E2="","",GLAPS자동계산!E2) -> 08:00 | E3: =IF(GLAPS자동계산!F2="","",GLAPS자동계산!F2) -> 오전 | F3: =IF(GLAPS자동계산!G2="","",GLAPS자동계산!G2) -> 아산 2포장장 | G3: =IF(GLAPS자동계산!H2="","",GLAPS자동계산!H2) -> EAS | H3: =IF(GLAPS자동계산!I2="","",GLAPS자동계산!I2) -> KIN | I3: =IF(GLAPS자동계산!J2="","",GLAPS자동계산!J2) -> WHL | ... AA3: =IF(GLAPS자동계산!AB2="","",GLAPS자동계산!AB2) | AC3: =IF($B3="","",$AC$1) -> 20 | AD3: =IF($B3="","",IFERROR(INDEX(GLAPS정리!$D$2:$D$50,MATCH(I3,GLAPS정리!$A$2:$A$50,0)),IFERROR(INDEX(GLAPS정리!$D$2:$D$50,MATCH(I3,GLAPS정리!$B$2:$B$50,0)),""))) -> WHL | AF3: =IF($B3="","",$AF$1) -> KR10 | AI3: =IF($B3="","",IF(F3="","",VLOOKUP(F3,GLAPS정리!$G$3:$J$114,2,0))) -> H000_GB | AJ3: =IF($B3="","",IF(Z3="울산정일","KRONS",IF(Z3="울산신항","KRUSN",IF(OR(Z3="선광종합물류(인천여객)",Z3="인천여객(인천여객)"),"KRINF",IF(OR(Z3="선광인천보세(인천신)",Z3="한진인천(인천신)",Z3="선광인천신항(인천신)",Z3="인천더로지스(인천신)"),"KRINN",IF(OR(Z3="인천진아(인천항)",Z3="인천E1(인천항)",Z3="인천SM경인터미널(인천항)",Z3="인천항(인천항)",Z3="인천우련(인천항)",Z3="인천항8부두(인천항)"),"KRINC",VLOOKUP(K3,GLAPS정리!$BB$2:$BC$33,2,0))))))) -> KRBNP | AL3: =IF($B3="","",$AL$1) -> 5010001 | AN3: =IF($B3="","",TEXT(B3,"YYYY-MM-DD")) -> 2026-06-04 | AO3: =IF($B3="","",IF(E3="오전", "0800", IF(E3="오후", "1300", IF(E3="잔업", "1800", "")))) -> 0800 | AP3: =IF($B3="","",IF(C3="","",VLOOKUP(C3,GLAPS정리!$AX$2:$AZ$17,3,0))) -> B000005273 | AR3: =IF($B3="","",IF(X3="","",X3)) -> 005GX17204 | AX3: =IF($B3="","",IF(L3="","",VLOOKUP(L3,GLAPS정리!$V$3:$W$180,2,0))) -> INKAT | BM3: =IF($B3="","",IF(AND(Q3=1,OR(P3="",P3="위험물")), "2210", IF(AND(Q3=1,OR(P3="리퍼",P3="위험물리퍼")), "2230", IF(AND(S3=1,OR(P3="",P3="위험물")), "4510", IF(AND(S3=1,OR(P3="리퍼",P3="위험물리퍼")), "4530", IF(AND(R3=1,OR(P3="",P3="위험물")), "4210", IF(AND(R3=1,P3="리퍼"), "4230", " "))))))) -> 4510 | BN3: =IF($B3="","",$BN$1) -> 1 | BR3: =IF($B3="","",IF(OR(P3="리퍼",P3="위험물리퍼"),"Y","")) | BS3: =IF($B3="","",IF(OR(P3="위험물",P3="위험물리퍼"),"Y","")) | BV3: =IF($B3="","",IF(O3="","",VLOOKUP(O3,GLAPS정리!$BH$2:$BI$94,2,0))) | BW3: =IF($B3="","",IF(OR(Z3="동원",Z3="세방",Z3="한타"),"",IFERROR(INDEX(GLAPS정리!$BI$2:$BI$101,MATCH(Z3,GLAPS정리!$BH$2:$BH$101,0)),""))) | BX3: =IF($B3="","",IF(Z3="","",IFERROR(VLOOKUP(Z3,GLAPS정리!$AX$2:$AZ$17,3,0),""))) | BZ3: =IF($B3="","",IF(H3="","",VLOOKUP(H3,GLAPS정리!$L$3:$O$133,2,0))) -> GA0196 | CA3: =IF($B3="","",IF(V3="공휴일", 10, IF(V3="야간", 20, IF(V3="위험물", 30, IF(V3="중량", 40, ""))))) | CL3: =IF($B3="","",IF(AI3="","",VLOOKUP(AI3,GLAPS정리!$BT$3:$BV$26,3,0))) -> EAS
B4: =IF(GLAPS자동계산!C3="","",GLAPS자동계산!C3) -> 46177 | C4: =IF(GLAPS자동계산!D3="","",GLAPS자동계산!D3) -> ELS솔루션 | D4: =IF(GLAPS자동계산!E3="","",GLAPS자동계산!E3) -> 09:00 | E4: =IF(GLAPS자동계산!F3="","",GLAPS자동계산!F3) -> 오전 | F4: =IF(GLAPS자동계산!G3="","",GLAPS자동계산!G3) -> 아산 2포장장 | G4: =IF(GLAPS자동계산!H3="","",GLAPS자동계산!H3) -> EAS | H4: =IF(GLAPS자동계산!I3="","",GLAPS자동계산!I3) -> KIN | I4: =IF(GLAPS자동계산!J3="","",GLAPS자동계산!J3) -> WHL | ... AA4: =IF(GLAPS자동계산!AB3="","",GLAPS자동계산!AB3) | AC4: =IF($B4="","",$AC$1) -> 20 | AD4: =IF($B4="","",IFERROR(INDEX(GLAPS정리!$D$2:$D$50,MATCH(I4,GLAPS정리!$A$2:$A$50,0)),IFERROR(INDEX(GLAPS정리!$D$2:$D$50,MATCH(I4,GLAPS정리!$B$2:$B$50,0)),""))) -> WHL | AF4: =IF($B4="","",$AF$1) -> KR10 | AI4: =IF($B4="","",IF(F4="","",VLOOKUP(F4,GLAPS정리!$G$3:$J$114,2,0))) -> H000_GB | AJ4: =IF($B4="","",IF(Z4="울산정일","KRONS",IF(Z4="울산신항","KRUSN",IF(OR(Z4="선광종합물류(인천여객)",Z4="인천여객(인천여객)"),"KRINF",IF(OR(Z4="선광인천보세(인천신)",Z4="한진인천(인천신)",Z4="선광인천신항(인천신)",Z4="인천더로지스(인천신)"),"KRINN",IF(OR(Z4="인천진아(인천항)",Z4="인천E1(인천항)",Z4="인천SM경인터미널(인천항)",Z4="인천항(인천항)",Z4="인천우련(인천항)",Z4="인천항8부두(인천항)"),"KRINC",VLOOKUP(K4,GLAPS정리!$BB$2:$BC$33,2,0))))))) -> KRBNP | AL4: =IF($B4="","",$AL$1) -> 5010001 | AN4: =IF($B4="","",TEXT(B4,"YYYY-MM-DD")) -> 2026-06-04 | AO4: =IF($B4="","",IF(E4="오전", "0800", IF(E4="오후", "1300", IF(E4="잔업", "1800", "")))) -> 0800 | AP4: =IF($B4="","",IF(C4="","",VLOOKUP(C4,GLAPS정리!$AX$2:$AZ$17,3,0))) -> B000005273 | AR4: =IF($B4="","",IF(X4="","",X4)) -> 005GX17204 | AX4: =IF($B4="","",IF(L4="","",VLOOKUP(L4,GLAPS정리!$V$3:$W$180,2,0))) -> INKAT | BM4: =IF($B4="","",IF(AND(Q4=1,OR(P4="",P4="위험물")), "2210", IF(AND(Q4=1,OR(P4="리퍼",P4="위험물리퍼")), "2230", IF(AND(S4=1,OR(P4="",P4="위험물")), "4510", IF(AND(S4=1,OR(P4="리퍼",P4="위험물리퍼")), "4530", IF(AND(R4=1,OR(P4="",P4="위험물")), "4210", IF(AND(R4=1,P4="리퍼"), "4230", " "))))))) -> 4510 | BN4: =IF($B4="","",$BN$1) -> 1 | BR4: =IF($B4="","",IF(OR(P4="리퍼",P4="위험물리퍼"),"Y","")) | BS4: =IF($B4="","",IF(OR(P4="위험물",P4="위험물리퍼"),"Y","")) | BV4: =IF($B4="","",IF(O4="","",VLOOKUP(O4,GLAPS정리!$BH$2:$BI$94,2,0))) | BW4: =IF($B4="","",IF(OR(Z4="동원",Z4="세방",Z4="한타"),"",IFERROR(INDEX(GLAPS정리!$BI$2:$BI$101,MATCH(Z4,GLAPS정리!$BH$2:$BH$101,0)),""))) | BX4: =IF($B4="","",IF(Z4="","",IFERROR(VLOOKUP(Z4,GLAPS정리!$AX$2:$AZ$17,3,0),""))) | BZ4: =IF($B4="","",IF(H4="","",VLOOKUP(H4,GLAPS정리!$L$3:$O$133,2,0))) -> GA0196 | CA4: =IF($B4="","",IF(V4="공휴일", 10, IF(V4="야간", 20, IF(V4="위험물", 30, IF(V4="중량", 40, ""))))) | CL4: =IF($B4="","",IF(AI4="","",VLOOKUP(AI4,GLAPS정리!$BT$3:$BV$26,3,0))) -> EAS
B5: =IF(GLAPS자동계산!C4="","",GLAPS자동계산!C4) -> 46177 | C5: =IF(GLAPS자동계산!D4="","",GLAPS자동계산!D4) -> ELS솔루션 | D5: =IF(GLAPS자동계산!E4="","",GLAPS자동계산!E4) -> 08:00 | E5: =IF(GLAPS자동계산!F4="","",GLAPS자동계산!F4) -> 오전 | F5: =IF(GLAPS자동계산!G4="","",GLAPS자동계산!G4) -> 아산 1포장장 | G5: =IF(GLAPS자동계산!H4="","",GLAPS자동계산!H4) -> EAS | H5: =IF(GLAPS자동계산!I4="","",GLAPS자동계산!I4) -> KASK | I5: =IF(GLAPS자동계산!J4="","",GLAPS자동계산!J4) -> CMA | ... AA5: =IF(GLAPS자동계산!AB4="","",GLAPS자동계산!AB4) | AC5: =IF($B5="","",$AC$1) -> 20 | AD5: =IF($B5="","",IFERROR(INDEX(GLAPS정리!$D$2:$D$50,MATCH(I5,GLAPS정리!$A$2:$A$50,0)),IFERROR(INDEX(GLAPS정리!$D$2:$D$50,MATCH(I5,GLAPS정리!$B$2:$B$50,0)),""))) -> CMA | AF5: =IF($B5="","",$AF$1) -> KR10 | AI5: =IF($B5="","",IF(F5="","",VLOOKUP(F5,GLAPS정리!$G$3:$J$114,2,0))) -> H000_GA | AJ5: =IF($B5="","",IF(Z5="울산정일","KRONS",IF(Z5="울산신항","KRUSN",IF(OR(Z5="선광종합물류(인천여객)",Z5="인천여객(인천여객)"),"KRINF",IF(OR(Z5="선광인천보세(인천신)",Z5="한진인천(인천신)",Z5="선광인천신항(인천신)",Z5="인천더로지스(인천신)"),"KRINN",IF(OR(Z5="인천진아(인천항)",Z5="인천E1(인천항)",Z5="인천SM경인터미널(인천항)",Z5="인천항(인천항)",Z5="인천우련(인천항)",Z5="인천항8부두(인천항)"),"KRINC",VLOOKUP(K5,GLAPS정리!$BB$2:$BC$33,2,0))))))) -> KRBNP | AL5: =IF($B5="","",$AL$1) -> 5010001 | AN5: =IF($B5="","",TEXT(B5,"YYYY-MM-DD")) -> 2026-06-04 | AO5: =IF($B5="","",IF(E5="오전", "0800", IF(E5="오후", "1300", IF(E5="잔업", "1800", "")))) -> 0800 | AP5: =IF($B5="","",IF(C5="","",VLOOKUP(C5,GLAPS정리!$AX$2:$AZ$17,3,0))) -> B000005273 | AR5: =IF($B5="","",IF(X5="","",X5)) -> CMA2606010011 | AX5: =IF($B5="","",IF(L5="","",VLOOKUP(L5,GLAPS정리!$V$3:$W$180,2,0))) -> SIKOP | BM5: =IF($B5="","",IF(AND(Q5=1,OR(P5="",P5="위험물")), "2210", IF(AND(Q5=1,OR(P5="리퍼",P5="위험물리퍼")), "2230", IF(AND(S5=1,OR(P5="",P5="위험물")), "4510", IF(AND(S5=1,OR(P5="리퍼",P5="위험물리퍼")), "4530", IF(AND(R5=1,OR(P5="",P5="위험물")), "4210", IF(AND(R5=1,P5="리퍼"), "4230", " "))))))) -> 4510 | BN5: =IF($B5="","",$BN$1) -> 1 | BR5: =IF($B5="","",IF(OR(P5="리퍼",P5="위험물리퍼"),"Y","")) | BS5: =IF($B5="","",IF(OR(P5="위험물",P5="위험물리퍼"),"Y","")) | BV5: =IF($B5="","",IF(O5="","",VLOOKUP(O5,GLAPS정리!$BH$2:$BI$94,2,0))) | BW5: =IF($B5="","",IF(OR(Z5="동원",Z5="세방",Z5="한타"),"",IFERROR(INDEX(GLAPS정리!$BI$2:$BI$101,MATCH(Z5,GLAPS정리!$BH$2:$BH$101,0)),""))) | BX5: =IF($B5="","",IF(Z5="","",IFERROR(VLOOKUP(Z5,GLAPS정리!$AX$2:$AZ$17,3,0),""))) | BZ5: =IF($B5="","",IF(H5="","",VLOOKUP(H5,GLAPS정리!$L$3:$O$133,2,0))) -> SK02 | CA5: =IF($B5="","",IF(V5="공휴일", 10, IF(V5="야간", 20, IF(V5="위험물", 30, IF(V5="중량", 40, ""))))) | CL5: =IF($B5="","",IF(AI5="","",VLOOKUP(AI5,GLAPS정리!$BT$3:$BV$26,3,0))) -> EAS
B6: =IF(GLAPS자동계산!C5="","",GLAPS자동계산!C5) -> 46177 | C6: =IF(GLAPS자동계산!D5="","",GLAPS자동계산!D5) -> ELS솔루션 | D6: =IF(GLAPS자동계산!E5="","",GLAPS자동계산!E5) -> 09:00 | E6: =IF(GLAPS자동계산!F5="","",GLAPS자동계산!F5) -> 오전 | F6: =IF(GLAPS자동계산!G5="","",GLAPS자동계산!G5) -> 아산 1포장장 | G6: =IF(GLAPS자동계산!H5="","",GLAPS자동계산!H5) -> EAS | H6: =IF(GLAPS자동계산!I5="","",GLAPS자동계산!I5) -> KASK | I6: =IF(GLAPS자동계산!J5="","",GLAPS자동계산!J5) -> CMA | ... AA6: =IF(GLAPS자동계산!AB5="","",GLAPS자동계산!AB5) | AC6: =IF($B6="","",$AC$1) -> 20 | AD6: =IF($B6="","",IFERROR(INDEX(GLAPS정리!$D$2:$D$50,MATCH(I6,GLAPS정리!$A$2:$A$50,0)),IFERROR(INDEX(GLAPS정리!$D$2:$D$50,MATCH(I6,GLAPS정리!$B$2:$B$50,0)),""))) -> CMA | AF6: =IF($B6="","",$AF$1) -> KR10 | AI6: =IF($B6="","",IF(F6="","",VLOOKUP(F6,GLAPS정리!$G$3:$J$114,2,0))) -> H000_GA | AJ6: =IF($B6="","",IF(Z6="울산정일","KRONS",IF(Z6="울산신항","KRUSN",IF(OR(Z6="선광종합물류(인천여객)",Z6="인천여객(인천여객)"),"KRINF",IF(OR(Z6="선광인천보세(인천신)",Z6="한진인천(인천신)",Z6="선광인천신항(인천신)",Z6="인천더로지스(인천신)"),"KRINN",IF(OR(Z6="인천진아(인천항)",Z6="인천E1(인천항)",Z6="인천SM경인터미널(인천항)",Z6="인천항(인천항)",Z6="인천우련(인천항)",Z6="인천항8부두(인천항)"),"KRINC",VLOOKUP(K6,GLAPS정리!$BB$2:$BC$33,2,0))))))) -> KRBNP | AL6: =IF($B6="","",$AL$1) -> 5010001 | AN6: =IF($B6="","",TEXT(B6,"YYYY-MM-DD")) -> 2026-06-04 | AO6: =IF($B6="","",IF(E6="오전", "0800", IF(E6="오후", "1300", IF(E6="잔업", "1800", "")))) -> 0800 | AP6: =IF($B6="","",IF(C6="","",VLOOKUP(C6,GLAPS정리!$AX$2:$AZ$17,3,0))) -> B000005273 | AR6: =IF($B6="","",IF(X6="","",X6)) -> CMA2606010011 | AX6: =IF($B6="","",IF(L6="","",VLOOKUP(L6,GLAPS정리!$V$3:$W$180,2,0))) -> SIKOP | BM6: =IF($B6="","",IF(AND(Q6=1,OR(P6="",P6="위험물")), "2210", IF(AND(Q6=1,OR(P6="리퍼",P6="위험물리퍼")), "2230", IF(AND(S6=1,OR(P6="",P6="위험물")), "4510", IF(AND(S6=1,OR(P6="리퍼",P6="위험물리퍼")), "4530", IF(AND(R6=1,OR(P6="",P6="위험물")), "4210", IF(AND(R6=1,P6="리퍼"), "4230", " "))))))) -> 4510 | BN6: =IF($B6="","",$BN$1) -> 1 | BR6: =IF($B6="","",IF(OR(P6="리퍼",P6="위험물리퍼"),"Y","")) | BS6: =IF($B6="","",IF(OR(P6="위험물",P6="위험물리퍼"),"Y","")) | BV6: =IF($B6="","",IF(O6="","",VLOOKUP(O6,GLAPS정리!$BH$2:$BI$94,2,0))) | BW6: =IF($B6="","",IF(OR(Z6="동원",Z6="세방",Z6="한타"),"",IFERROR(INDEX(GLAPS정리!$BI$2:$BI$101,MATCH(Z6,GLAPS정리!$BH$2:$BH$101,0)),""))) | BX6: =IF($B6="","",IF(Z6="","",IFERROR(VLOOKUP(Z6,GLAPS정리!$AX$2:$AZ$17,3,0),""))) | BZ6: =IF($B6="","",IF(H6="","",VLOOKUP(H6,GLAPS정리!$L$3:$O$133,2,0))) -> SK02 | CA6: =IF($B6="","",IF(V6="공휴일", 10, IF(V6="야간", 20, IF(V6="위험물", 30, IF(V6="중량", 40, ""))))) | CL6: =IF($B6="","",IF(AI6="","",VLOOKUP(AI6,GLAPS정리!$BT$3:$BV$26,3,0))) -> EAS
B7: =IF(GLAPS자동계산!C6="","",GLAPS자동계산!C6) -> 46177 | C7: =IF(GLAPS자동계산!D6="","",GLAPS자동계산!D6) -> ELS솔루션 | D7: =IF(GLAPS자동계산!E6="","",GLAPS자동계산!E6) -> 08:00 | E7: =IF(GLAPS자동계산!F6="","",GLAPS자동계산!F6) -> 오전 | F7: =IF(GLAPS자동계산!G6="","",GLAPS자동계산!G6) -> 아산 1포장장 | G7: =IF(GLAPS자동계산!H6="","",GLAPS자동계산!H6) -> EAS | H7: =IF(GLAPS자동계산!I6="","",GLAPS자동계산!I6) -> HMMC | I7: =IF(GLAPS자동계산!J6="","",GLAPS자동계산!J6) -> CMA | ... AA7: =IF(GLAPS자동계산!AB6="","",GLAPS자동계산!AB6) | AC7: =IF($B7="","",$AC$1) -> 20 | AD7: =IF($B7="","",IFERROR(INDEX(GLAPS정리!$D$2:$D$50,MATCH(I7,GLAPS정리!$A$2:$A$50,0)),IFERROR(INDEX(GLAPS정리!$D$2:$D$50,MATCH(I7,GLAPS정리!$B$2:$B$50,0)),""))) -> CMA | AF7: =IF($B7="","",$AF$1) -> KR10 | AI7: =IF($B7="","",IF(F7="","",VLOOKUP(F7,GLAPS정리!$G$3:$J$114,2,0))) -> H000_GA | AJ7: =IF($B7="","",IF(Z7="울산정일","KRONS",IF(Z7="울산신항","KRUSN",IF(OR(Z7="선광종합물류(인천여객)",Z7="인천여객(인천여객)"),"KRINF",IF(OR(Z7="선광인천보세(인천신)",Z7="한진인천(인천신)",Z7="선광인천신항(인천신)",Z7="인천더로지스(인천신)"),"KRINN",IF(OR(Z7="인천진아(인천항)",Z7="인천E1(인천항)",Z7="인천SM경인터미널(인천항)",Z7="인천항(인천항)",Z7="인천우련(인천항)",Z7="인천항8부두(인천항)"),"KRINC",VLOOKUP(K7,GLAPS정리!$BB$2:$BC$33,2,0))))))) -> KRBNP | AL7: =IF($B7="","",$AL$1) -> 5010001 | AN7: =IF($B7="","",TEXT(B7,"YYYY-MM-DD")) -> 2026-06-04 | AO7: =IF($B7="","",IF(E7="오전", "0800", IF(E7="오후", "1300", IF(E7="잔업", "1800", "")))) -> 0800 | AP7: =IF($B7="","",IF(C7="","",VLOOKUP(C7,GLAPS정리!$AX$2:$AZ$17,3,0))) -> B000005273 | AR7: =IF($B7="","",IF(X7="","",X7)) -> CMA2606010011 | AX7: =IF($B7="","",IF(L7="","",VLOOKUP(L7,GLAPS정리!$V$3:$W$180,2,0))) -> SIKOP | BM7: =IF($B7="","",IF(AND(Q7=1,OR(P7="",P7="위험물")), "2210", IF(AND(Q7=1,OR(P7="리퍼",P7="위험물리퍼")), "2230", IF(AND(S7=1,OR(P7="",P7="위험물")), "4510", IF(AND(S7=1,OR(P7="리퍼",P7="위험물리퍼")), "4530", IF(AND(R7=1,OR(P7="",P7="위험물")), "4210", IF(AND(R7=1,P7="리퍼"), "4230", " "))))))) -> 4510 | BN7: =IF($B7="","",$BN$1) -> 1 | BR7: =IF($B7="","",IF(OR(P7="리퍼",P7="위험물리퍼"),"Y","")) | BS7: =IF($B7="","",IF(OR(P7="위험물",P7="위험물리퍼"),"Y","")) | BV7: =IF($B7="","",IF(O7="","",VLOOKUP(O7,GLAPS정리!$BH$2:$BI$94,2,0))) | BW7: =IF($B7="","",IF(OR(Z7="동원",Z7="세방",Z7="한타"),"",IFERROR(INDEX(GLAPS정리!$BI$2:$BI$101,MATCH(Z7,GLAPS정리!$BH$2:$BH$101,0)),""))) | BX7: =IF($B7="","",IF(Z7="","",IFERROR(VLOOKUP(Z7,GLAPS정리!$AX$2:$AZ$17,3,0),""))) | BZ7: =IF($B7="","",IF(H7="","",VLOOKUP(H7,GLAPS정리!$L$3:$O$133,2,0))) -> HMMC | CA7: =IF($B7="","",IF(V7="공휴일", 10, IF(V7="야간", 20, IF(V7="위험물", 30, IF(V7="중량", 40, ""))))) | CL7: =IF($B7="","",IF(AI7="","",VLOOKUP(AI7,GLAPS정리!$BT$3:$BV$26,3,0))) -> EAS
B8: =IF(GLAPS자동계산!C7="","",GLAPS자동계산!C7) -> 46177 | C8: =IF(GLAPS자동계산!D7="","",GLAPS자동계산!D7) -> ELS솔루션 | D8: =IF(GLAPS자동계산!E7="","",GLAPS자동계산!E7) -> 09:00 | E8: =IF(GLAPS자동계산!F7="","",GLAPS자동계산!F7) -> 오전 | F8: =IF(GLAPS자동계산!G7="","",GLAPS자동계산!G7) -> 아산 1포장장 | G8: =IF(GLAPS자동계산!H7="","",GLAPS자동계산!H7) -> EAS | H8: =IF(GLAPS자동계산!I7="","",GLAPS자동계산!I7) -> HMMC | I8: =IF(GLAPS자동계산!J7="","",GLAPS자동계산!J7) -> CMA | ... AA8: =IF(GLAPS자동계산!AB7="","",GLAPS자동계산!AB7) | AC8: =IF($B8="","",$AC$1) -> 20 | AD8: =IF($B8="","",IFERROR(INDEX(GLAPS정리!$D$2:$D$50,MATCH(I8,GLAPS정리!$A$2:$A$50,0)),IFERROR(INDEX(GLAPS정리!$D$2:$D$50,MATCH(I8,GLAPS정리!$B$2:$B$50,0)),""))) -> CMA | AF8: =IF($B8="","",$AF$1) -> KR10 | AI8: =IF($B8="","",IF(F8="","",VLOOKUP(F8,GLAPS정리!$G$3:$J$114,2,0))) -> H000_GA | AJ8: =IF($B8="","",IF(Z8="울산정일","KRONS",IF(Z8="울산신항","KRUSN",IF(OR(Z8="선광종합물류(인천여객)",Z8="인천여객(인천여객)"),"KRINF",IF(OR(Z8="선광인천보세(인천신)",Z8="한진인천(인천신)",Z8="선광인천신항(인천신)",Z8="인천더로지스(인천신)"),"KRINN",IF(OR(Z8="인천진아(인천항)",Z8="인천E1(인천항)",Z8="인천SM경인터미널(인천항)",Z8="인천항(인천항)",Z8="인천우련(인천항)",Z8="인천항8부두(인천항)"),"KRINC",VLOOKUP(K8,GLAPS정리!$BB$2:$BC$33,2,0))))))) -> KRBNP | AL8: =IF($B8="","",$AL$1) -> 5010001 | AN8: =IF($B8="","",TEXT(B8,"YYYY-MM-DD")) -> 2026-06-04 | AO8: =IF($B8="","",IF(E8="오전", "0800", IF(E8="오후", "1300", IF(E8="잔업", "1800", "")))) -> 0800 | AP8: =IF($B8="","",IF(C8="","",VLOOKUP(C8,GLAPS정리!$AX$2:$AZ$17,3,0))) -> B000005273 | AR8: =IF($B8="","",IF(X8="","",X8)) -> CMA2606010011 | AX8: =IF($B8="","",IF(L8="","",VLOOKUP(L8,GLAPS정리!$V$3:$W$180,2,0))) -> SIKOP | BM8: =IF($B8="","",IF(AND(Q8=1,OR(P8="",P8="위험물")), "2210", IF(AND(Q8=1,OR(P8="리퍼",P8="위험물리퍼")), "2230", IF(AND(S8=1,OR(P8="",P8="위험물")), "4510", IF(AND(S8=1,OR(P8="리퍼",P8="위험물리퍼")), "4530", IF(AND(R8=1,OR(P8="",P8="위험물")), "4210", IF(AND(R8=1,P8="리퍼"), "4230", " "))))))) -> 4510 | BN8: =IF($B8="","",$BN$1) -> 1 | BR8: =IF($B8="","",IF(OR(P8="리퍼",P8="위험물리퍼"),"Y","")) | BS8: =IF($B8="","",IF(OR(P8="위험물",P8="위험물리퍼"),"Y","")) | BV8: =IF($B8="","",IF(O8="","",VLOOKUP(O8,GLAPS정리!$BH$2:$BI$94,2,0))) | BW8: =IF($B8="","",IF(OR(Z8="동원",Z8="세방",Z8="한타"),"",IFERROR(INDEX(GLAPS정리!$BI$2:$BI$101,MATCH(Z8,GLAPS정리!$BH$2:$BH$101,0)),""))) | BX8: =IF($B8="","",IF(Z8="","",IFERROR(VLOOKUP(Z8,GLAPS정리!$AX$2:$AZ$17,3,0),""))) | BZ8: =IF($B8="","",IF(H8="","",VLOOKUP(H8,GLAPS정리!$L$3:$O$133,2,0))) -> HMMC | CA8: =IF($B8="","",IF(V8="공휴일", 10, IF(V8="야간", 20, IF(V8="위험물", 30, IF(V8="중량", 40, ""))))) | CL8: =IF($B8="","",IF(AI8="","",VLOOKUP(AI8,GLAPS정리!$BT$3:$BV$26,3,0))) -> EAS
B9: =IF(GLAPS자동계산!C8="","",GLAPS자동계산!C8) -> 46177 | C9: =IF(GLAPS자동계산!D8="","",GLAPS자동계산!D8) -> ELS솔루션 | D9: =IF(GLAPS자동계산!E8="","",GLAPS자동계산!E8) -> 10:30 | E9: =IF(GLAPS자동계산!F8="","",GLAPS자동계산!F8) -> 오전 | F9: =IF(GLAPS자동계산!G8="","",GLAPS자동계산!G8) -> 아산 1포장장 | G9: =IF(GLAPS자동계산!H8="","",GLAPS자동계산!H8) -> EAS | H9: =IF(GLAPS자동계산!I8="","",GLAPS자동계산!I8) -> HMMC | I9: =IF(GLAPS자동계산!J8="","",GLAPS자동계산!J8) -> CMA | ... AA9: =IF(GLAPS자동계산!AB8="","",GLAPS자동계산!AB8) | AC9: =IF($B9="","",$AC$1) -> 20 | AD9: =IF($B9="","",IFERROR(INDEX(GLAPS정리!$D$2:$D$50,MATCH(I9,GLAPS정리!$A$2:$A$50,0)),IFERROR(INDEX(GLAPS정리!$D$2:$D$50,MATCH(I9,GLAPS정리!$B$2:$B$50,0)),""))) -> CMA | AF9: =IF($B9="","",$AF$1) -> KR10 | AI9: =IF($B9="","",IF(F9="","",VLOOKUP(F9,GLAPS정리!$G$3:$J$114,2,0))) -> H000_GA | AJ9: =IF($B9="","",IF(Z9="울산정일","KRONS",IF(Z9="울산신항","KRUSN",IF(OR(Z9="선광종합물류(인천여객)",Z9="인천여객(인천여객)"),"KRINF",IF(OR(Z9="선광인천보세(인천신)",Z9="한진인천(인천신)",Z9="선광인천신항(인천신)",Z9="인천더로지스(인천신)"),"KRINN",IF(OR(Z9="인천진아(인천항)",Z9="인천E1(인천항)",Z9="인천SM경인터미널(인천항)",Z9="인천항(인천항)",Z9="인천우련(인천항)",Z9="인천항8부두(인천항)"),"KRINC",VLOOKUP(K9,GLAPS정리!$BB$2:$BC$33,2,0))))))) -> KRBNP | AL9: =IF($B9="","",$AL$1) -> 5010001 | AN9: =IF($B9="","",TEXT(B9,"YYYY-MM-DD")) -> 2026-06-04 | AO9: =IF($B9="","",IF(E9="오전", "0800", IF(E9="오후", "1300", IF(E9="잔업", "1800", "")))) -> 0800 | AP9: =IF($B9="","",IF(C9="","",VLOOKUP(C9,GLAPS정리!$AX$2:$AZ$17,3,0))) -> B000005273 | AR9: =IF($B9="","",IF(X9="","",X9)) -> CMA2606010011 | AX9: =IF($B9="","",IF(L9="","",VLOOKUP(L9,GLAPS정리!$V$3:$W$180,2,0))) -> SIKOP | BM9: =IF($B9="","",IF(AND(Q9=1,OR(P9="",P9="위험물")), "2210", IF(AND(Q9=1,OR(P9="리퍼",P9="위험물리퍼")), "2230", IF(AND(S9=1,OR(P9="",P9="위험물")), "4510", IF(AND(S9=1,OR(P9="리퍼",P9="위험물리퍼")), "4530", IF(AND(R9=1,OR(P9="",P9="위험물")), "4210", IF(AND(R9=1,P9="리퍼"), "4230", " "))))))) -> 4510 | BN9: =IF($B9="","",$BN$1) -> 1 | BR9: =IF($B9="","",IF(OR(P9="리퍼",P9="위험물리퍼"),"Y","")) | BS9: =IF($B9="","",IF(OR(P9="위험물",P9="위험물리퍼"),"Y","")) | BV9: =IF($B9="","",IF(O9="","",VLOOKUP(O9,GLAPS정리!$BH$2:$BI$94,2,0))) | BW9: =IF($B9="","",IF(OR(Z9="동원",Z9="세방",Z9="한타"),"",IFERROR(INDEX(GLAPS정리!$BI$2:$BI$101,MATCH(Z9,GLAPS정리!$BH$2:$BH$101,0)),""))) | BX9: =IF($B9="","",IF(Z9="","",IFERROR(VLOOKUP(Z9,GLAPS정리!$AX$2:$AZ$17,3,0),""))) | BZ9: =IF($B9="","",IF(H9="","",VLOOKUP(H9,GLAPS정리!$L$3:$O$133,2,0))) -> HMMC | CA9: =IF($B9="","",IF(V9="공휴일", 10, IF(V9="야간", 20, IF(V9="위험물", 30, IF(V9="중량", 40, ""))))) | CL9: =IF($B9="","",IF(AI9="","",VLOOKUP(AI9,GLAPS정리!$BT$3:$BV$26,3,0))) -> EAS
B10: =IF(GLAPS자동계산!C9="","",GLAPS자동계산!C9) -> 46177 | C10: =IF(GLAPS자동계산!D9="","",GLAPS자동계산!D9) -> ELS솔루션 | D10: =IF(GLAPS자동계산!E9="","",GLAPS자동계산!E9) -> 09:00 | E10: =IF(GLAPS자동계산!F9="","",GLAPS자동계산!F9) -> 오전 | F10: =IF(GLAPS자동계산!G9="","",GLAPS자동계산!G9) -> 아산 3포장장 | G10: =IF(GLAPS자동계산!H9="","",GLAPS자동계산!H9) -> EAS1 | H10: =IF(GLAPS자동계산!I9="","",GLAPS자동계산!I9) -> HMMA | I10: =IF(GLAPS자동계산!J9="","",GLAPS자동계산!J9) -> ONE | ... AA10: =IF(GLAPS자동계산!AB9="","",GLAPS자동계산!AB9) | AC10: =IF($B10="","",$AC$1) -> 20 | AD10: =IF($B10="","",IFERROR(INDEX(GLAPS정리!$D$2:$D$50,MATCH(I10,GLAPS정리!$A$2:$A$50,0)),IFERROR(INDEX(GLAPS정리!$D$2:$D$50,MATCH(I10,GLAPS정리!$B$2:$B$50,0)),""))) -> ONE | AF10: =IF($B10="","",$AF$1) -> KR10 | AI10: =IF($B10="","",IF(F10="","",VLOOKUP(F10,GLAPS정리!$G$3:$J$114,2,0))) -> H000_GC | AJ10: =IF($B10="","",IF(Z10="울산정일","KRONS",IF(Z10="울산신항","KRUSN",IF(OR(Z10="선광종합물류(인천여객)",Z10="인천여객(인천여객)"),"KRINF",IF(OR(Z10="선광인천보세(인천신)",Z10="한진인천(인천신)",Z10="선광인천신항(인천신)",Z10="인천더로지스(인천신)"),"KRINN",IF(OR(Z10="인천진아(인천항)",Z10="인천E1(인천항)",Z10="인천SM경인터미널(인천항)",Z10="인천항(인천항)",Z10="인천우련(인천항)",Z10="인천항8부두(인천항)"),"KRINC",VLOOKUP(K10,GLAPS정리!$BB$2:$BC$33,2,0))))))) -> KRBNP | AL10: =IF($B10="","",$AL$1) -> 5010001 | AN10: =IF($B10="","",TEXT(B10,"YYYY-MM-DD")) -> 2026-06-04 | AO10: =IF($B10="","",IF(E10="오전", "0800", IF(E10="오후", "1300", IF(E10="잔업", "1800", "")))) -> 0800 | AP10: =IF($B10="","",IF(C10="","",VLOOKUP(C10,GLAPS정리!$AX$2:$AZ$17,3,0))) -> B000005273 | AR10: =IF($B10="","",IF(X10="","",X10)) -> SELG82813400 | AX10: =IF($B10="","",IF(L10="","",VLOOKUP(L10,GLAPS정리!$V$3:$W$180,2,0))) -> USLAX | BM10: =IF($B10="","",IF(AND(Q10=1,OR(P10="",P10="위험물")), "2210", IF(AND(Q10=1,OR(P10="리퍼",P10="위험물리퍼")), "2230", IF(AND(S10=1,OR(P10="",P10="위험물")), "4510", IF(AND(S10=1,OR(P10="리퍼",P10="위험물리퍼")), "4530", IF(AND(R10=1,OR(P10="",P10="위험물")), "4210", IF(AND(R10=1,P10="리퍼"), "4230", " "))))))) -> 4510 | BN10: =IF($B10="","",$BN$1) -> 1 | BR10: =IF($B10="","",IF(OR(P10="리퍼",P10="위험물리퍼"),"Y","")) | BS10: =IF($B10="","",IF(OR(P10="위험물",P10="위험물리퍼"),"Y","")) | BV10: =IF($B10="","",IF(O10="","",VLOOKUP(O10,GLAPS정리!$BH$2:$BI$94,2,0))) | BW10: =IF($B10="","",IF(OR(Z10="동원",Z10="세방",Z10="한타"),"",IFERROR(INDEX(GLAPS정리!$BI$2:$BI$101,MATCH(Z10,GLAPS정리!$BH$2:$BH$101,0)),""))) | BX10: =IF($B10="","",IF(Z10="","",IFERROR(VLOOKUP(Z10,GLAPS정리!$AX$2:$AZ$17,3,0),""))) | BZ10: =IF($B10="","",IF(H10="","",VLOOKUP(H10,GLAPS정리!$L$3:$O$133,2,0))) -> UH03 | CA10: =IF($B10="","",IF(V10="공휴일", 10, IF(V10="야간", 20, IF(V10="위험물", 30, IF(V10="중량", 40, ""))))) | CL10: =IF($B10="","",IF(AI10="","",VLOOKUP(AI10,GLAPS정리!$BT$3:$BV$26,3,0))) -> EAS1
B11: =IF(GLAPS자동계산!C10="","",GLAPS자동계산!C10) -> 46177 | C11: =IF(GLAPS자동계산!D10="","",GLAPS자동계산!D10) -> ELS솔루션 | D11: =IF(GLAPS자동계산!E10="","",GLAPS자동계산!E10) -> 14:30 | E11: =IF(GLAPS자동계산!F10="","",GLAPS자동계산!F10) -> 오후 | F11: =IF(GLAPS자동계산!G10="","",GLAPS자동계산!G10) -> KCC 글라스 | G11: =IF(GLAPS자동계산!H10="","",GLAPS자동계산!H10) -> KAC | H11: =IF(GLAPS자동계산!I10="","",GLAPS자동계산!I10) -> HMGMA | I11: =IF(GLAPS자동계산!J10="","",GLAPS자동계산!J10) -> CMA | ... AA11: =IF(GLAPS자동계산!AB10="","",GLAPS자동계산!AB10) | AC11: =IF($B11="","",$AC$1) -> 20 | AD11: =IF($B11="","",IFERROR(INDEX(GLAPS정리!$D$2:$D$50,MATCH(I11,GLAPS정리!$A$2:$A$50,0)),IFERROR(INDEX(GLAPS정리!$D$2:$D$50,MATCH(I11,GLAPS정리!$B$2:$B$50,0)),""))) -> CMA | AF11: =IF($B11="","",$AF$1) -> KR10 | AI11: =IF($B11="","",IF(F11="","",VLOOKUP(F11,GLAPS정리!$G$3:$J$114,2,0))) -> H000_KC | AJ11: =IF($B11="","",IF(Z11="울산정일","KRONS",IF(Z11="울산신항","KRUSN",IF(OR(Z11="선광종합물류(인천여객)",Z11="인천여객(인천여객)"),"KRINF",IF(OR(Z11="선광인천보세(인천신)",Z11="한진인천(인천신)",Z11="선광인천신항(인천신)",Z11="인천더로지스(인천신)"),"KRINN",IF(OR(Z11="인천진아(인천항)",Z11="인천E1(인천항)",Z11="인천SM경인터미널(인천항)",Z11="인천항(인천항)",Z11="인천우련(인천항)",Z11="인천항8부두(인천항)"),"KRINC",VLOOKUP(K11,GLAPS정리!$BB$2:$BC$33,2,0))))))) -> KRBNP | AL11: =IF($B11="","",$AL$1) -> 5010001 | AN11: =IF($B11="","",TEXT(B11,"YYYY-MM-DD")) -> 2026-06-04 | AO11: =IF($B11="","",IF(E11="오전", "0800", IF(E11="오후", "1300", IF(E11="잔업", "1800", "")))) -> 1300 | AP11: =IF($B11="","",IF(C11="","",VLOOKUP(C11,GLAPS정리!$AX$2:$AZ$17,3,0))) -> B000005273 | AR11: =IF($B11="","",IF(X11="","",X11)) -> CMA2605290012 | AX11: =IF($B11="","",IF(L11="","",VLOOKUP(L11,GLAPS정리!$V$3:$W$180,2,0))) -> USSAV | BM11: =IF($B11="","",IF(AND(Q11=1,OR(P11="",P11="위험물")), "2210", IF(AND(Q11=1,OR(P11="리퍼",P11="위험물리퍼")), "2230", IF(AND(S11=1,OR(P11="",P11="위험물")), "4510", IF(AND(S11=1,OR(P11="리퍼",P11="위험물리퍼")), "4530", IF(AND(R11=1,OR(P11="",P11="위험물")), "4210", IF(AND(R11=1,P11="리퍼"), "4230", " "))))))) -> 4510 | BN11: =IF($B11="","",$BN$1) -> 1 | BR11: =IF($B11="","",IF(OR(P11="리퍼",P11="위험물리퍼"),"Y","")) | BS11: =IF($B11="","",IF(OR(P11="위험물",P11="위험물리퍼"),"Y","")) | BV11: =IF($B11="","",IF(O11="","",VLOOKUP(O11,GLAPS정리!$BH$2:$BI$94,2,0))) | BW11: =IF($B11="","",IF(OR(Z11="동원",Z11="세방",Z11="한타"),"",IFERROR(INDEX(GLAPS정리!$BI$2:$BI$101,MATCH(Z11,GLAPS정리!$BH$2:$BH$101,0)),""))) | BX11: =IF($B11="","",IF(Z11="","",IFERROR(VLOOKUP(Z11,GLAPS정리!$AX$2:$AZ$17,3,0),""))) | BZ11: =IF($B11="","",IF(H11="","",VLOOKUP(H11,GLAPS정리!$L$3:$O$133,2,0))) -> GA2982 | CA11: =IF($B11="","",IF(V11="공휴일", 10, IF(V11="야간", 20, IF(V11="위험물", 30, IF(V11="중량", 40, ""))))) | CL11: =IF($B11="","",IF(AI11="","",VLOOKUP(AI11,GLAPS정리!$BT$3:$BV$26,3,0))) -> KAC
B12: =IF(GLAPS자동계산!C11="","",GLAPS자동계산!C11) | C12: =IF(GLAPS자동계산!D11="","",GLAPS자동계산!D11) | D12: =IF(GLAPS자동계산!E11="","",GLAPS자동계산!E11) | E12: =IF(GLAPS자동계산!F11="","",GLAPS자동계산!F11) | F12: =IF(GLAPS자동계산!G11="","",GLAPS자동계산!G11) | G12: =IF(GLAPS자동계산!H11="","",GLAPS자동계산!H11) | H12: =IF(GLAPS자동계산!I11="","",GLAPS자동계산!I11) | I12: =IF(GLAPS자동계산!J11="","",GLAPS자동계산!J11) | ... AA12: =IF(GLAPS자동계산!AB11="","",GLAPS자동계산!AB11) | AC12: =IF($B12="","",$AC$1) | AD12: =IF($B12="","",IFERROR(INDEX(GLAPS정리!$D$2:$D$50,MATCH(I12,GLAPS정리!$A$2:$A$50,0)),IFERROR(INDEX(GLAPS정리!$D$2:$D$50,MATCH(I12,GLAPS정리!$B$2:$B$50,0)),""))) | AF12: =IF($B12="","",$AF$1) | AI12: =IF($B12="","",IF(F12="","",VLOOKUP(F12,GLAPS정리!$G$3:$J$114,2,0))) | AJ12: =IF($B12="","",IF(Z12="울산정일","KRONS",IF(Z12="울산신항","KRUSN",IF(OR(Z12="선광종합물류(인천여객)",Z12="인천여객(인천여객)"),"KRINF",IF(OR(Z12="선광인천보세(인천신)",Z12="한진인천(인천신)",Z12="선광인천신항(인천신)",Z12="인천더로지스(인천신)"),"KRINN",IF(OR(Z12="인천진아(인천항)",Z12="인천E1(인천항)",Z12="인천SM경인터미널(인천항)",Z12="인천항(인천항)",Z12="인천우련(인천항)",Z12="인천항8부두(인천항)"),"KRINC",VLOOKUP(K12,GLAPS정리!$BB$2:$BC$33,2,0))))))) | AL12: =IF($B12="","",$AL$1) | AN12: =IF($B12="","",TEXT(B12,"YYYY-MM-DD")) | AO12: =IF($B12="","",IF(E12="오전", "0800", IF(E12="오후", "1300", IF(E12="잔업", "1800", "")))) | AP12: =IF($B12="","",IF(C12="","",VLOOKUP(C12,GLAPS정리!$AX$2:$AZ$17,3,0))) | AR12: =IF($B12="","",IF(X12="","",X12)) | AX12: =IF($B12="","",IF(L12="","",VLOOKUP(L12,GLAPS정리!$V$3:$W$180,2,0))) | BM12: =IF($B12="","",IF(AND(Q12=1,OR(P12="",P12="위험물")), "2210", IF(AND(Q12=1,OR(P12="리퍼",P12="위험물리퍼")), "2230", IF(AND(S12=1,OR(P12="",P12="위험물")), "4510", IF(AND(S12=1,OR(P12="리퍼",P12="위험물리퍼")), "4530", IF(AND(R12=1,OR(P12="",P12="위험물")), "4210", IF(AND(R12=1,P12="리퍼"), "4230", " "))))))) | BN12: =IF($B12="","",$BN$1) | BR12: =IF($B12="","",IF(OR(P12="리퍼",P12="위험물리퍼"),"Y","")) | BS12: =IF($B12="","",IF(OR(P12="위험물",P12="위험물리퍼"),"Y","")) | BV12: =IF($B12="","",IF(O12="","",VLOOKUP(O12,GLAPS정리!$BH$2:$BI$94,2,0))) | BW12: =IF($B12="","",IF(OR(Z12="동원",Z12="세방",Z12="한타"),"",IFERROR(INDEX(GLAPS정리!$BI$2:$BI$101,MATCH(Z12,GLAPS정리!$BH$2:$BH$101,0)),""))) | BX12: =IF($B12="","",IF(Z12="","",IFERROR(VLOOKUP(Z12,GLAPS정리!$AX$2:$AZ$17,3,0),""))) | BZ12: =IF($B12="","",IF(H12="","",VLOOKUP(H12,GLAPS정리!$L$3:$O$133,2,0))) | CA12: =IF($B12="","",IF(V12="공휴일", 10, IF(V12="야간", 20, IF(V12="위험물", 30, IF(V12="중량", 40, ""))))) | CL12: =IF($B12="","",IF(AI12="","",VLOOKUP(AI12,GLAPS정리!$BT$3:$BV$26,3,0)))
B13: =IF(GLAPS자동계산!C12="","",GLAPS자동계산!C12) | C13: =IF(GLAPS자동계산!D12="","",GLAPS자동계산!D12) | D13: =IF(GLAPS자동계산!E12="","",GLAPS자동계산!E12) | E13: =IF(GLAPS자동계산!F12="","",GLAPS자동계산!F12) | F13: =IF(GLAPS자동계산!G12="","",GLAPS자동계산!G12) | G13: =IF(GLAPS자동계산!H12="","",GLAPS자동계산!H12) | H13: =IF(GLAPS자동계산!I12="","",GLAPS자동계산!I12) | I13: =IF(GLAPS자동계산!J12="","",GLAPS자동계산!J12) | ... AA13: =IF(GLAPS자동계산!AB12="","",GLAPS자동계산!AB12) | AC13: =IF($B13="","",$AC$1) | AD13: =IF($B13="","",IFERROR(INDEX(GLAPS정리!$D$2:$D$50,MATCH(I13,GLAPS정리!$A$2:$A$50,0)),IFERROR(INDEX(GLAPS정리!$D$2:$D$50,MATCH(I13,GLAPS정리!$B$2:$B$50,0)),""))) | AF13: =IF($B13="","",$AF$1) | AI13: =IF($B13="","",IF(F13="","",VLOOKUP(F13,GLAPS정리!$G$3:$J$114,2,0))) | AJ13: =IF($B13="","",IF(Z13="울산정일","KRONS",IF(Z13="울산신항","KRUSN",IF(OR(Z13="선광종합물류(인천여객)",Z13="인천여객(인천여객)"),"KRINF",IF(OR(Z13="선광인천보세(인천신)",Z13="한진인천(인천신)",Z13="선광인천신항(인천신)",Z13="인천더로지스(인천신)"),"KRINN",IF(OR(Z13="인천진아(인천항)",Z13="인천E1(인천항)",Z13="인천SM경인터미널(인천항)",Z13="인천항(인천항)",Z13="인천우련(인천항)",Z13="인천항8부두(인천항)"),"KRINC",VLOOKUP(K13,GLAPS정리!$BB$2:$BC$33,2,0))))))) | AL13: =IF($B13="","",$AL$1) | AN13: =IF($B13="","",TEXT(B13,"YYYY-MM-DD")) | AO13: =IF($B13="","",IF(E13="오전", "0800", IF(E13="오후", "1300", IF(E13="잔업", "1800", "")))) | AP13: =IF($B13="","",IF(C13="","",VLOOKUP(C13,GLAPS정리!$AX$2:$AZ$17,3,0))) | AR13: =IF($B13="","",IF(X13="","",X13)) | AX13: =IF($B13="","",IF(L13="","",VLOOKUP(L13,GLAPS정리!$V$3:$W$180,2,0))) | BM13: =IF($B13="","",IF(AND(Q13=1,OR(P13="",P13="위험물")), "2210", IF(AND(Q13=1,OR(P13="리퍼",P13="위험물리퍼")), "2230", IF(AND(S13=1,OR(P13="",P13="위험물")), "4510", IF(AND(S13=1,OR(P13="리퍼",P13="위험물리퍼")), "4530", IF(AND(R13=1,OR(P13="",P13="위험물")), "4210", IF(AND(R13=1,P13="리퍼"), "4230", " "))))))) | BN13: =IF($B13="","",$BN$1) | BR13: =IF($B13="","",IF(OR(P13="리퍼",P13="위험물리퍼"),"Y","")) | BS13: =IF($B13="","",IF(OR(P13="위험물",P13="위험물리퍼"),"Y","")) | BV13: =IF($B13="","",IF(O13="","",VLOOKUP(O13,GLAPS정리!$BH$2:$BI$94,2,0))) | BW13: =IF($B13="","",IF(OR(Z13="동원",Z13="세방",Z13="한타"),"",IFERROR(INDEX(GLAPS정리!$BI$2:$BI$101,MATCH(Z13,GLAPS정리!$BH$2:$BH$101,0)),""))) | BX13: =IF($B13="","",IF(Z13="","",IFERROR(VLOOKUP(Z13,GLAPS정리!$AX$2:$AZ$17,3,0),""))) | BZ13: =IF($B13="","",IF(H13="","",VLOOKUP(H13,GLAPS정리!$L$3:$O$133,2,0))) | CA13: =IF($B13="","",IF(V13="공휴일", 10, IF(V13="야간", 20, IF(V13="위험물", 30, IF(V13="중량", 40, ""))))) | CL13: =IF($B13="","",IF(AI13="","",VLOOKUP(AI13,GLAPS정리!$BT$3:$BV$26,3,0)))
B14: =IF(GLAPS자동계산!C13="","",GLAPS자동계산!C13) | C14: =IF(GLAPS자동계산!D13="","",GLAPS자동계산!D13) | D14: =IF(GLAPS자동계산!E13="","",GLAPS자동계산!E13) | E14: =IF(GLAPS자동계산!F13="","",GLAPS자동계산!F13) | F14: =IF(GLAPS자동계산!G13="","",GLAPS자동계산!G13) | G14: =IF(GLAPS자동계산!H13="","",GLAPS자동계산!H13) | H14: =IF(GLAPS자동계산!I13="","",GLAPS자동계산!I13) | I14: =IF(GLAPS자동계산!J13="","",GLAPS자동계산!J13) | ... AA14: =IF(GLAPS자동계산!AB13="","",GLAPS자동계산!AB13) | AC14: =IF($B14="","",$AC$1) | AD14: =IF($B14="","",IFERROR(INDEX(GLAPS정리!$D$2:$D$50,MATCH(I14,GLAPS정리!$A$2:$A$50,0)),IFERROR(INDEX(GLAPS정리!$D$2:$D$50,MATCH(I14,GLAPS정리!$B$2:$B$50,0)),""))) | AF14: =IF($B14="","",$AF$1) | AI14: =IF($B14="","",IF(F14="","",VLOOKUP(F14,GLAPS정리!$G$3:$J$114,2,0))) | AJ14: =IF($B14="","",IF(Z14="울산정일","KRONS",IF(Z14="울산신항","KRUSN",IF(OR(Z14="선광종합물류(인천여객)",Z14="인천여객(인천여객)"),"KRINF",IF(OR(Z14="선광인천보세(인천신)",Z14="한진인천(인천신)",Z14="선광인천신항(인천신)",Z14="인천더로지스(인천신)"),"KRINN",IF(OR(Z14="인천진아(인천항)",Z14="인천E1(인천항)",Z14="인천SM경인터미널(인천항)",Z14="인천항(인천항)",Z14="인천우련(인천항)",Z14="인천항8부두(인천항)"),"KRINC",VLOOKUP(K14,GLAPS정리!$BB$2:$BC$33,2,0))))))) | AL14: =IF($B14="","",$AL$1) | AN14: =IF($B14="","",TEXT(B14,"YYYY-MM-DD")) | AO14: =IF($B14="","",IF(E14="오전", "0800", IF(E14="오후", "1300", IF(E14="잔업", "1800", "")))) | AP14: =IF($B14="","",IF(C14="","",VLOOKUP(C14,GLAPS정리!$AX$2:$AZ$17,3,0))) | AR14: =IF($B14="","",IF(X14="","",X14)) | AX14: =IF($B14="","",IF(L14="","",VLOOKUP(L14,GLAPS정리!$V$3:$W$180,2,0))) | BM14: =IF($B14="","",IF(AND(Q14=1,OR(P14="",P14="위험물")), "2210", IF(AND(Q14=1,OR(P14="리퍼",P14="위험물리퍼")), "2230", IF(AND(S14=1,OR(P14="",P14="위험물")), "4510", IF(AND(S14=1,OR(P14="리퍼",P14="위험물리퍼")), "4530", IF(AND(R14=1,OR(P14="",P14="위험물")), "4210", IF(AND(R14=1,P14="리퍼"), "4230", " "))))))) | BN14: =IF($B14="","",$BN$1) | BR14: =IF($B14="","",IF(OR(P14="리퍼",P14="위험물리퍼"),"Y","")) | BS14: =IF($B14="","",IF(OR(P14="위험물",P14="위험물리퍼"),"Y","")) | BV14: =IF($B14="","",IF(O14="","",VLOOKUP(O14,GLAPS정리!$BH$2:$BI$94,2,0))) | BW14: =IF($B14="","",IF(OR(Z14="동원",Z14="세방",Z14="한타"),"",IFERROR(INDEX(GLAPS정리!$BI$2:$BI$101,MATCH(Z14,GLAPS정리!$BH$2:$BH$101,0)),""))) | BX14: =IF($B14="","",IF(Z14="","",IFERROR(VLOOKUP(Z14,GLAPS정리!$AX$2:$AZ$17,3,0),""))) | BZ14: =IF($B14="","",IF(H14="","",VLOOKUP(H14,GLAPS정리!$L$3:$O$133,2,0))) | CA14: =IF($B14="","",IF(V14="공휴일", 10, IF(V14="야간", 20, IF(V14="위험물", 30, IF(V14="중량", 40, ""))))) | CL14: =IF($B14="","",IF(AI14="","",VLOOKUP(AI14,GLAPS정리!$BT$3:$BV$26,3,0)))
... B202: =IF(GLAPS자동계산!C201="","",GLAPS자동계산!C201) | C202: =IF(GLAPS자동계산!D201="","",GLAPS자동계산!D201) | D202: =IF(GLAPS자동계산!E201="","",GLAPS자동계산!E201) | E202: =IF(GLAPS자동계산!F201="","",GLAPS자동계산!F201) | F202: =IF(GLAPS자동계산!G201="","",GLAPS자동계산!G201) | G202: =IF(GLAPS자동계산!H201="","",GLAPS자동계산!H201) | H202: =IF(GLAPS자동계산!I201="","",GLAPS자동계산!I201) | I202: =IF(GLAPS자동계산!J201="","",GLAPS자동계산!J201) | ... AA202: =IF(GLAPS자동계산!AB201="","",GLAPS자동계산!AB201) | AC202: =IF($B202="","",$AC$1) | AD202: =IF($B202="","",IFERROR(INDEX(GLAPS정리!$D$2:$D$50,MATCH(I202,GLAPS정리!$A$2:$A$50,0)),IFERROR(INDEX(GLAPS정리!$D$2:$D$50,MATCH(I202,GLAPS정리!$B$2:$B$50,0)),""))) | AF202: =IF($B202="","",$AF$1) | AI202: =IF($B202="","",IF(F202="","",VLOOKUP(F202,GLAPS정리!$G$3:$J$114,2,0))) | AJ202: =IF($B202="","",IF(Z202="울산정일","KRONS",IF(Z202="울산신항","KRUSN",IF(OR(Z202="선광종합물류(인천여객)",Z202="인천여객(인천여객)"),"KRINF",IF(OR(Z202="선광인천보세(인천신)",Z202="한진인천(인천신)",Z202="선광인천신항(인천신)",Z202="인천더로지스(인천신)"),"KRINN",IF(OR(Z202="인천진아(인천항)",Z202="인천E1(인천항)",Z202="인천SM경인터미널(인천항)",Z202="인천항(인천항)",Z202="인천우련(인천항)",Z202="인천항8부두(인천항)"),"KRINC",VLOOKUP(K202,GLAPS정리!$BB$2:$BC$33,2,0))))))) | AL202: =IF($B202="","",$AL$1) | AN202: =IF($B202="","",TEXT(B202,"YYYY-MM-DD")) | AO202: =IF($B202="","",IF(E202="오전", "0800", IF(E202="오후", "1300", IF(E202="잔업", "1800", "")))) | AP202: =IF($B202="","",IF(C202="","",VLOOKUP(C202,GLAPS정리!$AX$2:$AZ$17,3,0))) | AR202: =IF($B202="","",IF(X202="","",X202)) | AX202: =IF($B202="","",IF(L202="","",VLOOKUP(L202,GLAPS정리!$V$3:$W$180,2,0))) | BM202: =IF($B202="","",IF(AND(Q202=1,OR(P202="",P202="위험물")), "2210", IF(AND(Q202=1,OR(P202="리퍼",P202="위험물리퍼")), "2230", IF(AND(S202=1,OR(P202="",P202="위험물")), "4510", IF(AND(S202=1,OR(P202="리퍼",P202="위험물리퍼")), "4530", IF(AND(R202=1,OR(P202="",P202="위험물")), "4210", IF(AND(R202=1,P202="리퍼"), "4230", " "))))))) | BN202: =IF($B202="","",$BN$1) | BR202: =IF($B202="","",IF(OR(P202="리퍼",P202="위험물리퍼"),"Y","")) | BS202: =IF($B202="","",IF(OR(P202="위험물",P202="위험물리퍼"),"Y","")) | BV202: =IF($B202="","",IF(O202="","",VLOOKUP(O202,GLAPS정리!$BH$2:$BI$94,2,0))) | BW202: =IF($B202="","",IF(OR(Z202="동원",Z202="세방",Z202="한타"),"",IFERROR(INDEX(GLAPS정리!$BI$2:$BI$101,MATCH(Z202,GLAPS정리!$BH$2:$BH$101,0)),""))) | BX202: =IF($B202="","",IF(Z202="","",IFERROR(VLOOKUP(Z202,GLAPS정리!$AX$2:$AZ$17,3,0),""))) | BZ202: =IF($B202="","",IF(H202="","",VLOOKUP(H202,GLAPS정리!$L$3:$O$133,2,0))) | CA202: =IF($B202="","",IF(V202="공휴일", 10, IF(V202="야간", 20, IF(V202="위험물", 30, IF(V202="중량", 40, ""))))) | CL202: =IF($B202="","",IF(AI202="","",VLOOKUP(AI202,GLAPS정리!$BT$3:$BV$26,3,0)))

Sheet GLAPS컨테이너배차관리
A1: ODCY명 | B1: 번호 | C1: 배차 | D1: 운송 | E1: 오더번호(TMS) | F1: 편성번호 | G1: 배차번호 | H1: 진행상태 | I1: 정산상태 | J1: 오더구분 | K1: 작업지(하차지)도착요청일 | L1: 작업지(하차지)도착요청시간 | M1: 픽업부킹번호 | N1: 반입부킹번호 | O1: 선사코드 | P1: 선사명 | Q1: POL | R1: Pod | S1: 최종목적지 | T1: 작업지(하차지)명 | U1: 컨샤이니명 | V1: 선적지 | W1: 화주사 | X1: 컨테이너 번호 | Y1: 컨규격 | Z1: 봉인번호 | AA1: 컨테이너 사진 | AB1: 차량번호 | AC1: 운전원명 | AD1: 기사전화번호 | AE1: 차량아이디 | AF1: ATD | AG1: ETD | AH1: ETA | AI1: 냉동 | AJ1: 온도 | AK1: 위험물 | AL1: 위험물코드 | AM1: 위험물 Free Time | AN1: 공컨반납기한 | AO1: 반납기한초과 | AP1: 철송여부 | AQ1: 오더등급 | AR1: 하차지등급 | AS1: 운송구분 | AT1: 직계약여부 | AU1: 모바일배정 | AV1: 운전원매입금액 | AW1: 운전원배차여부 | AX1: GMMS 등록 | AY1: 운송사코드 | AZ1: 운송사 | BA1: 수기배정사유 | BB1: 수기배정사유내용 | BC1: 판매시장 | BD1: 판매구분 | BE1: 매출구분 | BF1: 직계약 차량 | BG1: 입차영업소 | BH1: 입차일자 | BI1: COPINO | BJ1: COPINO전송일시 | BK1: COPINO응답여부 | BL1: COPINO응답메시지 | BM1: 운송경로코드 | BN1: 운송경로명 | BO1: 운송경로 기준거리(KM) | BP1: 반출가능여부 | BQ1: 반출지 코드 | BR1: 반출지명(출발) | BS1: 반출지 주소 | BT1: 파손컨 여부 | BU1: 파손사진 | BV1: 파손신고일 | BW1: 파손신고시간 | BX1: 반출완료일시 | BY1: 작업지 코드 | BZ1: 작업지(하차지) 주소 | CA1: 작업(하차)완료일시 | CB1: 경유지코드 | CC1: 경유지명 | CD1: 경유지주소 | CE1: 선픽업여부 | CF1: 선픽업정산방식 | CG1: 선픽업창고명 | CH1: 선픽업시작일 | CI1: 선픽업종료일 | CJ1: 선픽업보관일수 | CK1: ODCY 여부 | CL1: ODCY 코드 | CM1: ODCY창고명 | CN1: 보관일수 | CO1: 선픽업 보관일수 | CP1: 반출CY | CQ1: 반출CY일치여부 | CR1: 반출일시 | CS1: 반입CY | CT1: 반입CY일치여부 | CU1: 반입일시 | CV1: 컨테이너 중량 | CW1: VGM | CX1: 화물설명 | CY1: 화주 구분 | CZ1: 산업군 | DA1: 오더일시 | DB1: 배정일시 | DC1: 배차일시 | DD1: 배차취소시간 | DE1: 정산기준일자 | DF1: 통지사항 | DG1: 메모 | DH1: 매입금액 | DI1: 할증1 | DJ1: 할증2 | DK1: 할증3 | DL1: 할증4 | DM1: 할증5 | DN1: 매입할증 합계 | DO1: 선픽업료 | DP1: 공컨상차비여부 | DQ1: 정산정보 | DR1: 오더등록업체 | DS1: 오더등록자명 | DT1: 오더등록자 연락처 | DU1: 오더등록자 이메일 | DV1: 운송서비스 | DW1: 운송서비스코드 | DX1: 공차중량
B2: 193 | E2: W260602-00000423 | F2: X260602-001956 | G2: Y260602-001956 | H2: 배정 | I2: 미생성 | J2: 수출 | K2: 46177 | L2: 18:00 | M2: SELG82813400 | N2: SELG82813400 | O2: ONE | P2: 오션네트워크익스프레스 | S2: USSAV | T2: [GB]아산 2포장장 (오토쎌) | U2: KAGA | V2: 네슬리 | W2: 현대글로비스주식회사 | Y2: 4510 | AK2: N | AP2: N | AQ2: D | AS2: 주선 | AT2: N | AV2: 0 | AX2: N | AY2: 1011 | AZ2: ㈜이엘에스솔루션 | BC2: 수출 | BD2: 반제품 | BE2: 운송료 | BI2: N | BK2: N | BM2: AAAAAAAAA | BN2: 컨테이너 미정의 | BP2: N | BQ2: AAA | BR2: 미정의 | BT2: N | BW2: __:__ | BY2: H000_GB | CK2: N | CQ2: N | CT2: N | CV2: 0 | CY2: 계열 | DA2: 02)16:51 | DB2: 02)16:51 | DH2: 0 | DN2: 0 | DO2: 0 | DP2: N | DS2: 박승기 | DV2: 컨테이너_수출 | DW2: 5010001 | DX2: 0
B3: 192 | E3: W260602-00000422 | F3: X260602-001957 | G3: Y260602-001957 | H3: 배정 | I3: 미생성 | J3: 수출 | K3: 46177 | L3: 13:00 | M3: D713CJ044 | N3: D713CJ044 | O3: MAE | P3: 머스크 | S3: USMOB | T3: [GB]아산 2포장장 (오토쎌) | U3: HMMA | V3: 셔틀 | W3: 현대글로비스주식회사 | Y3: 4510 | AK3: N | AP3: N | AQ3: D | AS3: 주선 | AT3: N | AV3: 0 | AX3: N | AY3: 1011 | AZ3: ㈜이엘에스솔루션 | BC3: 수출 | BD3: 반제품 | BE3: 운송료 | BI3: N | BK3: N | BM3: AAAAAAAAA | BN3: 컨테이너 미정의 | BP3: N | BQ3: AAA | BR3: 미정의 | BT3: N | BW3: __:__ | BY3: H000_GB | CK3: N | CQ3: N | CT3: N | CV3: 0 | CY3: 계열 | DA3: 02)16:51 | DB3: 02)16:51 | DH3: 0 | DN3: 0 | DO3: 0 | DP3: N | DS3: 박승기 | DV3: 컨테이너_수출 | DW3: 5010001 | DX3: 0
B4: 191 | E4: W260602-00000421 | F4: X260602-002072 | G4: Y260602-002072 | H4: 배정 | I4: 미생성 | J4: 수출 | K4: 46177 | L4: 18:00 | M4: D713CJ044 | N4: D713CJ044 | O4: MAE | P4: 머스크 | S4: USMOB | T4: [GB]아산 2포장장 (오토쎌) | U4: HMMA | V4: 대신 | W4: 현대글로비스주식회사 | Y4: 4510 | AK4: N | AP4: N | AQ4: D | AS4: 주선 | AT4: N | AV4: 0 | AX4: N | AY4: 1011 | AZ4: ㈜이엘에스솔루션 | BC4: 수출 | BD4: 반제품 | BE4: 운송료 | BI4: N | BK4: N | BM4: AAAAAAAAA | BN4: 컨테이너 미정의 | BP4: N | BQ4: AAA | BR4: 미정의 | BT4: N | BW4: __:__ | BY4: H000_GB | CK4: N | CQ4: N | CT4: N | CV4: 0 | CY4: 계열 | DA4: 02)17:35 | DB4: 02)17:35 | DH4: 0 | DN4: 0 | DO4: 0 | DP4: N | DS4: 박승기 | DV4: 컨테이너_수출 | DW4: 5010001 | DX4: 0
B5: 190 | E5: W260602-00000421 | F5: X260602-002071 | G5: Y260602-002071 | H5: 배정 | I5: 미생성 | J5: 수출 | K5: 46177 | L5: 19:00 | M5: D713CJ044 | N5: D713CJ044 | O5: MAE | P5: 머스크 | S5: USMOB | T5: [GB]아산 2포장장 (오토쎌) | U5: HMMA | V5: 대신 | W5: 현대글로비스주식회사 | Y5: 4510 | AK5: N | AP5: N | AQ5: D | AS5: 주선 | AT5: N | AV5: 0 | AX5: N | AY5: 1011 | AZ5: ㈜이엘에스솔루션 | BC5: 수출 | BD5: 반제품 | BE5: 운송료 | BI5: N | BK5: N | BM5: AAAAAAAAA | BN5: 컨테이너 미정의 | BP5: N | BQ5: AAA | BR5: 미정의 | BT5: N | BW5: __:__ | BY5: H000_GB | CK5: N | CQ5: N | CT5: N | CV5: 0 | CY5: 계열 | DA5: 02)17:34 | DB5: 02)17:34 | DH5: 0 | DN5: 0 | DO5: 0 | DP5: N | DS5: 박승기 | DV5: 컨테이너_수출 | DW5: 5010001 | DX5: 0
B6: 189 | E6: W260602-00000421 | F6: X260602-002070 | G6: Y260602-002070 | H6: 배정 | I6: 미생성 | J6: 수출 | K6: 46177 | L6: 14:00 | M6: D713CJ044 | N6: D713CJ044 | O6: MAE | P6: 머스크 | S6: USMOB | T6: [GB]아산 2포장장 (오토쎌) | U6: HMMA | V6: 셔틀 | W6: 현대글로비스주식회사 | Y6: 4510 | AK6: N | AP6: N | AQ6: D | AS6: 주선 | AT6: N | AV6: 0 | AX6: N | AY6: 1011 | AZ6: ㈜이엘에스솔루션 | BC6: 수출 | BD6: 반제품 | BE6: 운송료 | BI6: N | BK6: N | BM6: AAAAAAAAA | BN6: 컨테이너 미정의 | BP6: N | BQ6: AAA | BR6: 미정의 | BT6: N | BW6: __:__ | BY6: H000_GB | CK6: N | CQ6: N | CT6: N | CV6: 0 | CY6: 계열 | DA6: 02)17:33 | DB6: 02)17:33 | DH6: 0 | DN6: 0 | DO6: 0 | DP6: N | DS6: 박승기 | DV6: 컨테이너_수출 | DW6: 5010001 | DX6: 0
B7: 188 | E7: W260602-00000421 | F7: X260602-001958 | G7: Y260602-001958 | H7: 배정 | I7: 미생성 | J7: 수출 | K7: 46177 | L7: 19:00 | M7: D713CJ044 | N7: D713CJ044 | O7: MAE | P7: 머스크 | S7: USMOB | T7: [GB]아산 2포장장 (오토쎌) | U7: HMMA | V7: 미배정 | W7: 현대글로비스주식회사 | Y7: 4510 | AK7: N | AP7: N | AQ7: D | AS7: 주선 | AT7: N | AV7: 0 | AX7: N | AY7: 1011 | AZ7: ㈜이엘에스솔루션 | BC7: 수출 | BD7: 반제품 | BE7: 운송료 | BI7: N | BK7: N | BM7: AAAAAAAAA | BN7: 컨테이너 미정의 | BP7: N | BQ7: AAA | BR7: 미정의 | BT7: N | BW7: __:__ | BY7: H000_GB | CK7: N | CQ7: N | CT7: N | CV7: 0 | CY7: 계열 | DA7: 02)16:51 | DB7: 02)16:51 | DH7: 0 | DN7: 0 | DO7: 0 | DP7: N | DS7: 박승기 | DV7: 컨테이너_수출 | DW7: 5010001 | DX7: 0
B8: 187 | E8: W260602-00000417 | F8: X260602-001962 | G8: Y260602-001962 | H8: 배정 | I8: 미생성 | J8: 수출 | K8: 46177 | L8: 15:00 | M8: SELG82813400 | N8: SELG82813400 | O8: ONE | P8: 오션네트워크익스프레스 | S8: USLAX | T8: [GB]아산 2포장장 (오토쎌) | U8: HMMA | V8: 셔틀 | W8: 현대글로비스주식회사 | Y8: 4510 | AK8: N | AP8: N | AQ8: D | AS8: 주선 | AT8: N | AV8: 0 | AX8: N | AY8: 1011 | AZ8: ㈜이엘에스솔루션 | BC8: 수출 | BD8: 반제품 | BE8: 운송료 | BI8: N | BK8: N | BM8: AAAAAAAAA | BN8: 컨테이너 미정의 | BP8: N | BQ8: AAA | BR8: 미정의 | BT8: N | BW8: __:__ | BY8: H000_GB | CK8: N | CQ8: N | CT8: N | CV8: 0 | CY8: 계열 | DA8: 02)16:51 | DB8: 02)16:51 | DH8: 0 | DN8: 0 | DO8: 0 | DP8: N | DS8: 박승기 | DV8: 컨테이너_수출 | DW8: 5010001 | DX8: 0
B9: 186 | E9: W260602-00000416 | F9: X260602-001963 | G9: Y260602-001963 | H9: 배정 | I9: 미생성 | J9: 수출 | K9: 46177 | L9: 09:00 | M9: D713CJ044 | N9: D713CJ044 | O9: MAE | P9: 머스크 | S9: USLAX | T9: [GB]아산 2포장장 (오토쎌) | U9: KAGA | V9: 이지 | W9: 현대글로비스주식회사 | Y9: 4510 | AK9: N | AP9: N | AQ9: D | AS9: 주선 | AT9: N | AV9: 0 | AX9: N | AY9: 1011 | AZ9: ㈜이엘에스솔루션 | BC9: 수출 | BD9: 반제품 | BE9: 운송료 | BI9: N | BK9: N | BM9: AAAAAAAAA | BN9: 컨테이너 미정의 | BP9: N | BQ9: AAA | BR9: 미정의 | BT9: N | BW9: __:__ | BY9: H000_GB | CK9: N | CQ9: N | CT9: N | CV9: 0 | CY9: 계열 | DA9: 02)16:51 | DB9: 02)16:51 | DH9: 0 | DN9: 0 | DO9: 0 | DP9: N | DS9: 박승기 | DV9: 컨테이너_수출 | DW9: 5010001 | DX9: 0
B10: 185 | E10: W260602-00000415 | F10: X260602-001964 | G10: Y260602-001964 | H10: 배정 | I10: 미생성 | J10: 수출 | K10: 46177 | L10: 11:00 | M10: D713CJ044 | N10: D713CJ044 | O10: MAE | P10: 머스크 | S10: USLAX | T10: [GB]아산 2포장장 (오토쎌) | U10: KAGA | V10: 셔틀 | W10: 현대글로비스주식회사 | Y10: 4510 | AK10: N | AP10: N | AQ10: D | AS10: 주선 | AT10: N | AV10: 0 | AX10: N | AY10: 1011 | AZ10: ㈜이엘에스솔루션 | BC10: 수출 | BD10: 반제품 | BE10: 운송료 | BI10: N | BK10: N | BM10: AAAAAAAAA | BN10: 컨테이너 미정의 | BP10: N | BQ10: AAA | BR10: 미정의 | BT10: N | BW10: __:__ | BY10: H000_GB | CK10: N | CQ10: N | CT10: N | CV10: 0 | CY10: 계열 | DA10: 02)16:51 | DB10: 02)16:51 | DH10: 0 | DN10: 0 | DO10: 0 | DP10: N | DS10: 박승기 | DV10: 컨테이너_수출 | DW10: 5010001 | DX10: 0
B11: 184 | E11: W260602-00000414 | F11: X260602-001965 | G11: Y260602-001965 | H11: 배정 | I11: 미생성 | J11: 수출 | K11: 46177 | L11: 16:00 | M11: 005GX17204 | N11: 005GX17204 | O11: WHL | P11: Wanhai라인 | S11: INKAT | T11: [GB]아산 2포장장 (오토쎌) | U11: HMI/HMI PUNE | V11: 대신 | W11: 현대글로비스주식회사 | Y11: 4510 | AK11: N | AP11: N | AQ11: D | AS11: 주선 | AT11: N | AV11: 0 | AX11: N | AY11: 1011 | AZ11: ㈜이엘에스솔루션 | BC11: 수출 | BD11: 반제품 | BE11: 운송료 | BI11: N | BK11: N | BM11: GLC00263 | BN11: 부산신항 [GB]아산 2포장장 부산신항 | BO11: 0 | BP11: N | BQ11: KRBNP | BR11: 부산신항 | BT11: N | BW11: __:__ | BY11: H000_GB | CK11: N | CQ11: N | CT11: N | CV11: 0 | CY11: 계열 | DA11: 02)16:51 | DB11: 02)16:51 | DH11: 1023500 | DN11: 0 | DO11: 0 | DP11: N | DS11: 박승기 | DV11: 컨테이너_수출 | DW11: 5010001 | DX11: 0
B12: 183 | E12: W260602-00000413 | F12: X260602-001966 | G12: Y260602-001966 | H12: 배차확정 | I12: 미생성 | J12: 수출 | K12: 46177 | L12: 08:00 | M12: 005GX17204 | N12: 005GX17204 | O12: WHL | P12: Wanhai라인 | S12: INKAT | T12: [GB]아산 2포장장 (오토쎌) | U12: KIN | V12: 자차 | W12: 현대글로비스주식회사 | X12: WHSU6549777 | Y12: 4510 | Z12: WHA3168605 | AA12: 보기 | AB12: 부산99바7157 | AC12: 현우진 | AD12: 01062228360 | AE12: DSDS7157 | AK12: N | AP12: N | AQ12: D | AS12: 주선 | AT12: N | AV12: 0 | AX12: N | AY12: 1011 | AZ12: ㈜이엘에스솔루션 | BC12: 수출 | BD12: 반제품 | BE12: 운송료 | BF12: N | BI12: N | BK12: N | BM12: GLC00263 | BN12: 부산신항 [GB]아산 2포장장 부산신항 | BO12: 0 | BP12: N | BQ12: KRBNP | BR12: 부산신항 | BT12: N | BW12: __:__ | BX12: 2026-06-02 17:21:28 | BY12: H000_GB | CK12: N | CQ12: N | CT12: N | CV12: 0 | CY12: 계열 | DA12: 02)16:51 | DB12: 02)16:51 | DC12: 02)16:55 | DH12: 1023500 | DN12: 0 | DO12: 0 | DP12: N | DS12: 박승기 | DV12: 컨테이너_수출 | DW12: 5010001 | DX12: 0
B13: 182 | E13: W260602-00000412 | F13: X260602-001967 | G13: Y260602-001967 | H13: 배차확정 | I13: 미생성 | J13: 수출 | K13: 46177 | L13: 09:00 | M13: 005GX17204 | N13: 005GX17204 | O13: WHL | P13: Wanhai라인 | S13: INKAT | T13: [GB]아산 2포장장 (오토쎌) | U13: KIN | V13: 자차 | W13: 현대글로비스주식회사 | X13: WHSU5174357 | Y13: 4510 | Z13: WHA3168615 | AA13: 보기 | AB13: 경북98사1145 | AC13: 김현수 | AD13: 01074705405 | AE13: KDBE1145 | AK13: N | AP13: N | AQ13: D | AS13: 주선 | AT13: N | AV13: 0 | AX13: N | AY13: 1011 | AZ13: ㈜이엘에스솔루션 | BC13: 수출 | BD13: 반제품 | BE13: 운송료 | BF13: N | BI13: N | BK13: N | BM13: GLC00263 | BN13: 부산신항 [GB]아산 2포장장 부산신항 | BO13: 0 | BP13: N | BQ13: KRBNP | BR13: 부산신항 | BT13: N | BW13: __:__ | BX13: 2026-06-02 17:17:11 | BY13: H000_GB | CK13: N | CQ13: N | CT13: N | CV13: 0 | CY13: 계열 | DA13: 02)16:51 | DB13: 02)16:51 | DC13: 02)16:55 | DH13: 1023500 | DN13: 0 | DO13: 0 | DP13: N | DS13: 박승기 | DV13: 컨테이너_수출 | DW13: 5010001 | DX13: 0
B14: 181 | E14: W260602-00000411 | F14: X260602-001968 | G14: Y260602-001968 | H14: 배정 | I14: 미생성 | J14: 수출 | K14: 46177 | L14: 10:00 | M14: 005GX17204 | N14: 005GX17204 | O14: WHL | P14: Wanhai라인 | S14: INKAT | T14: [GB]아산 2포장장 (오토쎌) | U14: KIN | V14: 칸 | W14: 현대글로비스주식회사 | Y14: 4510 | AK14: N | AP14: N | AQ14: D | AS14: 주선 | AT14: N | AV14: 0 | AX14: N | AY14: 1011 | AZ14: ㈜이엘에스솔루션 | BC14: 수출 | BD14: 반제품 | BE14: 운송료 | BI14: N | BK14: N | BM14: GLC00263 | BN14: 부산신항 [GB]아산 2포장장 부산신항 | BO14: 0 | BP14: N | BQ14: KRBNP | BR14: 부산신항 | BT14: N | BW14: __:__ | BY14: H000_GB | CK14: N | CQ14: N | CT14: N | CV14: 0 | CY14: 계열 | DA14: 02)16:51 | DB14: 02)16:51 | DH14: 1023500 | DN14: 0 | DO14: 0 | DP14: N | DS14: 박승기 | DV14: 컨테이너_수출 | DW14: 5010001 | DX14: 0
B15: 180 | E15: W260602-00000410 | F15: X260602-001969 | G15: Y260602-001969 | H15: 배정 | I15: 미생성 | J15: 수출 | K15: 46177 | L15: 16:00 | M15: 005GX17204 | N15: 005GX17204 | O15: WHL | P15: Wanhai라인 | S15: INKAT | T15: [GB]아산 2포장장 (오토쎌) | U15: KIN | V15: 신승 | W15: 현대글로비스주식회사 | Y15: 4510 | AK15: N | AP15: N | AQ15: D | AS15: 주선 | AT15: N | AV15: 0 | AX15: N | AY15: 1011 | AZ15: ㈜이엘에스솔루션 | BC15: 수출 | BD15: 반제품 | BE15: 운송료 | BI15: N | BK15: N | BM15: GLC00263 | BN15: 부산신항 [GB]아산 2포장장 부산신항 | BO15: 0 | BP15: N | BQ15: KRBNP | BR15: 부산신항 | BT15: N | BW15: __:__ | BY15: H000_GB | CK15: N | CQ15: N | CT15: N | CV15: 0 | CY15: 계열 | DA15: 02)16:51 | DB15: 02)16:51 | DH15: 1023500 | DN15: 0 | DO15: 0 | DP15: N | DS15: 박승기 | DV15: 컨테이너_수출 | DW15: 5010001 | DX15: 0
B16: 179 | E16: W260602-00000409 | F16: X260602-001970 | G16: Y260602-001970 | H16: 배정 | I16: 미생성 | J16: 수출 | K16: 46177 | L16: 18:00 | M16: 005GX17204 | N16: 005GX17204 | O16: WHL | P16: Wanhai라인 | S16: INKAT | T16: [GB]아산 2포장장 (오토쎌) | U16: KIN | V16: 대신 | W16: 현대글로비스주식회사 | Y16: 4510 | AK16: N | AP16: N | AQ16: D | AS16: 주선 | AT16: N | AV16: 0 | AX16: N | AY16: 1011 | AZ16: ㈜이엘에스솔루션 | BC16: 수출 | BD16: 반제품 | BE16: 운송료 | BI16: N | BK16: N | BM16: GLC00263 | BN16: 부산신항 [GB]아산 2포장장 부산신항 | BO16: 0 | BP16: N | BQ16: KRBNP | BR16: 부산신항 | BT16: N | BW16: __:__ | BY16: H000_GB | CK16: N | CQ16: N | CT16: N | CV16: 0 | CY16: 계열 | DA16: 02)16:51 | DB16: 02)16:51 | DH16: 1023500 | DN16: 0 | DO16: 0 | DP16: N | DS16: 박승기 | DV16: 컨테이너_수출 | DW16: 5010001 | DX16: 0
B17: 178 | E17: W260602-00000408 | F17: X260602-001971 | G17: Y260602-001971 | H17: 배정 | I17: 미생성 | J17: 수출 | K17: 46177 | L17: 08:00 | M17: HLAKRGLOVKDPUS | N17: HLAKRGLOVKDPUS | O17: HLC | P17: 하파그로이드 | S17: MXESE | T17: [GB]아산 2포장장 (오토쎌) | U17: TRANSLEAD | V17: 이지 | W17: 현대글로비스주식회사 | Y17: 4510 | AK17: N | AP17: N | AQ17: D | AS17: 주선 | AT17: N | AV17: 0 | AX17: N | AY17: 1011 | AZ17: ㈜이엘에스솔루션 | BC17: 수출 | BD17: 반제품 | BE17: 운송료 | BI17: N | BK17: N | BM17: AAAAAAAAA | BN17: 컨테이너 미정의 | BP17: N | BQ17: AAA | BR17: 미정의 | BT17: N | BW17: __:__ | BY17: H000_GB | CK17: N | CQ17: N | CT17: N | CV17: 0 | CY17: 계열 | DA17: 02)16:51 | DB17: 02)16:51 | DH17: 0 | DN17: 0 | DO17: 0 | DP17: N | DS17: 박승기 | DV17: 컨테이너_수출 | DW17: 5010001 | DX17: 0
B18: 177 | E18: W260602-00000407 | F18: X260602-001972 | G18: Y260602-001972 | H18: 배정 | I18: 미생성 | J18: 수출 | K18: 46177 | L18: 10:00 | M18: HLAKRGLOVKDPUS | N18: HLAKRGLOVKDPUS | O18: HLC | P18: 하파그로이드 | S18: MXESE | T18: [GB]아산 2포장장 (오토쎌) | U18: TRANSLEAD | V18: 이지 | W18: 현대글로비스주식회사 | Y18: 4510 | AK18: N | AP18: N | AQ18: D | AS18: 주선 | AT18: N | AV18: 0 | AX18: N | AY18: 1011 | AZ18: ㈜이엘에스솔루션 | BC18: 수출 | BD18: 반제품 | BE18: 운송료 | BI18: N | BK18: N | BM18: AAAAAAAAA | BN18: 컨테이너 미정의 | BP18: N | BQ18: AAA | BR18: 미정의 | BT18: N | BW18: __:__ | BY18: H000_GB | CK18: N | CQ18: N | CT18: N | CV18: 0 | CY18: 계열 | DA18: 02)16:51 | DB18: 02)16:51 | DH18: 0 | DN18: 0 | DO18: 0 | DP18: N | DS18: 박승기 | DV18: 컨테이너_수출 | DW18: 5010001 | DX18: 0
B19: 176 | E19: W260602-00000406 | F19: X260602-001973 | G19: Y260602-001973 | H19: 운송완료 | I19: 정산실적생성 | J19: 수출 | K19: 46177 | L19: 08:00 | M19: CMA2606010011 | N19: CMA2606010011 | O19: CMA | P19: CMA-CGM | S19: SIKOP | T19: [GA]아산 1포장장 (공성실업) | U19: KASK | V19: 자차 | W19: 현대글로비스주식회사 | X19: CMAU7117159 | Y19: 4510 | Z19: M6412892 | AB19: 경남99바4922 | AC19: 이명열 | AD19: 01053830311 | AE19: FSFS4922 | AK19: N | AP19: N | AQ19: D | AS19: 주선 | AT19: N | AV19: 0 | AX19: N | AY19: 1011 | AZ19: ㈜이엘에스솔루션 | BC19: 수출 | BD19: 반제품 | BE19: 운송료 | BF19: N | BI19: N | BK19: N | BM19: GLC00003 | BN19: 부산신항 [GA]아산 1포장장 (공성실업) 부산신항 | BO19: 0 | BP19: N | BQ19: KRBNP | BR19: 부산신항 | BT19: N | BW19: __:__ | BY19: H000_GA | CK19: N | CQ19: N | CT19: N | CV19: 0 | CY19: 계열 | DA19: 02)16:51 | DB19: 02)16:51 | DC19: 02)16:54 | DE19: 46175 | DH19: 1023500 | DN19: 0 | DO19: 0 | DP19: N | DS19: 박승기 | DV19: 컨테이너_수출 | DW19: 5010001 | DX19: 0
B20: 175 | E20: W260602-00000405 | F20: X260602-001974 | G20: Y260602-001974 | H20: 배차확정 | I20: 미생성 | J20: 수출 | K20: 46177 | L20: 09:00 | M20: CMA2606010011 | N20: CMA2606010011 | O20: CMA | P20: CMA-CGM | S20: SIKOP | T20: [GA]아산 1포장장 (공성실업) | U20: KASK | V20: 자차 | W20: 현대글로비스주식회사 | X20: BMOU5643070 | Y20: 4510 | Z20: M6519509 | AA20: 보기 | AB20: 대구98바2977 | AC20: 이성수 | AD20: 01064842977 | AE20: GJEW2977 | AK20: N | AP20: N | AQ20: D | AS20: 주선 | AT20: N | AV20: 0 | AX20: N | AY20: 1011 | AZ20: ㈜이엘에스솔루션 | BC20: 수출 | BD20: 반제품 | BE20: 운송료 | BF20: N | BI20: N | BK20: N | BM20: GLC00003 | BN20: 부산신항 [GA]아산 1포장장 (공성실업) 부산신항 | BO20: 0 | BP20: N | BQ20: KRBNP | BR20: 부산신항 | BT20: N | BW20: __:__ | BX20: 2026-06-02 21:40:29 | BY20: H000_GA | CK20: N | CQ20: N | CT20: N | CV20: 0 | CY20: 계열 | DA20: 02)16:51 | DB20: 02)16:51 | DC20: 02)16:54 | DH20: 1023500 | DN20: 0 | DO20: 0 | DP20: N | DS20: 박승기 | DV20: 컨테이너_수출 | DW20: 5010001 | DX20: 0
B21: 170 | E21: W260602-00000400 | F21: X260602-001979 | G21: Y260602-001979 | H21: 배정 | I21: 미생성 | J21: 수출 | K21: 46177 | L21: 10:30 | M21: CMA2606010011 | N21: CMA2606010011 | O21: CMA | P21: CMA-CGM | S21: SIKOP | T21: [GA]아산 1포장장 (공성실업) | U21: KASK | V21: 셔틀 | W21: 현대글로비스주식회사 | Y21: 4510 | AK21: N | AP21: N | AQ21: D | AS21: 주선 | AT21: N | AV21: 0 | AX21: N | AY21: 1011 | AZ21: ㈜이엘에스솔루션 | BC21: 수출 | BD21: 반제품 | BE21: 운송료 | BI21: N | BK21: N | BM21: GLC00003 | BN21: 부산신항 [GA]아산 1포장장 (공성실업) 부산신항 | BO21: 0 | BP21: N | BQ21: KRBNP | BR21: 부산신항 | BT21: N | BW21: __:__ | BY21: H000_GA | CK21: N | CQ21: N | CT21: N | CV21: 0 | CY21: 계열 | DA21: 02)16:51 | DB21: 02)16:51 | DH21: 1023500 | DN21: 0 | DO21: 0 | DP21: N | DS21: 박승기 | DV21: 컨테이너_수출 | DW21: 5010001 | DX21: 0
B22: 169 | E22: W260602-00000399 | F22: X260602-001980 | G22: Y260602-001980 | H22: 배정 | I22: 미생성 | J22: 수출 | K22: 46177 | L22: 13:00 | M22: CMA2606010011 | N22: CMA2606010011 | O22: CMA | P22: CMA-CGM | S22: SIKOP | T22: [GA]아산 1포장장 (공성실업) | U22: HMMC | V22: 대신 | W22: 현대글로비스주식회사 | Y22: 4510 | AK22: N | AP22: N | AQ22: D | AS22: 주선 | AT22: N | AV22: 0 | AX22: N | AY22: 1011 | AZ22: ㈜이엘에스솔루션 | BC22: 수출 | BD22: 반제품 | BE22: 운송료 | BI22: N | BK22: N | BM22: AAAAAAAAA | BN22: 컨테이너 미정의 | BP22: N | BQ22: AAA | BR22: 미정의 | BT22: N | BW22: __:__ | BY22: H000_GA | CK22: N | CQ22: N | CT22: N | CV22: 0 | CY22: 계열 | DA22: 02)16:51 | DB22: 02)16:51 | DH22: 0 | DN22: 0 | DO22: 0 | DP22: N | DS22: 박승기 | DV22: 컨테이너_수출 | DW22: 5010001 | DX22: 0
B23: 168 | E23: W260602-00000398 | F23: X260602-001981 | G23: Y260602-001981 | H23: 배정 | I23: 미생성 | J23: 수출 | K23: 46177 | L23: 15:00 | M23: CMA2606010011 | N23: CMA2606010011 | O23: CMA | P23: CMA-CGM | S23: SIKOP | T23: [GA]아산 1포장장 (공성실업) | U23: HMMC | V23: 대신 | W23: 현대글로비스주식회사 | Y23: 4510 | AK23: N | AP23: N | AQ23: D | AS23: 주선 | AT23: N | AV23: 0 | AX23: N | AY23: 1011 | AZ23: ㈜이엘에스솔루션 | BC23: 수출 | BD23: 반제품 | BE23: 운송료 | BI23: N | BK23: N | BM23: AAAAAAAAA | BN23: 컨테이너 미정의 | BP23: N | BQ23: AAA | BR23: 미정의 | BT23: N | BW23: __:__ | BY23: H000_GA | CK23: N | CQ23: N | CT23: N | CV23: 0 | CY23: 계열 | DA23: 02)16:51 | DB23: 02)16:51 | DH23: 0 | DN23: 0 | DO23: 0 | DP23: N | DS23: 박승기 | DV23: 컨테이너_수출 | DW23: 5010001 | DX23: 0
B24: 167 | E24: W260602-00000397 | F24: X260602-001982 | G24: Y260602-001982 | H24: 배차확정 | I24: 미생성 | J24: 수출 | K24: 46177 | L24: 08:00 | M24: CMA2606010011 | N24: CMA2606010011 | O24: CMA | P24: CMA-CGM | S24: SIKOP | T24: [GA]아산 1포장장 (공성실업) | U24: HMMC | V24: 자차 | W24: 현대글로비스주식회사 | X24: BEAU4767641 | Y24: 4510 | Z24: M6412856 | AA24: 보기 | AB24: 대구98바3558 | AC24: 문성진 | AD24: 01036465666 | AE24: SYSY3558 | AK24: N | AP24: N | AQ24: D | AS24: 주선 | AT24: N | AV24: 0 | AX24: N | AY24: 1011 | AZ24: ㈜이엘에스솔루션 | BC24: 수출 | BD24: 반제품 | BE24: 운송료 | BF24: N | BI24: N | BK24: N | BM24: GLC00003 | BN24: 부산신항 [GA]아산 1포장장 (공성실업) 부산신항 | BO24: 0 | BP24: N | BQ24: KRBNP | BR24: 부산신항 | BT24: N | BW24: __:__ | BX24: 2026-06-02 17:12:45 | BY24: H000_GA | CK24: N | CQ24: N | CT24: N | CV24: 0 | CY24: 계열 | DA24: 02)16:51 | DB24: 02)16:51 | DC24: 02)16:54 | DH24: 1023500 | DN24: 0 | DO24: 0 | DP24: N | DS24: 박승기 | DV24: 컨테이너_수출 | DW24: 5010001 | DX24: 0
B25: 166 | E25: W260602-00000396 | F25: X260602-001983 | G25: Y260602-001983 | H25: 배차확정 | I25: 미생성 | J25: 수출 | K25: 46177 | L25: 09:00 | M25: CMA2606010011 | N25: CMA2606010011 | O25: CMA | P25: CMA-CGM | S25: SIKOP | T25: [GA]아산 1포장장 (공성실업) | U25: HMMC | V25: 자차 | W25: 현대글로비스주식회사 | X25: ECMU5193316 | Y25: 4510 | Z25: M6427485 | AA25: 보기 | AB25: 경기99사1487 | AC25: 박준일 | AD25: 01052330030 | AE25: LOVE1487 | AK25: N | AP25: N | AQ25: D | AS25: 주선 | AT25: N | AV25: 0 | AX25: N | AY25: 1011 | AZ25: ㈜이엘에스솔루션 | BC25: 수출 | BD25: 반제품 | BE25: 운송료 | BF25: N | BI25: N | BK25: N | BM25: GLC00003 | BN25: 부산신항 [GA]아산 1포장장 (공성실업) 부산신항 | BO25: 0 | BP25: N | BQ25: KRBNP | BR25: 부산신항 | BT25: N | BW25: __:__ | BX25: 2026-06-02 18:53:29 | BY25: H000_GA | CK25: N | CQ25: N | CT25: N | CV25: 0 | CY25: 계열 | DA25: 02)16:51 | DB25: 02)16:51 | DC25: 02)16:54 | DH25: 1023500 | DN25: 0 | DO25: 0 | DP25: N | DS25: 박승기 | DV25: 컨테이너_수출 | DW25: 5010001 | DX25: 0
B26: 164 | E26: W260602-00000394 | F26: X260602-001985 | G26: Y260602-001985 | H26: 배차확정 | I26: 미생성 | J26: 수출 | K26: 46177 | L26: 10:30 | M26: CMA2606010011 | N26: CMA2606010011 | O26: CMA | P26: CMA-CGM | S26: SIKOP | T26: [GA]아산 1포장장 (공성실업) | U26: HMMC | V26: 포유 | W26: 현대글로비스주식회사 | X26: ECMU5790944 | Y26: 4510 | Z26: M6412845 | AA26: 보기 | AB26: 경남99사8337 | AC26: 박상무 | AD26: 01085064681 | AE26: FYOU8337 | AK26: N | AP26: N | AQ26: D | AS26: 주선 | AT26: N | AV26: 0 | AX26: N | AY26: 1011 | AZ26: ㈜이엘에스솔루션 | BC26: 수출 | BD26: 반제품 | BE26: 운송료 | BF26: N | BI26: N | BK26: N | BM26: GLC00003 | BN26: 부산신항 [GA]아산 1포장장 (공성실업) 부산신항 | BO26: 0 | BP26: N | BQ26: KRBNP | BR26: 부산신항 | BT26: N | BW26: __:__ | BX26: 2026-06-03 09:44:56 | BY26: H000_GA | CK26: N | CQ26: N | CT26: N | CV26: 0 | CY26: 계열 | DA26: 02)16:51 | DB26: 02)16:51 | DC26: 03)09:44 | DH26: 1023500 | DN26: 0 | DO26: 0 | DP26: N | DS26: 박승기 | DV26: 컨테이너_수출 | DW26: 5010001 | DX26: 0
B27: 163 | E27: W260602-00000393 | F27: X260602-001986 | G27: Y260602-001986 | H27: 배정 | I27: 미생성 | J27: 수출 | K27: 46177 | L27: 15:00 | M27: 005GX17204 | N27: 005GX17204 | O27: WHL | P27: Wanhai라인 | S27: INKAT | T27: [GA]아산 1포장장 (공성실업) | U27: KIN | V27: 신승 | W27: 현대글로비스주식회사 | Y27: 4510 | AK27: N | AP27: N | AQ27: D | AS27: 주선 | AT27: N | AV27: 0 | AX27: N | AY27: 1011 | AZ27: ㈜이엘에스솔루션 | BC27: 수출 | BD27: 반제품 | BE27: 운송료 | BI27: N | BK27: N | BM27: GLC00003 | BN27: 부산신항 [GA]아산 1포장장 (공성실업) 부산신항 | BO27: 0 | BP27: N | BQ27: KRBNP | BR27: 부산신항 | BT27: N | BW27: __:__ | BY27: H000_GA | CK27: N | CQ27: N | CT27: N | CV27: 0 | CY27: 계열 | DA27: 02)16:51 | DB27: 02)16:51 | DH27: 1023500 | DN27: 0 | DO27: 0 | DP27: N | DS27: 박승기 | DV27: 컨테이너_수출 | DW27: 5010001 | DX27: 0
B28: 162 | E28: W260602-00000392 | F28: X260602-002069 | G28: Y260602-002069 | H28: 배정 | I28: 미생성 | J28: 수출 | K28: 46177 | L28: 09:00 | M28: D713CJ044 | N28: D713CJ044 | O28: MAE | P28: 머스크 | S28: MXLZC | T28: [GC]아산 3포장장 (아산YSP) | U28: KMX/KMM | V28: 이지 | W28: 현대글로비스주식회사 | Y28: 4510 | AK28: N | AP28: N | AQ28: D | AS28: 주선 | AT28: N | AV28: 0 | AX28: N | AY28: 1011 | AZ28: ㈜이엘에스솔루션 | BC28: 수출 | BD28: 반제품 | BE28: 운송료 | BI28: N | BK28: N | BM28: AAAAAAAAA | BN28: 컨테이너 미정의 | BP28: N | BQ28: AAA | BR28: 미정의 | BT28: N | BW28: __:__ | BY28: H000_GC | CK28: N | CQ28: N | CT28: N | CV28: 0 | CY28: 계열 | DA28: 02)17:29 | DB28: 02)17:29 | DH28: 0 | DN28: 0 | DO28: 0 | DP28: N | DS28: 박승기 | DV28: 컨테이너_수출 | DW28: 5010001 | DX28: 0
B29: 161 | E29: W260602-00000392 | F29: X260602-001987 | G29: Y260602-001987 | H29: 배정 | I29: 미생성 | J29: 수출 | K29: 46177 | L29: 13:00 | M29: D713CJ044 | N29: D713CJ044 | O29: MAE | P29: 머스크 | S29: MXLZC | T29: [GC]아산 3포장장 (아산YSP) | U29: KMX/KMM | V29: 미배정 | W29: 현대글로비스주식회사 | Y29: 4510 | AK29: N | AP29: N | AQ29: D | AS29: 주선 | AT29: N | AV29: 0 | AX29: N | AY29: 1011 | AZ29: ㈜이엘에스솔루션 | BC29: 수출 | BD29: 반제품 | BE29: 운송료 | BI29: N | BK29: N | BM29: AAAAAAAAA | BN29: 컨테이너 미정의 | BP29: N | BQ29: AAA | BR29: 미정의 | BT29: N | BW29: __:__ | BY29: H000_GC | CK29: N | CQ29: N | CT29: N | CV29: 0 | CY29: 계열 | DA29: 02)16:51 | DB29: 02)16:51 | DH29: 0 | DN29: 0 | DO29: 0 | DP29: N | DS29: 박승기 | DV29: 컨테이너_수출 | DW29: 5010001 | DX29: 0
B30: 160 | E30: W260602-00000391 | F30: X260602-001988 | G30: Y260602-001988 | H30: 배정 | I30: 미생성 | J30: 수출 | K30: 46177 | L30: 13:00 | M30: D713CJ044 | N30: D713CJ044 | O30: MAE | P30: 머스크 | S30: MXLZC | T30: [GC]아산 3포장장 (아산YSP) | U30: KMX/KMM | V30: CSS | W30: 현대글로비스주식회사 | Y30: 4510 | AK30: N | AP30: N | AQ30: D | AS30: 주선 | AT30: N | AV30: 0 | AX30: N | AY30: 1011 | AZ30: ㈜이엘에스솔루션 | BC30: 수출 | BD30: 반제품 | BE30: 운송료 | BI30: N | BK30: N | BM30: AAAAAAAAA | BN30: 컨테이너 미정의 | BP30: N | BQ30: AAA | BR30: 미정의 | BT30: N | BW30: __:__ | BY30: H000_GC | CK30: N | CQ30: N | CT30: N | CV30: 0 | CY30: 계열 | DA30: 02)16:51 | DB30: 02)16:51 | DH30: 0 | DN30: 0 | DO30: 0 | DP30: N | DS30: 박승기 | DV30: 컨테이너_수출 | DW30: 5010001 | DX30: 0
B31: 159 | E31: W260602-00000390 | F31: X260602-001989 | G31: Y260602-001989 | H31: 배정 | I31: 미생성 | J31: 수출 | K31: 46177 | L31: 14:00 | M31: D713CJ044 | N31: D713CJ044 | O31: MAE | P31: 머스크 | S31: USMOB | T31: [GC]아산 3포장장 (아산YSP) | U31: HMMA | V31: 신승 | W31: 현대글로비스주식회사 | Y31: 4510 | AK31: N | AP31: N | AQ31: D | AS31: 주선 | AT31: N | AV31: 0 | AX31: N | AY31: 1011 | AZ31: ㈜이엘에스솔루션 | BC31: 수출 | BD31: 반제품 | BE31: 운송료 | BI31: N | BK31: N | BM31: AAAAAAAAA | BN31: 컨테이너 미정의 | BP31: N | BQ31: AAA | BR31: 미정의 | BT31: N | BW31: __:__ | BY31: H000_GC | CK31: N | CQ31: N | CT31: N | CV31: 0 | CY31: 계열 | DA31: 02)16:51 | DB31: 02)16:51 | DH31: 0 | DN31: 0 | DO31: 0 | DP31: N | DS31: 박승기 | DV31: 컨테이너_수출 | DW31: 5010001 | DX31: 0
B32: 158 | E32: W260602-00000389 | F32: X260602-001990 | G32: Y260602-001990 | H32: 배정 | I32: 미생성 | J32: 수출 | K32: 46177 | L32: 15:00 | M32: D713CJ044 | N32: D713CJ044 | O32: MAE | P32: 머스크 | S32: USMOB | T32: [GC]아산 3포장장 (아산YSP) | U32: HMMA | V32: 신승 | W32: 현대글로비스주식회사 | Y32: 4510 | AK32: N | AP32: N | AQ32: D | AS32: 주선 | AT32: N | AV32: 0 | AX32: N | AY32: 1011 | AZ32: ㈜이엘에스솔루션 | BC32: 수출 | BD32: 반제품 | BE32: 운송료 | BI32: N | BK32: N | BM32: AAAAAAAAA | BN32: 컨테이너 미정의 | BP32: N | BQ32: AAA | BR32: 미정의 | BT32: N | BW32: __:__ | BY32: H000_GC | CK32: N | CQ32: N | CT32: N | CV32: 0 | CY32: 계열 | DA32: 02)16:51 | DB32: 02)16:51 | DH32: 0 | DN32: 0 | DO32: 0 | DP32: N | DS32: 박승기 | DV32: 컨테이너_수출 | DW32: 5010001 | DX32: 0
