Workbook

Sheet ELS
B1: !U001,!GA1588,!MOBBEL | F1: 목록외 작성금지 | H1: KIA-실 고객사 확인 수정 | K1: ULSAN, INCHEON 실 반입코드 변경!! | O1: 목록외 작성금지 | P1: 리퍼 ,위험물 위험물리퍼 | V1: 공휴일, 위험물,중량 | Z1: 목록외 작성금지 | AC1: 20 | AF1: KR10 | AH1: 입력X | AJ1: GLAPS 포트 | AL1: 5010001 | BN1: 1 | BV1: GLAPS 코드 | BW1: 직반입 이트란스IF 또는 수기입력 ,ODCY보관은 보관소 또는 I/F | CA1: 공휴일-10 위험물-30
B2: 배차 요청일 | C2: 운송사 | D2: 배차시간 | E2: 구분(오전,오후) | F2: 포장장 | G2: 실출하지 | H2: 고객사 | I2: 선사 | J2: 사이즈 | K2: 반입지 | L2: 국가(도착항) | M2: 비고 | N2: 차량넘버 | O2: 반출지 | P2: 컨테이너 종류 (위험물,리퍼) | Q2: 20 | R2: 40 | S2: 40HC | T2: ContainerNo. | U2: SealNumber1 | V2: 할증 | W2: 편성넘버 | X2: 부킹 | Y2: 반입일 (ODCY/터미널) | Z2: ODCY(세방) 반입터미널 | AA2: ODCY 세부명칭 | AC2: 오더구분 | AD2: 선사코드 | AE2: 선사명 | AF2: 화주사 코드 | AG2: 화주사명 | AH2: 반출지(출발)코드 | AI2: 작업지(하차지)코드 | AJ2: 반입지(도착)코드 | AK2: 운송경로 코드 | AL2: 운송서비스 코드 | AM2: 운송서비스명 | AN2: 배차요청일자 | AO2: 배차요청시간 | AP2: 운송사 코드 | AQ2: 운송사명 | AR2: 부킹번호 | AS2: B/L | AT2: 컨테이너 번호 | AU2: MRN | AV2: POL | AW2: POD | AX2: 최종목적지 | AY2: ETA | AZ2: ETD | BA2: DOC | BB2: CGO | BC2: 실화주사 코드 | BD2: 실화주사명 | BE2: 포워더 코드 | BF2: 포워더명 | BG2: 선사항차 | BH2: 모선코드 | BI2: 반출기한 | BJ2: 모선항차 | BK2: 모선명 | BL2: 선적지 | BM2: 컨테이너 규격 | BN2: 컨테이너 수량 | BO2: 터미널 | BP2: 양하터미널 | BQ2: 반출예약 | BR2: 냉동 여부 | BS2: 위험물 여부 | BT2: FREE TIME | BU2: 공컨반납기한 | BV2: 반출CY | BW2: 반입CY | BX2: ODCY업체코드 | BY2: 선픽업 | BZ2: 컨사이니 | CA2: 할증 1 | CB2: 할증 2 | CC2: 할증 3 | CD2: 할증 4 | CE2: 할증 5 | CF2: 오더등록자명 | CG2: 오더등록자연락처 | CH2: 오더등록업체코드 | CI2: 오더등록자이메일 | CJ2: 통지사항 | CK2: 차량번호 | CL2: 실출하지
AC3: =$AC$1 -> 20 | AD3: =IFERROR(INDEX(GLAPS정리!$D$2:$D$50,MATCH(I3,GLAPS정리!$A$2:$A$50,0)),IFERROR(INDEX(GLAPS정리!$D$2:$D$50,MATCH(I3,GLAPS정리!$B$2:$B$50,0)),"")) | AF3: =$AF$1 -> KR10 | AI3: =VLOOKUP(F3,GLAPS정리!$G$3:$J$114,2,0) -> #N/A | AJ3: =IF(Z3="울산정일","KRONS",IF(Z3="울산신항","KRUSN",IF(OR(Z3="선광종합물류(인천여객)",Z3="인천여객(인천여객)"),"KRINF",IF(OR(Z3="선광인천보세(인천신)",Z3="한진인천(인천신)",Z3="선광인천신항(인천신)",Z3="인천더로지스(인천신)"),"KRINN",IF(OR(Z3="인천진아(인천항)",Z3="인천E1(인천항)",Z3="인천SM경인터미널(인천항)",Z3="인천항(인천항)",Z3="인천우련(인천항)",Z3="인천항8부두(인천항)"),"KRINC",VLOOKUP(K3,GLAPS정리!$BB$2:$BC$33,2,0)))))) -> #N/A | AL3: =$AL$1 -> 5010001 | AN3: =TEXT(B3,"YYYY-MM-DD") -> 1900-01-00 | AO3: =IF(E3="오전", "0800", IF(E3="오후", "1300", IF(E3="잔업", "1800", ""))) | AP3: =VLOOKUP(C3,GLAPS정리!$AX$2:$AZ$17,3,0) -> #N/A | AR3: =X3 -> 0 | AX3: =VLOOKUP(L3,GLAPS정리!$V$3:$W$180,2,0) -> #N/A | BM3: =IF(AND(Q3=1,OR(P3="",P3="위험물")), "2210", IF(AND(Q3=1,OR(P3="리퍼",P3="위험물리퍼")), "2230", IF(AND(S3=1,OR(P3="",P3="위험물")), "4510", IF(AND(S3=1,OR(P3="리퍼",P3="위험물리퍼")), "4530", IF(AND(R3=1,OR(P3="",P3="위험물")), "4210", IF(AND(R3=1,P3="리퍼"), "4230", " ")))))) | BN3: =$BN$1 -> 1 | BR3: =IF(OR(P3="리퍼",P3="위험물리퍼"),"Y","") | BS3: =IF(OR(P3="위험물",P3="위험물리퍼"),"Y","") | BV3: =VLOOKUP(O3,GLAPS정리!$BH$2:$BI$94,2,0) -> #N/A | BW3: =IF(OR(Z3="동원",Z3="세방",Z3="한타"),"",IFERROR(INDEX(GLAPS정리!$BI$2:$BI$101,MATCH(Z3,GLAPS정리!$BH$2:$BH$101,0)),"")) | BX3: =IF(Z3="","",IFERROR(VLOOKUP(Z3,GLAPS정리!$AX$2:$AZ$17,3,0),"")) | BZ3: =VLOOKUP(H3,GLAPS정리!$L$3:$O$133,2,0) -> #N/A | CA3: =IF(V3="공휴일", 10, IF(V3="야간", 20, IF(V3="위험물", 30, IF(V3="중량", 40, "")))) | CL3: =VLOOKUP(AI3,GLAPS정리!$BT$3:$BV$26,3,0) -> #N/A
AC4: =$AC$1 -> 20 | AD4: =IFERROR(INDEX(GLAPS정리!$D$2:$D$50,MATCH(I4,GLAPS정리!$A$2:$A$50,0)),IFERROR(INDEX(GLAPS정리!$D$2:$D$50,MATCH(I4,GLAPS정리!$B$2:$B$50,0)),"")) | AF4: =$AF$1 -> KR10 | AI4: =VLOOKUP(F4,GLAPS정리!$G$3:$J$114,2,0) -> #N/A | AJ4: =IF(Z4="울산정일","KRONS",IF(Z4="울산신항","KRUSN",IF(OR(Z4="선광종합물류(인천여객)",Z4="인천여객(인천여객)"),"KRINF",IF(OR(Z4="선광인천보세(인천신)",Z4="한진인천(인천신)",Z4="선광인천신항(인천신)",Z4="인천더로지스(인천신)"),"KRINN",IF(OR(Z4="인천진아(인천항)",Z4="인천E1(인천항)",Z4="인천SM경인터미널(인천항)",Z4="인천항(인천항)",Z4="인천우련(인천항)",Z4="인천항8부두(인천항)"),"KRINC",VLOOKUP(K4,GLAPS정리!$BB$2:$BC$33,2,0)))))) -> #N/A | AL4: =$AL$1 -> 5010001 | AN4: =TEXT(B4,"YYYY-MM-DD") -> 1900-01-00 | AO4: =IF(E4="오전", "0800", IF(E4="오후", "1300", IF(E4="잔업", "1800", ""))) | AP4: =VLOOKUP(C4,GLAPS정리!$AX$2:$AZ$17,3,0) -> #N/A | AR4: =X4 -> 0 | AX4: =VLOOKUP(L4,GLAPS정리!$V$3:$W$180,2,0) -> #N/A | BM4: =IF(AND(Q4=1,OR(P4="",P4="위험물")), "2210", IF(AND(Q4=1,OR(P4="리퍼",P4="위험물리퍼")), "2230", IF(AND(S4=1,OR(P4="",P4="위험물")), "4510", IF(AND(S4=1,OR(P4="리퍼",P4="위험물리퍼")), "4530", IF(AND(R4=1,OR(P4="",P4="위험물")), "4210", IF(AND(R4=1,P4="리퍼"), "4230", " ")))))) | BN4: =$BN$1 -> 1 | BR4: =IF(OR(P4="리퍼",P4="위험물리퍼"),"Y","") | BS4: =IF(OR(P4="위험물",P4="위험물리퍼"),"Y","") | BV4: =VLOOKUP(O4,GLAPS정리!$BH$2:$BI$94,2,0) -> #N/A | BW4: =IF(OR(Z4="동원",Z4="세방",Z4="한타"),"",IFERROR(INDEX(GLAPS정리!$BI$2:$BI$101,MATCH(Z4,GLAPS정리!$BH$2:$BH$101,0)),"")) | BX4: =IF(Z4="","",IFERROR(VLOOKUP(Z4,GLAPS정리!$AX$2:$AZ$17,3,0),"")) | BZ4: =VLOOKUP(H4,GLAPS정리!$L$3:$O$133,2,0) -> #N/A | CA4: =IF(V4="공휴일", 10, IF(V4="야간", 20, IF(V4="위험물", 30, IF(V4="중량", 40, "")))) | CL4: =VLOOKUP(AI4,GLAPS정리!$BT$3:$BV$26,3,0) -> #N/A
AC5: =$AC$1 -> 20 | AD5: =IFERROR(INDEX(GLAPS정리!$D$2:$D$50,MATCH(I5,GLAPS정리!$A$2:$A$50,0)),IFERROR(INDEX(GLAPS정리!$D$2:$D$50,MATCH(I5,GLAPS정리!$B$2:$B$50,0)),"")) | AF5: =$AF$1 -> KR10 | AI5: =VLOOKUP(F5,GLAPS정리!$G$3:$J$114,2,0) -> #N/A | AJ5: =IF(Z5="울산정일","KRONS",IF(Z5="울산신항","KRUSN",IF(OR(Z5="선광종합물류(인천여객)",Z5="인천여객(인천여객)"),"KRINF",IF(OR(Z5="선광인천보세(인천신)",Z5="한진인천(인천신)",Z5="선광인천신항(인천신)",Z5="인천더로지스(인천신)"),"KRINN",IF(OR(Z5="인천진아(인천항)",Z5="인천E1(인천항)",Z5="인천SM경인터미널(인천항)",Z5="인천항(인천항)",Z5="인천우련(인천항)",Z5="인천항8부두(인천항)"),"KRINC",VLOOKUP(K5,GLAPS정리!$BB$2:$BC$33,2,0)))))) -> #N/A | AL5: =$AL$1 -> 5010001 | AN5: =TEXT(B5,"YYYY-MM-DD") -> 1900-01-00 | AO5: =IF(E5="오전", "0800", IF(E5="오후", "1300", IF(E5="잔업", "1800", ""))) | AP5: =VLOOKUP(C5,GLAPS정리!$AX$2:$AZ$17,3,0) -> #N/A | AR5: =X5 -> 0 | AX5: =VLOOKUP(L5,GLAPS정리!$V$3:$W$180,2,0) -> #N/A | BM5: =IF(AND(Q5=1,OR(P5="",P5="위험물")), "2210", IF(AND(Q5=1,OR(P5="리퍼",P5="위험물리퍼")), "2230", IF(AND(S5=1,OR(P5="",P5="위험물")), "4510", IF(AND(S5=1,OR(P5="리퍼",P5="위험물리퍼")), "4530", IF(AND(R5=1,OR(P5="",P5="위험물")), "4210", IF(AND(R5=1,P5="리퍼"), "4230", " ")))))) | BN5: =$BN$1 -> 1 | BR5: =IF(OR(P5="리퍼",P5="위험물리퍼"),"Y","") | BS5: =IF(OR(P5="위험물",P5="위험물리퍼"),"Y","") | BV5: =VLOOKUP(O5,GLAPS정리!$BH$2:$BI$94,2,0) -> #N/A | BW5: =IF(OR(Z5="동원",Z5="세방",Z5="한타"),"",IFERROR(INDEX(GLAPS정리!$BI$2:$BI$101,MATCH(Z5,GLAPS정리!$BH$2:$BH$101,0)),"")) | BX5: =IF(Z5="","",IFERROR(VLOOKUP(Z5,GLAPS정리!$AX$2:$AZ$17,3,0),"")) | BZ5: =VLOOKUP(H5,GLAPS정리!$L$3:$O$133,2,0) -> #N/A | CA5: =IF(V5="공휴일", 10, IF(V5="야간", 20, IF(V5="위험물", 30, IF(V5="중량", 40, "")))) | CL5: =VLOOKUP(AI5,GLAPS정리!$BT$3:$BV$26,3,0) -> #N/A
AC6: =$AC$1 -> 20 | AD6: =IFERROR(INDEX(GLAPS정리!$D$2:$D$50,MATCH(I6,GLAPS정리!$A$2:$A$50,0)),IFERROR(INDEX(GLAPS정리!$D$2:$D$50,MATCH(I6,GLAPS정리!$B$2:$B$50,0)),"")) | AF6: =$AF$1 -> KR10 | AI6: =VLOOKUP(F6,GLAPS정리!$G$3:$J$114,2,0) -> #N/A | AJ6: =IF(Z6="울산정일","KRONS",IF(Z6="울산신항","KRUSN",IF(OR(Z6="선광종합물류(인천여객)",Z6="인천여객(인천여객)"),"KRINF",IF(OR(Z6="선광인천보세(인천신)",Z6="한진인천(인천신)",Z6="선광인천신항(인천신)",Z6="인천더로지스(인천신)"),"KRINN",IF(OR(Z6="인천진아(인천항)",Z6="인천E1(인천항)",Z6="인천SM경인터미널(인천항)",Z6="인천항(인천항)",Z6="인천우련(인천항)",Z6="인천항8부두(인천항)"),"KRINC",VLOOKUP(K6,GLAPS정리!$BB$2:$BC$33,2,0)))))) -> #N/A | AL6: =$AL$1 -> 5010001 | AN6: =TEXT(B6,"YYYY-MM-DD") -> 1900-01-00 | AO6: =IF(E6="오전", "0800", IF(E6="오후", "1300", IF(E6="잔업", "1800", ""))) | AP6: =VLOOKUP(C6,GLAPS정리!$AX$2:$AZ$17,3,0) -> #N/A | AR6: =X6 -> 0 | AX6: =VLOOKUP(L6,GLAPS정리!$V$3:$W$180,2,0) -> #N/A | BM6: =IF(AND(Q6=1,OR(P6="",P6="위험물")), "2210", IF(AND(Q6=1,OR(P6="리퍼",P6="위험물리퍼")), "2230", IF(AND(S6=1,OR(P6="",P6="위험물")), "4510", IF(AND(S6=1,OR(P6="리퍼",P6="위험물리퍼")), "4530", IF(AND(R6=1,OR(P6="",P6="위험물")), "4210", IF(AND(R6=1,P6="리퍼"), "4230", " ")))))) | BN6: =$BN$1 -> 1 | BR6: =IF(OR(P6="리퍼",P6="위험물리퍼"),"Y","") | BS6: =IF(OR(P6="위험물",P6="위험물리퍼"),"Y","") | BV6: =VLOOKUP(O6,GLAPS정리!$BH$2:$BI$94,2,0) -> #N/A | BW6: =IF(OR(Z6="동원",Z6="세방",Z6="한타"),"",IFERROR(INDEX(GLAPS정리!$BI$2:$BI$101,MATCH(Z6,GLAPS정리!$BH$2:$BH$101,0)),"")) | BX6: =IF(Z6="","",IFERROR(VLOOKUP(Z6,GLAPS정리!$AX$2:$AZ$17,3,0),"")) | BZ6: =VLOOKUP(H6,GLAPS정리!$L$3:$O$133,2,0) -> #N/A | CA6: =IF(V6="공휴일", 10, IF(V6="야간", 20, IF(V6="위험물", 30, IF(V6="중량", 40, "")))) | CL6: =VLOOKUP(AI6,GLAPS정리!$BT$3:$BV$26,3,0) -> #N/A
AC7: =$AC$1 -> 20 | AD7: =IFERROR(INDEX(GLAPS정리!$D$2:$D$50,MATCH(I7,GLAPS정리!$A$2:$A$50,0)),IFERROR(INDEX(GLAPS정리!$D$2:$D$50,MATCH(I7,GLAPS정리!$B$2:$B$50,0)),"")) | AF7: =$AF$1 -> KR10 | AI7: =VLOOKUP(F7,GLAPS정리!$G$3:$J$114,2,0) -> #N/A | AJ7: =IF(Z7="울산정일","KRONS",IF(Z7="울산신항","KRUSN",IF(OR(Z7="선광종합물류(인천여객)",Z7="인천여객(인천여객)"),"KRINF",IF(OR(Z7="선광인천보세(인천신)",Z7="한진인천(인천신)",Z7="선광인천신항(인천신)",Z7="인천더로지스(인천신)"),"KRINN",IF(OR(Z7="인천진아(인천항)",Z7="인천E1(인천항)",Z7="인천SM경인터미널(인천항)",Z7="인천항(인천항)",Z7="인천우련(인천항)",Z7="인천항8부두(인천항)"),"KRINC",VLOOKUP(K7,GLAPS정리!$BB$2:$BC$33,2,0)))))) -> #N/A | AL7: =$AL$1 -> 5010001 | AN7: =TEXT(B7,"YYYY-MM-DD") -> 1900-01-00 | AO7: =IF(E7="오전", "0800", IF(E7="오후", "1300", IF(E7="잔업", "1800", ""))) | AP7: =VLOOKUP(C7,GLAPS정리!$AX$2:$AZ$17,3,0) -> #N/A | AR7: =X7 -> 0 | AX7: =VLOOKUP(L7,GLAPS정리!$V$3:$W$180,2,0) -> #N/A | BM7: =IF(AND(Q7=1,OR(P7="",P7="위험물")), "2210", IF(AND(Q7=1,OR(P7="리퍼",P7="위험물리퍼")), "2230", IF(AND(S7=1,OR(P7="",P7="위험물")), "4510", IF(AND(S7=1,OR(P7="리퍼",P7="위험물리퍼")), "4530", IF(AND(R7=1,OR(P7="",P7="위험물")), "4210", IF(AND(R7=1,P7="리퍼"), "4230", " ")))))) | BN7: =$BN$1 -> 1 | BR7: =IF(OR(P7="리퍼",P7="위험물리퍼"),"Y","") | BS7: =IF(OR(P7="위험물",P7="위험물리퍼"),"Y","") | BV7: =VLOOKUP(O7,GLAPS정리!$BH$2:$BI$94,2,0) -> #N/A | BW7: =IF(OR(Z7="동원",Z7="세방",Z7="한타"),"",IFERROR(INDEX(GLAPS정리!$BI$2:$BI$101,MATCH(Z7,GLAPS정리!$BH$2:$BH$101,0)),"")) | BX7: =IF(Z7="","",IFERROR(VLOOKUP(Z7,GLAPS정리!$AX$2:$AZ$17,3,0),"")) | BZ7: =VLOOKUP(H7,GLAPS정리!$L$3:$O$133,2,0) -> #N/A | CA7: =IF(V7="공휴일", 10, IF(V7="야간", 20, IF(V7="위험물", 30, IF(V7="중량", 40, "")))) | CL7: =VLOOKUP(AI7,GLAPS정리!$BT$3:$BV$26,3,0) -> #N/A
AC8: =$AC$1 -> 20 | AD8: =IFERROR(INDEX(GLAPS정리!$D$2:$D$50,MATCH(I8,GLAPS정리!$A$2:$A$50,0)),IFERROR(INDEX(GLAPS정리!$D$2:$D$50,MATCH(I8,GLAPS정리!$B$2:$B$50,0)),"")) | AF8: =$AF$1 -> KR10 | AI8: =VLOOKUP(F8,GLAPS정리!$G$3:$J$114,2,0) -> #N/A | AJ8: =IF(Z8="울산정일","KRONS",IF(Z8="울산신항","KRUSN",IF(OR(Z8="선광종합물류(인천여객)",Z8="인천여객(인천여객)"),"KRINF",IF(OR(Z8="선광인천보세(인천신)",Z8="한진인천(인천신)",Z8="선광인천신항(인천신)",Z8="인천더로지스(인천신)"),"KRINN",IF(OR(Z8="인천진아(인천항)",Z8="인천E1(인천항)",Z8="인천SM경인터미널(인천항)",Z8="인천항(인천항)",Z8="인천우련(인천항)",Z8="인천항8부두(인천항)"),"KRINC",VLOOKUP(K8,GLAPS정리!$BB$2:$BC$33,2,0)))))) -> #N/A | AL8: =$AL$1 -> 5010001 | AN8: =TEXT(B8,"YYYY-MM-DD") -> 1900-01-00 | AO8: =IF(E8="오전", "0800", IF(E8="오후", "1300", IF(E8="잔업", "1800", ""))) | AP8: =VLOOKUP(C8,GLAPS정리!$AX$2:$AZ$17,3,0) -> #N/A | AR8: =X8 -> 0 | AX8: =VLOOKUP(L8,GLAPS정리!$V$3:$W$180,2,0) -> #N/A | BM8: =IF(AND(Q8=1,OR(P8="",P8="위험물")), "2210", IF(AND(Q8=1,OR(P8="리퍼",P8="위험물리퍼")), "2230", IF(AND(S8=1,OR(P8="",P8="위험물")), "4510", IF(AND(S8=1,OR(P8="리퍼",P8="위험물리퍼")), "4530", IF(AND(R8=1,OR(P8="",P8="위험물")), "4210", IF(AND(R8=1,P8="리퍼"), "4230", " ")))))) | BN8: =$BN$1 -> 1 | BR8: =IF(OR(P8="리퍼",P8="위험물리퍼"),"Y","") | BS8: =IF(OR(P8="위험물",P8="위험물리퍼"),"Y","") | BV8: =VLOOKUP(O8,GLAPS정리!$BH$2:$BI$94,2,0) -> #N/A | BW8: =IF(OR(Z8="동원",Z8="세방",Z8="한타"),"",IFERROR(INDEX(GLAPS정리!$BI$2:$BI$101,MATCH(Z8,GLAPS정리!$BH$2:$BH$101,0)),"")) | BX8: =IF(Z8="","",IFERROR(VLOOKUP(Z8,GLAPS정리!$AX$2:$AZ$17,3,0),"")) | BZ8: =VLOOKUP(H8,GLAPS정리!$L$3:$O$133,2,0) -> #N/A | CA8: =IF(V8="공휴일", 10, IF(V8="야간", 20, IF(V8="위험물", 30, IF(V8="중량", 40, "")))) | CL8: =VLOOKUP(AI8,GLAPS정리!$BT$3:$BV$26,3,0) -> #N/A
AC9: =$AC$1 -> 20 | AD9: =IFERROR(INDEX(GLAPS정리!$D$2:$D$50,MATCH(I9,GLAPS정리!$A$2:$A$50,0)),IFERROR(INDEX(GLAPS정리!$D$2:$D$50,MATCH(I9,GLAPS정리!$B$2:$B$50,0)),"")) | AF9: =$AF$1 -> KR10 | AI9: =VLOOKUP(F9,GLAPS정리!$G$3:$J$114,2,0) -> #N/A | AJ9: =IF(Z9="울산정일","KRONS",IF(Z9="울산신항","KRUSN",IF(OR(Z9="선광종합물류(인천여객)",Z9="인천여객(인천여객)"),"KRINF",IF(OR(Z9="선광인천보세(인천신)",Z9="한진인천(인천신)",Z9="선광인천신항(인천신)",Z9="인천더로지스(인천신)"),"KRINN",IF(OR(Z9="인천진아(인천항)",Z9="인천E1(인천항)",Z9="인천SM경인터미널(인천항)",Z9="인천항(인천항)",Z9="인천우련(인천항)",Z9="인천항8부두(인천항)"),"KRINC",VLOOKUP(K9,GLAPS정리!$BB$2:$BC$33,2,0)))))) -> #N/A | AL9: =$AL$1 -> 5010001 | AN9: =TEXT(B9,"YYYY-MM-DD") -> 1900-01-00 | AO9: =IF(E9="오전", "0800", IF(E9="오후", "1300", IF(E9="잔업", "1800", ""))) | AP9: =VLOOKUP(C9,GLAPS정리!$AX$2:$AZ$17,3,0) -> #N/A | AR9: =X9 -> 0 | AX9: =VLOOKUP(L9,GLAPS정리!$V$3:$W$180,2,0) -> #N/A | BM9: =IF(AND(Q9=1,OR(P9="",P9="위험물")), "2210", IF(AND(Q9=1,OR(P9="리퍼",P9="위험물리퍼")), "2230", IF(AND(S9=1,OR(P9="",P9="위험물")), "4510", IF(AND(S9=1,OR(P9="리퍼",P9="위험물리퍼")), "4530", IF(AND(R9=1,OR(P9="",P9="위험물")), "4210", IF(AND(R9=1,P9="리퍼"), "4230", " ")))))) | BN9: =$BN$1 -> 1 | BR9: =IF(OR(P9="리퍼",P9="위험물리퍼"),"Y","") | BS9: =IF(OR(P9="위험물",P9="위험물리퍼"),"Y","") | BV9: =VLOOKUP(O9,GLAPS정리!$BH$2:$BI$94,2,0) -> #N/A | BW9: =IF(OR(Z9="동원",Z9="세방",Z9="한타"),"",IFERROR(INDEX(GLAPS정리!$BI$2:$BI$101,MATCH(Z9,GLAPS정리!$BH$2:$BH$101,0)),"")) | BX9: =IF(Z9="","",IFERROR(VLOOKUP(Z9,GLAPS정리!$AX$2:$AZ$17,3,0),"")) | BZ9: =VLOOKUP(H9,GLAPS정리!$L$3:$O$133,2,0) -> #N/A | CA9: =IF(V9="공휴일", 10, IF(V9="야간", 20, IF(V9="위험물", 30, IF(V9="중량", 40, "")))) | CL9: =VLOOKUP(AI9,GLAPS정리!$BT$3:$BV$26,3,0) -> #N/A
AC10: =$AC$1 -> 20 | AD10: =IFERROR(INDEX(GLAPS정리!$D$2:$D$50,MATCH(I10,GLAPS정리!$A$2:$A$50,0)),IFERROR(INDEX(GLAPS정리!$D$2:$D$50,MATCH(I10,GLAPS정리!$B$2:$B$50,0)),"")) | AF10: =$AF$1 -> KR10 | AI10: =VLOOKUP(F10,GLAPS정리!$G$3:$J$114,2,0) -> #N/A | AJ10: =IF(Z10="울산정일","KRONS",IF(Z10="울산신항","KRUSN",IF(OR(Z10="선광종합물류(인천여객)",Z10="인천여객(인천여객)"),"KRINF",IF(OR(Z10="선광인천보세(인천신)",Z10="한진인천(인천신)",Z10="선광인천신항(인천신)",Z10="인천더로지스(인천신)"),"KRINN",IF(OR(Z10="인천진아(인천항)",Z10="인천E1(인천항)",Z10="인천SM경인터미널(인천항)",Z10="인천항(인천항)",Z10="인천우련(인천항)",Z10="인천항8부두(인천항)"),"KRINC",VLOOKUP(K10,GLAPS정리!$BB$2:$BC$33,2,0)))))) -> #N/A | AL10: =$AL$1 -> 5010001 | AN10: =TEXT(B10,"YYYY-MM-DD") -> 1900-01-00 | AO10: =IF(E10="오전", "0800", IF(E10="오후", "1300", IF(E10="잔업", "1800", ""))) | AP10: =VLOOKUP(C10,GLAPS정리!$AX$2:$AZ$17,3,0) -> #N/A | AR10: =X10 -> 0 | AX10: =VLOOKUP(L10,GLAPS정리!$V$3:$W$180,2,0) -> #N/A | BM10: =IF(AND(Q10=1,OR(P10="",P10="위험물")), "2210", IF(AND(Q10=1,OR(P10="리퍼",P10="위험물리퍼")), "2230", IF(AND(S10=1,OR(P10="",P10="위험물")), "4510", IF(AND(S10=1,OR(P10="리퍼",P10="위험물리퍼")), "4530", IF(AND(R10=1,OR(P10="",P10="위험물")), "4210", IF(AND(R10=1,P10="리퍼"), "4230", " ")))))) | BN10: =$BN$1 -> 1 | BR10: =IF(OR(P10="리퍼",P10="위험물리퍼"),"Y","") | BS10: =IF(OR(P10="위험물",P10="위험물리퍼"),"Y","") | BV10: =VLOOKUP(O10,GLAPS정리!$BH$2:$BI$94,2,0) -> #N/A | BW10: =IF(OR(Z10="동원",Z10="세방",Z10="한타"),"",IFERROR(INDEX(GLAPS정리!$BI$2:$BI$101,MATCH(Z10,GLAPS정리!$BH$2:$BH$101,0)),"")) | BX10: =IF(Z10="","",IFERROR(VLOOKUP(Z10,GLAPS정리!$AX$2:$AZ$17,3,0),"")) | BZ10: =VLOOKUP(H10,GLAPS정리!$L$3:$O$133,2,0) -> #N/A | CA10: =IF(V10="공휴일", 10, IF(V10="야간", 20, IF(V10="위험물", 30, IF(V10="중량", 40, "")))) | CL10: =VLOOKUP(AI10,GLAPS정리!$BT$3:$BV$26,3,0) -> #N/A
AC11: =$AC$1 -> 20 | AD11: =IFERROR(INDEX(GLAPS정리!$D$2:$D$50,MATCH(I11,GLAPS정리!$A$2:$A$50,0)),IFERROR(INDEX(GLAPS정리!$D$2:$D$50,MATCH(I11,GLAPS정리!$B$2:$B$50,0)),"")) | AF11: =$AF$1 -> KR10 | AI11: =VLOOKUP(F11,GLAPS정리!$G$3:$J$114,2,0) -> #N/A | AJ11: =IF(Z11="울산정일","KRONS",IF(Z11="울산신항","KRUSN",IF(OR(Z11="선광종합물류(인천여객)",Z11="인천여객(인천여객)"),"KRINF",IF(OR(Z11="선광인천보세(인천신)",Z11="한진인천(인천신)",Z11="선광인천신항(인천신)",Z11="인천더로지스(인천신)"),"KRINN",IF(OR(Z11="인천진아(인천항)",Z11="인천E1(인천항)",Z11="인천SM경인터미널(인천항)",Z11="인천항(인천항)",Z11="인천우련(인천항)",Z11="인천항8부두(인천항)"),"KRINC",VLOOKUP(K11,GLAPS정리!$BB$2:$BC$33,2,0)))))) -> #N/A | AL11: =$AL$1 -> 5010001 | AN11: =TEXT(B11,"YYYY-MM-DD") -> 1900-01-00 | AO11: =IF(E11="오전", "0800", IF(E11="오후", "1300", IF(E11="잔업", "1800", ""))) | AP11: =VLOOKUP(C11,GLAPS정리!$AX$2:$AZ$17,3,0) -> #N/A | AR11: =X11 -> 0 | AX11: =VLOOKUP(L11,GLAPS정리!$V$3:$W$180,2,0) -> #N/A | BM11: =IF(AND(Q11=1,OR(P11="",P11="위험물")), "2210", IF(AND(Q11=1,OR(P11="리퍼",P11="위험물리퍼")), "2230", IF(AND(S11=1,OR(P11="",P11="위험물")), "4510", IF(AND(S11=1,OR(P11="리퍼",P11="위험물리퍼")), "4530", IF(AND(R11=1,OR(P11="",P11="위험물")), "4210", IF(AND(R11=1,P11="리퍼"), "4230", " ")))))) | BN11: =$BN$1 -> 1 | BR11: =IF(OR(P11="리퍼",P11="위험물리퍼"),"Y","") | BS11: =IF(OR(P11="위험물",P11="위험물리퍼"),"Y","") | BV11: =VLOOKUP(O11,GLAPS정리!$BH$2:$BI$94,2,0) -> #N/A | BW11: =IF(OR(Z11="동원",Z11="세방",Z11="한타"),"",IFERROR(INDEX(GLAPS정리!$BI$2:$BI$101,MATCH(Z11,GLAPS정리!$BH$2:$BH$101,0)),"")) | BX11: =IF(Z11="","",IFERROR(VLOOKUP(Z11,GLAPS정리!$AX$2:$AZ$17,3,0),"")) | BZ11: =VLOOKUP(H11,GLAPS정리!$L$3:$O$133,2,0) -> #N/A | CA11: =IF(V11="공휴일", 10, IF(V11="야간", 20, IF(V11="위험물", 30, IF(V11="중량", 40, "")))) | CL11: =VLOOKUP(AI11,GLAPS정리!$BT$3:$BV$26,3,0) -> #N/A
AC12: =$AC$1 -> 20 | AD12: =IFERROR(INDEX(GLAPS정리!$D$2:$D$50,MATCH(I12,GLAPS정리!$A$2:$A$50,0)),IFERROR(INDEX(GLAPS정리!$D$2:$D$50,MATCH(I12,GLAPS정리!$B$2:$B$50,0)),"")) | AF12: =$AF$1 -> KR10 | AI12: =VLOOKUP(F12,GLAPS정리!$G$3:$J$114,2,0) -> #N/A | AJ12: =IF(Z12="울산정일","KRONS",IF(Z12="울산신항","KRUSN",IF(OR(Z12="선광종합물류(인천여객)",Z12="인천여객(인천여객)"),"KRINF",IF(OR(Z12="선광인천보세(인천신)",Z12="한진인천(인천신)",Z12="선광인천신항(인천신)",Z12="인천더로지스(인천신)"),"KRINN",IF(OR(Z12="인천진아(인천항)",Z12="인천E1(인천항)",Z12="인천SM경인터미널(인천항)",Z12="인천항(인천항)",Z12="인천우련(인천항)",Z12="인천항8부두(인천항)"),"KRINC",VLOOKUP(K12,GLAPS정리!$BB$2:$BC$33,2,0)))))) -> #N/A | AL12: =$AL$1 -> 5010001 | AN12: =TEXT(B12,"YYYY-MM-DD") -> 1900-01-00 | AO12: =IF(E12="오전", "0800", IF(E12="오후", "1300", IF(E12="잔업", "1800", ""))) | AP12: =VLOOKUP(C12,GLAPS정리!$AX$2:$AZ$17,3,0) -> #N/A | AR12: =X12 -> 0 | AX12: =VLOOKUP(L12,GLAPS정리!$V$3:$W$180,2,0) -> #N/A | BM12: =IF(AND(Q12=1,OR(P12="",P12="위험물")), "2210", IF(AND(Q12=1,OR(P12="리퍼",P12="위험물리퍼")), "2230", IF(AND(S12=1,OR(P12="",P12="위험물")), "4510", IF(AND(S12=1,OR(P12="리퍼",P12="위험물리퍼")), "4530", IF(AND(R12=1,OR(P12="",P12="위험물")), "4210", IF(AND(R12=1,P12="리퍼"), "4230", " ")))))) | BN12: =$BN$1 -> 1 | BR12: =IF(OR(P12="리퍼",P12="위험물리퍼"),"Y","") | BS12: =IF(OR(P12="위험물",P12="위험물리퍼"),"Y","") | BV12: =VLOOKUP(O12,GLAPS정리!$BH$2:$BI$94,2,0) -> #N/A | BW12: =IF(OR(Z12="동원",Z12="세방",Z12="한타"),"",IFERROR(INDEX(GLAPS정리!$BI$2:$BI$101,MATCH(Z12,GLAPS정리!$BH$2:$BH$101,0)),"")) | BX12: =IF(Z12="","",IFERROR(VLOOKUP(Z12,GLAPS정리!$AX$2:$AZ$17,3,0),"")) | BZ12: =VLOOKUP(H12,GLAPS정리!$L$3:$O$133,2,0) -> #N/A | CA12: =IF(V12="공휴일", 10, IF(V12="야간", 20, IF(V12="위험물", 30, IF(V12="중량", 40, "")))) | CL12: =VLOOKUP(AI12,GLAPS정리!$BT$3:$BV$26,3,0) -> #N/A
AC13: =$AC$1 -> 20 | AD13: =IFERROR(INDEX(GLAPS정리!$D$2:$D$50,MATCH(I13,GLAPS정리!$A$2:$A$50,0)),IFERROR(INDEX(GLAPS정리!$D$2:$D$50,MATCH(I13,GLAPS정리!$B$2:$B$50,0)),"")) | AF13: =$AF$1 -> KR10 | AI13: =VLOOKUP(F13,GLAPS정리!$G$3:$J$114,2,0) -> #N/A | AJ13: =IF(Z13="울산정일","KRONS",IF(Z13="울산신항","KRUSN",IF(OR(Z13="선광종합물류(인천여객)",Z13="인천여객(인천여객)"),"KRINF",IF(OR(Z13="선광인천보세(인천신)",Z13="한진인천(인천신)",Z13="선광인천신항(인천신)",Z13="인천더로지스(인천신)"),"KRINN",IF(OR(Z13="인천진아(인천항)",Z13="인천E1(인천항)",Z13="인천SM경인터미널(인천항)",Z13="인천항(인천항)",Z13="인천우련(인천항)",Z13="인천항8부두(인천항)"),"KRINC",VLOOKUP(K13,GLAPS정리!$BB$2:$BC$33,2,0)))))) -> #N/A | AL13: =$AL$1 -> 5010001 | AN13: =TEXT(B13,"YYYY-MM-DD") -> 1900-01-00 | AO13: =IF(E13="오전", "0800", IF(E13="오후", "1300", IF(E13="잔업", "1800", ""))) | AP13: =VLOOKUP(C13,GLAPS정리!$AX$2:$AZ$17,3,0) -> #N/A | AR13: =X13 -> 0 | AX13: =VLOOKUP(L13,GLAPS정리!$V$3:$W$180,2,0) -> #N/A | BM13: =IF(AND(Q13=1,OR(P13="",P13="위험물")), "2210", IF(AND(Q13=1,OR(P13="리퍼",P13="위험물리퍼")), "2230", IF(AND(S13=1,OR(P13="",P13="위험물")), "4510", IF(AND(S13=1,OR(P13="리퍼",P13="위험물리퍼")), "4530", IF(AND(R13=1,OR(P13="",P13="위험물")), "4210", IF(AND(R13=1,P13="리퍼"), "4230", " ")))))) | BN13: =$BN$1 -> 1 | BR13: =IF(OR(P13="리퍼",P13="위험물리퍼"),"Y","") | BS13: =IF(OR(P13="위험물",P13="위험물리퍼"),"Y","") | BV13: =VLOOKUP(O13,GLAPS정리!$BH$2:$BI$94,2,0) -> #N/A | BW13: =IF(OR(Z13="동원",Z13="세방",Z13="한타"),"",IFERROR(INDEX(GLAPS정리!$BI$2:$BI$101,MATCH(Z13,GLAPS정리!$BH$2:$BH$101,0)),"")) | BX13: =IF(Z13="","",IFERROR(VLOOKUP(Z13,GLAPS정리!$AX$2:$AZ$17,3,0),"")) | BZ13: =VLOOKUP(H13,GLAPS정리!$L$3:$O$133,2,0) -> #N/A | CA13: =IF(V13="공휴일", 10, IF(V13="야간", 20, IF(V13="위험물", 30, IF(V13="중량", 40, "")))) | CL13: =VLOOKUP(AI13,GLAPS정리!$BT$3:$BV$26,3,0) -> #N/A
AC14: =$AC$1 -> 20 | AD14: =IFERROR(INDEX(GLAPS정리!$D$2:$D$50,MATCH(I14,GLAPS정리!$A$2:$A$50,0)),IFERROR(INDEX(GLAPS정리!$D$2:$D$50,MATCH(I14,GLAPS정리!$B$2:$B$50,0)),"")) | AF14: =$AF$1 -> KR10 | AI14: =VLOOKUP(F14,GLAPS정리!$G$3:$J$114,2,0) -> #N/A | AJ14: =IF(Z14="울산정일","KRONS",IF(Z14="울산신항","KRUSN",IF(OR(Z14="선광종합물류(인천여객)",Z14="인천여객(인천여객)"),"KRINF",IF(OR(Z14="선광인천보세(인천신)",Z14="한진인천(인천신)",Z14="선광인천신항(인천신)",Z14="인천더로지스(인천신)"),"KRINN",IF(OR(Z14="인천진아(인천항)",Z14="인천E1(인천항)",Z14="인천SM경인터미널(인천항)",Z14="인천항(인천항)",Z14="인천우련(인천항)",Z14="인천항8부두(인천항)"),"KRINC",VLOOKUP(K14,GLAPS정리!$BB$2:$BC$33,2,0)))))) -> #N/A | AL14: =$AL$1 -> 5010001 | AN14: =TEXT(B14,"YYYY-MM-DD") -> 1900-01-00 | AO14: =IF(E14="오전", "0800", IF(E14="오후", "1300", IF(E14="잔업", "1800", ""))) | AP14: =VLOOKUP(C14,GLAPS정리!$AX$2:$AZ$17,3,0) -> #N/A | AR14: =X14 -> 0 | AX14: =VLOOKUP(L14,GLAPS정리!$V$3:$W$180,2,0) -> #N/A | BM14: =IF(AND(Q14=1,OR(P14="",P14="위험물")), "2210", IF(AND(Q14=1,OR(P14="리퍼",P14="위험물리퍼")), "2230", IF(AND(S14=1,OR(P14="",P14="위험물")), "4510", IF(AND(S14=1,OR(P14="리퍼",P14="위험물리퍼")), "4530", IF(AND(R14=1,OR(P14="",P14="위험물")), "4210", IF(AND(R14=1,P14="리퍼"), "4230", " ")))))) | BN14: =$BN$1 -> 1 | BR14: =IF(OR(P14="리퍼",P14="위험물리퍼"),"Y","") | BS14: =IF(OR(P14="위험물",P14="위험물리퍼"),"Y","") | BV14: =VLOOKUP(O14,GLAPS정리!$BH$2:$BI$94,2,0) -> #N/A | BW14: =IF(OR(Z14="동원",Z14="세방",Z14="한타"),"",IFERROR(INDEX(GLAPS정리!$BI$2:$BI$101,MATCH(Z14,GLAPS정리!$BH$2:$BH$101,0)),"")) | BX14: =IF(Z14="","",IFERROR(VLOOKUP(Z14,GLAPS정리!$AX$2:$AZ$17,3,0),"")) | BZ14: =VLOOKUP(H14,GLAPS정리!$L$3:$O$133,2,0) -> #N/A | CA14: =IF(V14="공휴일", 10, IF(V14="야간", 20, IF(V14="위험물", 30, IF(V14="중량", 40, "")))) | CL14: =VLOOKUP(AI14,GLAPS정리!$BT$3:$BV$26,3,0) -> #N/A
... AC130: =$AC$1 -> 20 | AD130: =IFERROR(INDEX(GLAPS정리!$D$2:$D$50,MATCH(I130,GLAPS정리!$A$2:$A$50,0)),IFERROR(INDEX(GLAPS정리!$D$2:$D$50,MATCH(I130,GLAPS정리!$B$2:$B$50,0)),"")) | AF130: =$AF$1 -> KR10 | AI130: =VLOOKUP(F130,GLAPS정리!$G$3:$J$114,2,0) -> #N/A | AJ130: =IF(Z130="울산정일","KRONS",IF(Z130="울산신항","KRUSN",IF(OR(Z130="선광종합물류(인천여객)",Z130="인천여객(인천여객)"),"KRINF",IF(OR(Z130="선광인천보세(인천신)",Z130="한진인천(인천신)",Z130="선광인천신항(인천신)",Z130="인천더로지스(인천신)"),"KRINN",IF(OR(Z130="인천진아(인천항)",Z130="인천E1(인천항)",Z130="인천SM경인터미널(인천항)",Z130="인천항(인천항)",Z130="인천우련(인천항)",Z130="인천항8부두(인천항)"),"KRINC",VLOOKUP(K130,GLAPS정리!$BB$2:$BC$33,2,0)))))) -> #N/A | AL130: =$AL$1 -> 5010001 | AN130: =TEXT(B130,"YYYY-MM-DD") -> 1900-01-00 | AO130: =IF(E130="오전", "0800", IF(E130="오후", "1300", IF(E130="잔업", "1800", ""))) | AP130: =VLOOKUP(C130,GLAPS정리!$AX$2:$AZ$17,3,0) -> #N/A | AR130: =X130 -> 0 | AX130: =VLOOKUP(L130,GLAPS정리!$V$3:$W$180,2,0) -> #N/A | BM130: =IF(AND(Q130=1,OR(P130="",P130="위험물")), "2210", IF(AND(Q130=1,OR(P130="리퍼",P130="위험물리퍼")), "2230", IF(AND(S130=1,OR(P130="",P130="위험물")), "4510", IF(AND(S130=1,OR(P130="리퍼",P130="위험물리퍼")), "4530", IF(AND(R130=1,OR(P130="",P130="위험물")), "4210", IF(AND(R130=1,P130="리퍼"), "4230", " ")))))) | BN130: =$BN$1 -> 1 | BR130: =IF(OR(P130="리퍼",P130="위험물리퍼"),"Y","") | BS130: =IF(OR(P130="위험물",P130="위험물리퍼"),"Y","") | BV130: =VLOOKUP(O130,GLAPS정리!$BH$2:$BI$94,2,0) -> #N/A | BW130: =IF(OR(Z130="동원",Z130="세방",Z130="한타"),"",IFERROR(INDEX(GLAPS정리!$BI$2:$BI$101,MATCH(Z130,GLAPS정리!$BH$2:$BH$101,0)),"")) | BX130: =IF(Z130="","",IFERROR(VLOOKUP(Z130,GLAPS정리!$AX$2:$AZ$17,3,0),"")) | BZ130: =VLOOKUP(H130,GLAPS정리!$L$3:$O$133,2,0) -> #N/A | CA130: =IF(V130="공휴일", 10, IF(V130="야간", 20, IF(V130="위험물", 30, IF(V130="중량", 40, "")))) | CL130: =VLOOKUP(AI130,GLAPS정리!$BT$3:$BV$26,3,0) -> #N/A
Q131: =IF(J131="20 FeeT",1,"") | R131: =IF(J131="40 Feet N",1,"") | S131: =IF(J131="40 Feet H",1,"") | AC131: =$AC$1 -> 20 | AD131: =IFERROR(INDEX(GLAPS정리!$D$2:$D$50,MATCH(I131,GLAPS정리!$A$2:$A$50,0)),IFERROR(INDEX(GLAPS정리!$D$2:$D$50,MATCH(I131,GLAPS정리!$B$2:$B$50,0)),"")) | AF131: =$AF$1 -> KR10 | AI131: =VLOOKUP(F131,GLAPS정리!$G$3:$J$114,2,0) -> #N/A | AJ131: =IF(Z131="울산정일","KRONS",IF(Z131="울산신항","KRUSN",IF(OR(Z131="선광종합물류(인천여객)",Z131="인천여객(인천여객)"),"KRINF",IF(OR(Z131="선광인천보세(인천신)",Z131="한진인천(인천신)",Z131="선광인천신항(인천신)",Z131="인천더로지스(인천신)"),"KRINN",IF(OR(Z131="인천진아(인천항)",Z131="인천E1(인천항)",Z131="인천SM경인터미널(인천항)",Z131="인천항(인천항)",Z131="인천우련(인천항)",Z131="인천항8부두(인천항)"),"KRINC",VLOOKUP(K131,GLAPS정리!$BB$2:$BC$33,2,0)))))) -> #N/A | AL131: =$AL$1 -> 5010001 | AN131: =TEXT(B131,"YYYY-MM-DD") -> 1900-01-00 | AO131: =IF(E131="오전", "0800", IF(E131="오후", "1300", IF(E131="잔업", "1800", ""))) | AP131: =VLOOKUP(C131,GLAPS정리!$AX$2:$AZ$17,3,0) -> #N/A | AR131: =X131 -> 0 | AX131: =VLOOKUP(L131,GLAPS정리!$V$3:$W$180,2,0) -> #N/A | BM131: =IF(AND(Q131=1,OR(P131="",P131="위험물")), "2210", IF(AND(Q131=1,OR(P131="리퍼",P131="위험물리퍼")), "2230", IF(AND(S131=1,OR(P131="",P131="위험물")), "4510", IF(AND(S131=1,OR(P131="리퍼",P131="위험물리퍼")), "4530", IF(AND(R131=1,OR(P131="",P131="위험물")), "4210", IF(AND(R131=1,P131="리퍼"), "4230", " ")))))) | BN131: =$BN$1 -> 1 | BR131: =IF(OR(P131="리퍼",P131="위험물리퍼"),"Y","") | BS131: =IF(OR(P131="위험물",P131="위험물리퍼"),"Y","") | BV131: =VLOOKUP(O131,GLAPS정리!$BH$2:$BI$94,2,0) -> #N/A | BW131: =IF(OR(Z131="동원",Z131="세방",Z131="한타"),"",IFERROR(INDEX(GLAPS정리!$BI$2:$BI$101,MATCH(Z131,GLAPS정리!$BH$2:$BH$101,0)),"")) | BX131: =IF(Z131="","",IFERROR(VLOOKUP(Z131,GLAPS정리!$AX$2:$AZ$17,3,0),"")) | BZ131: =VLOOKUP(H131,GLAPS정리!$L$3:$O$133,2,0) -> #N/A | CA131: =IF(V131="공휴일", 10, IF(V131="야간", 20, IF(V131="위험물", 30, IF(V131="중량", 40, "")))) | CL131: =VLOOKUP(AI131,GLAPS정리!$BT$3:$BV$26,3,0) -> #N/A
Q132: =IF(J132="20 FeeT",1,"") | R132: =IF(J132="40 Feet N",1,"") | S132: =IF(J132="40 Feet H",1,"") | AC132: =$AC$1 -> 20 | AD132: =IFERROR(INDEX(GLAPS정리!$D$2:$D$50,MATCH(I132,GLAPS정리!$A$2:$A$50,0)),IFERROR(INDEX(GLAPS정리!$D$2:$D$50,MATCH(I132,GLAPS정리!$B$2:$B$50,0)),"")) | AF132: =$AF$1 -> KR10 | AI132: =VLOOKUP(F132,GLAPS정리!$G$3:$J$114,2,0) -> #N/A | AJ132: =IF(Z132="울산정일","KRONS",IF(Z132="울산신항","KRUSN",IF(OR(Z132="선광종합물류(인천여객)",Z132="인천여객(인천여객)"),"KRINF",IF(OR(Z132="선광인천보세(인천신)",Z132="한진인천(인천신)",Z132="선광인천신항(인천신)",Z132="인천더로지스(인천신)"),"KRINN",IF(OR(Z132="인천진아(인천항)",Z132="인천E1(인천항)",Z132="인천SM경인터미널(인천항)",Z132="인천항(인천항)",Z132="인천우련(인천항)",Z132="인천항8부두(인천항)"),"KRINC",VLOOKUP(K132,GLAPS정리!$BB$2:$BC$33,2,0)))))) -> #N/A | AL132: =$AL$1 -> 5010001 | AN132: =TEXT(B132,"YYYY-MM-DD") -> 1900-01-00 | AO132: =IF(E132="오전", "0800", IF(E132="오후", "1300", IF(E132="잔업", "1800", ""))) | AP132: =VLOOKUP(C132,GLAPS정리!$AX$2:$AZ$17,3,0) -> #N/A | AR132: =X132 -> 0 | AX132: =VLOOKUP(L132,GLAPS정리!$V$3:$W$180,2,0) -> #N/A | BM132: =IF(AND(Q132=1,OR(P132="",P132="위험물")), "2210", IF(AND(Q132=1,OR(P132="리퍼",P132="위험물리퍼")), "2230", IF(AND(S132=1,OR(P132="",P132="위험물")), "4510", IF(AND(S132=1,OR(P132="리퍼",P132="위험물리퍼")), "4530", IF(AND(R132=1,OR(P132="",P132="위험물")), "4210", IF(AND(R132=1,P132="리퍼"), "4230", " ")))))) | BN132: =$BN$1 -> 1 | BR132: =IF(OR(P132="리퍼",P132="위험물리퍼"),"Y","") | BS132: =IF(OR(P132="위험물",P132="위험물리퍼"),"Y","") | BV132: =VLOOKUP(O132,GLAPS정리!$BH$2:$BI$94,2,0) -> #N/A | BW132: =IF(OR(Z132="동원",Z132="세방",Z132="한타"),"",IFERROR(INDEX(GLAPS정리!$BI$2:$BI$101,MATCH(Z132,GLAPS정리!$BH$2:$BH$101,0)),"")) | BX132: =IF(Z132="","",IFERROR(VLOOKUP(Z132,GLAPS정리!$AX$2:$AZ$17,3,0),"")) | BZ132: =VLOOKUP(H132,GLAPS정리!$L$3:$O$133,2,0) -> #N/A | CA132: =IF(V132="공휴일", 10, IF(V132="야간", 20, IF(V132="위험물", 30, IF(V132="중량", 40, "")))) | CL132: =VLOOKUP(AI132,GLAPS정리!$BT$3:$BV$26,3,0) -> #N/A
Q133: =IF(J133="20 FeeT",1,"") | R133: =IF(J133="40 Feet N",1,"") | S133: =IF(J133="40 Feet H",1,"") | AC133: =$AC$1 -> 20 | AD133: =IFERROR(INDEX(GLAPS정리!$D$2:$D$50,MATCH(I133,GLAPS정리!$A$2:$A$50,0)),IFERROR(INDEX(GLAPS정리!$D$2:$D$50,MATCH(I133,GLAPS정리!$B$2:$B$50,0)),"")) | AF133: =$AF$1 -> KR10 | AI133: =VLOOKUP(F133,GLAPS정리!$G$3:$J$114,2,0) -> #N/A | AJ133: =IF(Z133="울산정일","KRONS",IF(Z133="울산신항","KRUSN",IF(OR(Z133="선광종합물류(인천여객)",Z133="인천여객(인천여객)"),"KRINF",IF(OR(Z133="선광인천보세(인천신)",Z133="한진인천(인천신)",Z133="선광인천신항(인천신)",Z133="인천더로지스(인천신)"),"KRINN",IF(OR(Z133="인천진아(인천항)",Z133="인천E1(인천항)",Z133="인천SM경인터미널(인천항)",Z133="인천항(인천항)",Z133="인천우련(인천항)",Z133="인천항8부두(인천항)"),"KRINC",VLOOKUP(K133,GLAPS정리!$BB$2:$BC$33,2,0)))))) -> #N/A | AL133: =$AL$1 -> 5010001 | AN133: =TEXT(B133,"YYYY-MM-DD") -> 1900-01-00 | AO133: =IF(E133="오전", "0800", IF(E133="오후", "1300", IF(E133="잔업", "1800", ""))) | AP133: =VLOOKUP(C133,GLAPS정리!$AX$2:$AZ$17,3,0) -> #N/A | AR133: =X133 -> 0 | AX133: =VLOOKUP(L133,GLAPS정리!$V$3:$W$180,2,0) -> #N/A | BM133: =IF(AND(Q133=1,OR(P133="",P133="위험물")), "2210", IF(AND(Q133=1,OR(P133="리퍼",P133="위험물리퍼")), "2230", IF(AND(S133=1,OR(P133="",P133="위험물")), "4510", IF(AND(S133=1,OR(P133="리퍼",P133="위험물리퍼")), "4530", IF(AND(R133=1,OR(P133="",P133="위험물")), "4210", IF(AND(R133=1,P133="리퍼"), "4230", " ")))))) | BN133: =$BN$1 -> 1 | BR133: =IF(OR(P133="리퍼",P133="위험물리퍼"),"Y","") | BS133: =IF(OR(P133="위험물",P133="위험물리퍼"),"Y","") | BV133: =VLOOKUP(O133,GLAPS정리!$BH$2:$BI$94,2,0) -> #N/A | BW133: =IF(OR(Z133="동원",Z133="세방",Z133="한타"),"",IFERROR(INDEX(GLAPS정리!$BI$2:$BI$101,MATCH(Z133,GLAPS정리!$BH$2:$BH$101,0)),"")) | BX133: =IF(Z133="","",IFERROR(VLOOKUP(Z133,GLAPS정리!$AX$2:$AZ$17,3,0),"")) | BZ133: =VLOOKUP(H133,GLAPS정리!$L$3:$O$133,2,0) -> #N/A | CA133: =IF(V133="공휴일", 10, IF(V133="야간", 20, IF(V133="위험물", 30, IF(V133="중량", 40, "")))) | CL133: =VLOOKUP(AI133,GLAPS정리!$BT$3:$BV$26,3,0) -> #N/A
Q134: =IF(J134="20 FeeT",1,"") | R134: =IF(J134="40 Feet N",1,"") | S134: =IF(J134="40 Feet H",1,"") | AC134: =$AC$1 -> 20 | AD134: =IFERROR(INDEX(GLAPS정리!$D$2:$D$50,MATCH(I134,GLAPS정리!$A$2:$A$50,0)),IFERROR(INDEX(GLAPS정리!$D$2:$D$50,MATCH(I134,GLAPS정리!$B$2:$B$50,0)),"")) | AF134: =$AF$1 -> KR10 | AI134: =VLOOKUP(F134,GLAPS정리!$G$3:$J$114,2,0) -> #N/A | AJ134: =IF(Z134="울산정일","KRONS",IF(Z134="울산신항","KRUSN",IF(OR(Z134="선광종합물류(인천여객)",Z134="인천여객(인천여객)"),"KRINF",IF(OR(Z134="선광인천보세(인천신)",Z134="한진인천(인천신)",Z134="선광인천신항(인천신)",Z134="인천더로지스(인천신)"),"KRINN",IF(OR(Z134="인천진아(인천항)",Z134="인천E1(인천항)",Z134="인천SM경인터미널(인천항)",Z134="인천항(인천항)",Z134="인천우련(인천항)",Z134="인천항8부두(인천항)"),"KRINC",VLOOKUP(K134,GLAPS정리!$BB$2:$BC$33,2,0)))))) -> #N/A | AL134: =$AL$1 -> 5010001 | AN134: =TEXT(B134,"YYYY-MM-DD") -> 1900-01-00 | AO134: =IF(E134="오전", "0800", IF(E134="오후", "1300", IF(E134="잔업", "1800", ""))) | AP134: =VLOOKUP(C134,GLAPS정리!$AX$2:$AZ$17,3,0) -> #N/A | AR134: =X134 -> 0 | AX134: =VLOOKUP(L134,GLAPS정리!$V$3:$W$180,2,0) -> #N/A | BM134: =IF(AND(Q134=1,OR(P134="",P134="위험물")), "2210", IF(AND(Q134=1,OR(P134="리퍼",P134="위험물리퍼")), "2230", IF(AND(S134=1,OR(P134="",P134="위험물")), "4510", IF(AND(S134=1,OR(P134="리퍼",P134="위험물리퍼")), "4530", IF(AND(R134=1,OR(P134="",P134="위험물")), "4210", IF(AND(R134=1,P134="리퍼"), "4230", " ")))))) | BN134: =$BN$1 -> 1 | BR134: =IF(OR(P134="리퍼",P134="위험물리퍼"),"Y","") | BS134: =IF(OR(P134="위험물",P134="위험물리퍼"),"Y","") | BV134: =VLOOKUP(O134,GLAPS정리!$BH$2:$BI$94,2,0) -> #N/A | BW134: =IF(OR(Z134="동원",Z134="세방",Z134="한타"),"",IFERROR(INDEX(GLAPS정리!$BI$2:$BI$101,MATCH(Z134,GLAPS정리!$BH$2:$BH$101,0)),"")) | BX134: =IF(Z134="","",IFERROR(VLOOKUP(Z134,GLAPS정리!$AX$2:$AZ$17,3,0),"")) | BZ134: =VLOOKUP(H134,GLAPS정리!$L$3:$O$133,2,0) -> #N/A | CA134: =IF(V134="공휴일", 10, IF(V134="야간", 20, IF(V134="위험물", 30, IF(V134="중량", 40, "")))) | CL134: =VLOOKUP(AI134,GLAPS정리!$BT$3:$BV$26,3,0) -> #N/A
Q135: =IF(J135="20 FeeT",1,"") | R135: =IF(J135="40 Feet N",1,"") | S135: =IF(J135="40 Feet H",1,"") | AC135: =$AC$1 -> 20 | AD135: =IFERROR(INDEX(GLAPS정리!$D$2:$D$50,MATCH(I135,GLAPS정리!$A$2:$A$50,0)),IFERROR(INDEX(GLAPS정리!$D$2:$D$50,MATCH(I135,GLAPS정리!$B$2:$B$50,0)),"")) | AF135: =$AF$1 -> KR10 | AI135: =VLOOKUP(F135,GLAPS정리!$G$3:$J$114,2,0) -> #N/A | AJ135: =IF(Z135="울산정일","KRONS",IF(Z135="울산신항","KRUSN",IF(OR(Z135="선광종합물류(인천여객)",Z135="인천여객(인천여객)"),"KRINF",IF(OR(Z135="선광인천보세(인천신)",Z135="한진인천(인천신)",Z135="선광인천신항(인천신)",Z135="인천더로지스(인천신)"),"KRINN",IF(OR(Z135="인천진아(인천항)",Z135="인천E1(인천항)",Z135="인천SM경인터미널(인천항)",Z135="인천항(인천항)",Z135="인천우련(인천항)",Z135="인천항8부두(인천항)"),"KRINC",VLOOKUP(K135,GLAPS정리!$BB$2:$BC$33,2,0)))))) -> #N/A | AL135: =$AL$1 -> 5010001 | AN135: =TEXT(B135,"YYYY-MM-DD") -> 1900-01-00 | AO135: =IF(E135="오전", "0800", IF(E135="오후", "1300", IF(E135="잔업", "1800", ""))) | AP135: =VLOOKUP(C135,GLAPS정리!$AX$2:$AZ$17,3,0) -> #N/A | AR135: =X135 -> 0 | AX135: =VLOOKUP(L135,GLAPS정리!$V$3:$W$180,2,0) -> #N/A | BM135: =IF(AND(Q135=1,OR(P135="",P135="위험물")), "2210", IF(AND(Q135=1,OR(P135="리퍼",P135="위험물리퍼")), "2230", IF(AND(S135=1,OR(P135="",P135="위험물")), "4510", IF(AND(S135=1,OR(P135="리퍼",P135="위험물리퍼")), "4530", IF(AND(R135=1,OR(P135="",P135="위험물")), "4210", IF(AND(R135=1,P135="리퍼"), "4230", " ")))))) | BN135: =$BN$1 -> 1 | BR135: =IF(OR(P135="리퍼",P135="위험물리퍼"),"Y","") | BS135: =IF(OR(P135="위험물",P135="위험물리퍼"),"Y","") | BV135: =VLOOKUP(O135,GLAPS정리!$BH$2:$BI$94,2,0) -> #N/A | BW135: =IF(OR(Z135="동원",Z135="세방",Z135="한타"),"",IFERROR(INDEX(GLAPS정리!$BI$2:$BI$101,MATCH(Z135,GLAPS정리!$BH$2:$BH$101,0)),"")) | BX135: =IF(Z135="","",IFERROR(VLOOKUP(Z135,GLAPS정리!$AX$2:$AZ$17,3,0),"")) | BZ135: =VLOOKUP(H135,GLAPS정리!$L$3:$O$133,2,0) -> #N/A | CA135: =IF(V135="공휴일", 10, IF(V135="야간", 20, IF(V135="위험물", 30, IF(V135="중량", 40, "")))) | CL135: =VLOOKUP(AI135,GLAPS정리!$BT$3:$BV$26,3,0) -> #N/A
Q136: =IF(J136="20 FeeT",1,"") | R136: =IF(J136="40 Feet N",1,"") | S136: =IF(J136="40 Feet H",1,"") | AC136: =$AC$1 -> 20 | AD136: =IFERROR(INDEX(GLAPS정리!$D$2:$D$50,MATCH(I136,GLAPS정리!$A$2:$A$50,0)),IFERROR(INDEX(GLAPS정리!$D$2:$D$50,MATCH(I136,GLAPS정리!$B$2:$B$50,0)),"")) | AF136: =$AF$1 -> KR10 | AI136: =VLOOKUP(F136,GLAPS정리!$G$3:$J$114,2,0) -> #N/A | AJ136: =IF(Z136="울산정일","KRONS",IF(Z136="울산신항","KRUSN",IF(OR(Z136="선광종합물류(인천여객)",Z136="인천여객(인천여객)"),"KRINF",IF(OR(Z136="선광인천보세(인천신)",Z136="한진인천(인천신)",Z136="선광인천신항(인천신)",Z136="인천더로지스(인천신)"),"KRINN",IF(OR(Z136="인천진아(인천항)",Z136="인천E1(인천항)",Z136="인천SM경인터미널(인천항)",Z136="인천항(인천항)",Z136="인천우련(인천항)",Z136="인천항8부두(인천항)"),"KRINC",VLOOKUP(K136,GLAPS정리!$BB$2:$BC$33,2,0)))))) -> #N/A | AL136: =$AL$1 -> 5010001 | AN136: =TEXT(B136,"YYYY-MM-DD") -> 1900-01-00 | AO136: =IF(E136="오전", "0800", IF(E136="오후", "1300", IF(E136="잔업", "1800", ""))) | AP136: =VLOOKUP(C136,GLAPS정리!$AX$2:$AZ$17,3,0) -> #N/A | AR136: =X136 -> 0 | AX136: =VLOOKUP(L136,GLAPS정리!$V$3:$W$180,2,0) -> #N/A | BM136: =IF(AND(Q136=1,OR(P136="",P136="위험물")), "2210", IF(AND(Q136=1,OR(P136="리퍼",P136="위험물리퍼")), "2230", IF(AND(S136=1,OR(P136="",P136="위험물")), "4510", IF(AND(S136=1,OR(P136="리퍼",P136="위험물리퍼")), "4530", IF(AND(R136=1,OR(P136="",P136="위험물")), "4210", IF(AND(R136=1,P136="리퍼"), "4230", " ")))))) | BN136: =$BN$1 -> 1 | BR136: =IF(OR(P136="리퍼",P136="위험물리퍼"),"Y","") | BS136: =IF(OR(P136="위험물",P136="위험물리퍼"),"Y","") | BV136: =VLOOKUP(O136,GLAPS정리!$BH$2:$BI$94,2,0) -> #N/A | BW136: =IF(OR(Z136="동원",Z136="세방",Z136="한타"),"",IFERROR(INDEX(GLAPS정리!$BI$2:$BI$101,MATCH(Z136,GLAPS정리!$BH$2:$BH$101,0)),"")) | BX136: =IF(Z136="","",IFERROR(VLOOKUP(Z136,GLAPS정리!$AX$2:$AZ$17,3,0),"")) | BZ136: =VLOOKUP(H136,GLAPS정리!$L$3:$O$133,2,0) -> #N/A | CA136: =IF(V136="공휴일", 10, IF(V136="야간", 20, IF(V136="위험물", 30, IF(V136="중량", 40, "")))) | CL136: =VLOOKUP(AI136,GLAPS정리!$BT$3:$BV$26,3,0) -> #N/A
Q137: =IF(J137="20 FeeT",1,"") | R137: =IF(J137="40 Feet N",1,"") | S137: =IF(J137="40 Feet H",1,"") | AC137: =$AC$1 -> 20 | AD137: =IFERROR(INDEX(GLAPS정리!$D$2:$D$50,MATCH(I137,GLAPS정리!$A$2:$A$50,0)),IFERROR(INDEX(GLAPS정리!$D$2:$D$50,MATCH(I137,GLAPS정리!$B$2:$B$50,0)),"")) | AF137: =$AF$1 -> KR10 | AI137: =VLOOKUP(F137,GLAPS정리!$G$3:$J$114,2,0) -> #N/A | AJ137: =IF(Z137="울산정일","KRONS",IF(Z137="울산신항","KRUSN",IF(OR(Z137="선광종합물류(인천여객)",Z137="인천여객(인천여객)"),"KRINF",IF(OR(Z137="선광인천보세(인천신)",Z137="한진인천(인천신)",Z137="선광인천신항(인천신)",Z137="인천더로지스(인천신)"),"KRINN",IF(OR(Z137="인천진아(인천항)",Z137="인천E1(인천항)",Z137="인천SM경인터미널(인천항)",Z137="인천항(인천항)",Z137="인천우련(인천항)",Z137="인천항8부두(인천항)"),"KRINC",VLOOKUP(K137,GLAPS정리!$BB$2:$BC$33,2,0)))))) -> #N/A | AL137: =$AL$1 -> 5010001 | AN137: =TEXT(B137,"YYYY-MM-DD") -> 1900-01-00 | AO137: =IF(E137="오전", "0800", IF(E137="오후", "1300", IF(E137="잔업", "1800", ""))) | AP137: =VLOOKUP(C137,GLAPS정리!$AX$2:$AZ$17,3,0) -> #N/A | AR137: =X137 -> 0 | AX137: =VLOOKUP(L137,GLAPS정리!$V$3:$W$180,2,0) -> #N/A | BM137: =IF(AND(Q137=1,OR(P137="",P137="위험물")), "2210", IF(AND(Q137=1,OR(P137="리퍼",P137="위험물리퍼")), "2230", IF(AND(S137=1,OR(P137="",P137="위험물")), "4510", IF(AND(S137=1,OR(P137="리퍼",P137="위험물리퍼")), "4530", IF(AND(R137=1,OR(P137="",P137="위험물")), "4210", IF(AND(R137=1,P137="리퍼"), "4230", " ")))))) | BN137: =$BN$1 -> 1 | BR137: =IF(OR(P137="리퍼",P137="위험물리퍼"),"Y","") | BS137: =IF(OR(P137="위험물",P137="위험물리퍼"),"Y","") | BV137: =VLOOKUP(O137,GLAPS정리!$BH$2:$BI$94,2,0) -> #N/A | BW137: =IF(OR(Z137="동원",Z137="세방",Z137="한타"),"",IFERROR(INDEX(GLAPS정리!$BI$2:$BI$101,MATCH(Z137,GLAPS정리!$BH$2:$BH$101,0)),"")) | BX137: =IF(Z137="","",IFERROR(VLOOKUP(Z137,GLAPS정리!$AX$2:$AZ$17,3,0),"")) | BZ137: =VLOOKUP(H137,GLAPS정리!$L$3:$O$133,2,0) -> #N/A | CA137: =IF(V137="공휴일", 10, IF(V137="야간", 20, IF(V137="위험물", 30, IF(V137="중량", 40, "")))) | CL137: =VLOOKUP(AI137,GLAPS정리!$BT$3:$BV$26,3,0) -> #N/A
Q138: =IF(J138="20 FeeT",1,"") | R138: =IF(J138="40 Feet N",1,"") | S138: =IF(J138="40 Feet H",1,"") | AC138: =$AC$1 -> 20 | AD138: =IFERROR(INDEX(GLAPS정리!$D$2:$D$50,MATCH(I138,GLAPS정리!$A$2:$A$50,0)),IFERROR(INDEX(GLAPS정리!$D$2:$D$50,MATCH(I138,GLAPS정리!$B$2:$B$50,0)),"")) | AF138: =$AF$1 -> KR10 | AI138: =VLOOKUP(F138,GLAPS정리!$G$3:$J$114,2,0) -> #N/A | AJ138: =IF(Z138="울산정일","KRONS",IF(Z138="울산신항","KRUSN",IF(OR(Z138="선광종합물류(인천여객)",Z138="인천여객(인천여객)"),"KRINF",IF(OR(Z138="선광인천보세(인천신)",Z138="한진인천(인천신)",Z138="선광인천신항(인천신)",Z138="인천더로지스(인천신)"),"KRINN",IF(OR(Z138="인천진아(인천항)",Z138="인천E1(인천항)",Z138="인천SM경인터미널(인천항)",Z138="인천항(인천항)",Z138="인천우련(인천항)",Z138="인천항8부두(인천항)"),"KRINC",VLOOKUP(K138,GLAPS정리!$BB$2:$BC$33,2,0)))))) -> #N/A | AL138: =$AL$1 -> 5010001 | AN138: =TEXT(B138,"YYYY-MM-DD") -> 1900-01-00 | AO138: =IF(E138="오전", "0800", IF(E138="오후", "1300", IF(E138="잔업", "1800", ""))) | AP138: =VLOOKUP(C138,GLAPS정리!$AX$2:$AZ$17,3,0) -> #N/A | AR138: =X138 -> 0 | AX138: =VLOOKUP(L138,GLAPS정리!$V$3:$W$180,2,0) -> #N/A | BM138: =IF(AND(Q138=1,OR(P138="",P138="위험물")), "2210", IF(AND(Q138=1,OR(P138="리퍼",P138="위험물리퍼")), "2230", IF(AND(S138=1,OR(P138="",P138="위험물")), "4510", IF(AND(S138=1,OR(P138="리퍼",P138="위험물리퍼")), "4530", IF(AND(R138=1,OR(P138="",P138="위험물")), "4210", IF(AND(R138=1,P138="리퍼"), "4230", " ")))))) | BN138: =$BN$1 -> 1 | BR138: =IF(OR(P138="리퍼",P138="위험물리퍼"),"Y","") | BS138: =IF(OR(P138="위험물",P138="위험물리퍼"),"Y","") | BV138: =VLOOKUP(O138,GLAPS정리!$BH$2:$BI$94,2,0) -> #N/A | BW138: =IF(OR(Z138="동원",Z138="세방",Z138="한타"),"",IFERROR(INDEX(GLAPS정리!$BI$2:$BI$101,MATCH(Z138,GLAPS정리!$BH$2:$BH$101,0)),"")) | BX138: =IF(Z138="","",IFERROR(VLOOKUP(Z138,GLAPS정리!$AX$2:$AZ$17,3,0),"")) | BZ138: =VLOOKUP(H138,GLAPS정리!$L$3:$O$133,2,0) -> #N/A | CA138: =IF(V138="공휴일", 10, IF(V138="야간", 20, IF(V138="위험물", 30, IF(V138="중량", 40, "")))) | CL138: =VLOOKUP(AI138,GLAPS정리!$BT$3:$BV$26,3,0) -> #N/A
Q139: =IF(J139="20 FeeT",1,"") | R139: =IF(J139="40 Feet N",1,"") | S139: =IF(J139="40 Feet H",1,"") | AC139: =$AC$1 -> 20 | AD139: =IFERROR(INDEX(GLAPS정리!$D$2:$D$50,MATCH(I139,GLAPS정리!$A$2:$A$50,0)),IFERROR(INDEX(GLAPS정리!$D$2:$D$50,MATCH(I139,GLAPS정리!$B$2:$B$50,0)),"")) | AF139: =$AF$1 -> KR10 | AI139: =VLOOKUP(F139,GLAPS정리!$G$3:$J$114,2,0) -> #N/A | AJ139: =IF(Z139="울산정일","KRONS",IF(Z139="울산신항","KRUSN",IF(OR(Z139="선광종합물류(인천여객)",Z139="인천여객(인천여객)"),"KRINF",IF(OR(Z139="선광인천보세(인천신)",Z139="한진인천(인천신)",Z139="선광인천신항(인천신)",Z139="인천더로지스(인천신)"),"KRINN",IF(OR(Z139="인천진아(인천항)",Z139="인천E1(인천항)",Z139="인천SM경인터미널(인천항)",Z139="인천항(인천항)",Z139="인천우련(인천항)",Z139="인천항8부두(인천항)"),"KRINC",VLOOKUP(K139,GLAPS정리!$BB$2:$BC$33,2,0)))))) -> #N/A | AL139: =$AL$1 -> 5010001 | AN139: =TEXT(B139,"YYYY-MM-DD") -> 1900-01-00 | AO139: =IF(E139="오전", "0800", IF(E139="오후", "1300", IF(E139="잔업", "1800", ""))) | AP139: =VLOOKUP(C139,GLAPS정리!$AX$2:$AZ$17,3,0) -> #N/A | AR139: =X139 -> 0 | AX139: =VLOOKUP(L139,GLAPS정리!$V$3:$W$180,2,0) -> #N/A | BM139: =IF(AND(Q139=1,OR(P139="",P139="위험물")), "2210", IF(AND(Q139=1,OR(P139="리퍼",P139="위험물리퍼")), "2230", IF(AND(S139=1,OR(P139="",P139="위험물")), "4510", IF(AND(S139=1,OR(P139="리퍼",P139="위험물리퍼")), "4530", IF(AND(R139=1,OR(P139="",P139="위험물")), "4210", IF(AND(R139=1,P139="리퍼"), "4230", " ")))))) | BN139: =$BN$1 -> 1 | BR139: =IF(OR(P139="리퍼",P139="위험물리퍼"),"Y","") | BS139: =IF(OR(P139="위험물",P139="위험물리퍼"),"Y","") | BV139: =VLOOKUP(O139,GLAPS정리!$BH$2:$BI$94,2,0) -> #N/A | BW139: =IF(OR(Z139="동원",Z139="세방",Z139="한타"),"",IFERROR(INDEX(GLAPS정리!$BI$2:$BI$101,MATCH(Z139,GLAPS정리!$BH$2:$BH$101,0)),"")) | BX139: =IF(Z139="","",IFERROR(VLOOKUP(Z139,GLAPS정리!$AX$2:$AZ$17,3,0),"")) | BZ139: =VLOOKUP(H139,GLAPS정리!$L$3:$O$133,2,0) -> #N/A | CA139: =IF(V139="공휴일", 10, IF(V139="야간", 20, IF(V139="위험물", 30, IF(V139="중량", 40, "")))) | CL139: =VLOOKUP(AI139,GLAPS정리!$BT$3:$BV$26,3,0) -> #N/A
Q140: =IF(J140="20 FeeT",1,"") | R140: =IF(J140="40 Feet N",1,"") | S140: =IF(J140="40 Feet H",1,"") | AC140: =$AC$1 -> 20 | AD140: =IFERROR(INDEX(GLAPS정리!$D$2:$D$50,MATCH(I140,GLAPS정리!$A$2:$A$50,0)),IFERROR(INDEX(GLAPS정리!$D$2:$D$50,MATCH(I140,GLAPS정리!$B$2:$B$50,0)),"")) | AF140: =$AF$1 -> KR10 | AI140: =VLOOKUP(F140,GLAPS정리!$G$3:$J$114,2,0) -> #N/A | AJ140: =IF(Z140="울산정일","KRONS",IF(Z140="울산신항","KRUSN",IF(OR(Z140="선광종합물류(인천여객)",Z140="인천여객(인천여객)"),"KRINF",IF(OR(Z140="선광인천보세(인천신)",Z140="한진인천(인천신)",Z140="선광인천신항(인천신)",Z140="인천더로지스(인천신)"),"KRINN",IF(OR(Z140="인천진아(인천항)",Z140="인천E1(인천항)",Z140="인천SM경인터미널(인천항)",Z140="인천항(인천항)",Z140="인천우련(인천항)",Z140="인천항8부두(인천항)"),"KRINC",VLOOKUP(K140,GLAPS정리!$BB$2:$BC$33,2,0)))))) -> #N/A | AL140: =$AL$1 -> 5010001 | AN140: =TEXT(B140,"YYYY-MM-DD") -> 1900-01-00 | AO140: =IF(E140="오전", "0800", IF(E140="오후", "1300", IF(E140="잔업", "1800", ""))) | AP140: =VLOOKUP(C140,GLAPS정리!$AX$2:$AZ$17,3,0) -> #N/A | AR140: =X140 -> 0 | AX140: =VLOOKUP(L140,GLAPS정리!$V$3:$W$180,2,0) -> #N/A | BM140: =IF(AND(Q140=1,OR(P140="",P140="위험물")), "2210", IF(AND(Q140=1,OR(P140="리퍼",P140="위험물리퍼")), "2230", IF(AND(S140=1,OR(P140="",P140="위험물")), "4510", IF(AND(S140=1,OR(P140="리퍼",P140="위험물리퍼")), "4530", IF(AND(R140=1,OR(P140="",P140="위험물")), "4210", IF(AND(R140=1,P140="리퍼"), "4230", " ")))))) | BN140: =$BN$1 -> 1 | BR140: =IF(OR(P140="리퍼",P140="위험물리퍼"),"Y","") | BS140: =IF(OR(P140="위험물",P140="위험물리퍼"),"Y","") | BV140: =VLOOKUP(O140,GLAPS정리!$BH$2:$BI$94,2,0) -> #N/A | BW140: =IF(OR(Z140="동원",Z140="세방",Z140="한타"),"",IFERROR(INDEX(GLAPS정리!$BI$2:$BI$101,MATCH(Z140,GLAPS정리!$BH$2:$BH$101,0)),"")) | BX140: =IF(Z140="","",IFERROR(VLOOKUP(Z140,GLAPS정리!$AX$2:$AZ$17,3,0),"")) | BZ140: =VLOOKUP(H140,GLAPS정리!$L$3:$O$133,2,0) -> #N/A | CA140: =IF(V140="공휴일", 10, IF(V140="야간", 20, IF(V140="위험물", 30, IF(V140="중량", 40, "")))) | CL140: =VLOOKUP(AI140,GLAPS정리!$BT$3:$BV$26,3,0) -> #N/A
Q141: =IF(J141="20 FeeT",1,"") | R141: =IF(J141="40 Feet N",1,"") | S141: =IF(J141="40 Feet H",1,"") | AC141: =$AC$1 -> 20 | AD141: =IFERROR(INDEX(GLAPS정리!$D$2:$D$50,MATCH(I141,GLAPS정리!$A$2:$A$50,0)),IFERROR(INDEX(GLAPS정리!$D$2:$D$50,MATCH(I141,GLAPS정리!$B$2:$B$50,0)),"")) | AF141: =$AF$1 -> KR10 | AI141: =VLOOKUP(F141,GLAPS정리!$G$3:$J$114,2,0) -> #N/A | AJ141: =IF(Z141="울산정일","KRONS",IF(Z141="울산신항","KRUSN",IF(OR(Z141="선광종합물류(인천여객)",Z141="인천여객(인천여객)"),"KRINF",IF(OR(Z141="선광인천보세(인천신)",Z141="한진인천(인천신)",Z141="선광인천신항(인천신)",Z141="인천더로지스(인천신)"),"KRINN",IF(OR(Z141="인천진아(인천항)",Z141="인천E1(인천항)",Z141="인천SM경인터미널(인천항)",Z141="인천항(인천항)",Z141="인천우련(인천항)",Z141="인천항8부두(인천항)"),"KRINC",VLOOKUP(K141,GLAPS정리!$BB$2:$BC$33,2,0)))))) -> #N/A | AL141: =$AL$1 -> 5010001 | AN141: =TEXT(B141,"YYYY-MM-DD") -> 1900-01-00 | AO141: =IF(E141="오전", "0800", IF(E141="오후", "1300", IF(E141="잔업", "1800", ""))) | AP141: =VLOOKUP(C141,GLAPS정리!$AX$2:$AZ$17,3,0) -> #N/A | AR141: =X141 -> 0 | AX141: =VLOOKUP(L141,GLAPS정리!$V$3:$W$180,2,0) -> #N/A | BM141: =IF(AND(Q141=1,OR(P141="",P141="위험물")), "2210", IF(AND(Q141=1,OR(P141="리퍼",P141="위험물리퍼")), "2230", IF(AND(S141=1,OR(P141="",P141="위험물")), "4510", IF(AND(S141=1,OR(P141="리퍼",P141="위험물리퍼")), "4530", IF(AND(R141=1,OR(P141="",P141="위험물")), "4210", IF(AND(R141=1,P141="리퍼"), "4230", " ")))))) | BN141: =$BN$1 -> 1 | BR141: =IF(OR(P141="리퍼",P141="위험물리퍼"),"Y","") | BS141: =IF(OR(P141="위험물",P141="위험물리퍼"),"Y","") | BV141: =VLOOKUP(O141,GLAPS정리!$BH$2:$BI$94,2,0) -> #N/A | BW141: =IF(OR(Z141="동원",Z141="세방",Z141="한타"),"",IFERROR(INDEX(GLAPS정리!$BI$2:$BI$101,MATCH(Z141,GLAPS정리!$BH$2:$BH$101,0)),"")) | BX141: =IF(Z141="","",IFERROR(VLOOKUP(Z141,GLAPS정리!$AX$2:$AZ$17,3,0),"")) | BZ141: =VLOOKUP(H141,GLAPS정리!$L$3:$O$133,2,0) -> #N/A | CA141: =IF(V141="공휴일", 10, IF(V141="야간", 20, IF(V141="위험물", 30, IF(V141="중량", 40, "")))) | CL141: =VLOOKUP(AI141,GLAPS정리!$BT$3:$BV$26,3,0) -> #N/A
Q142: =IF(J142="20 FeeT",1,"") | R142: =IF(J142="40 Feet N",1,"") | S142: =IF(J142="40 Feet H",1,"") | AC142: =$AC$1 -> 20 | AD142: =IFERROR(INDEX(GLAPS정리!$D$2:$D$50,MATCH(I142,GLAPS정리!$A$2:$A$50,0)),IFERROR(INDEX(GLAPS정리!$D$2:$D$50,MATCH(I142,GLAPS정리!$B$2:$B$50,0)),"")) | AF142: =$AF$1 -> KR10 | AI142: =VLOOKUP(F142,GLAPS정리!$G$3:$J$114,2,0) -> #N/A | AJ142: =IF(Z142="울산정일","KRONS",IF(Z142="울산신항","KRUSN",IF(OR(Z142="선광종합물류(인천여객)",Z142="인천여객(인천여객)"),"KRINF",IF(OR(Z142="선광인천보세(인천신)",Z142="한진인천(인천신)",Z142="선광인천신항(인천신)",Z142="인천더로지스(인천신)"),"KRINN",IF(OR(Z142="인천진아(인천항)",Z142="인천E1(인천항)",Z142="인천SM경인터미널(인천항)",Z142="인천항(인천항)",Z142="인천우련(인천항)",Z142="인천항8부두(인천항)"),"KRINC",VLOOKUP(K142,GLAPS정리!$BB$2:$BC$33,2,0)))))) -> #N/A | AL142: =$AL$1 -> 5010001 | AN142: =TEXT(B142,"YYYY-MM-DD") -> 1900-01-00 | AO142: =IF(E142="오전", "0800", IF(E142="오후", "1300", IF(E142="잔업", "1800", ""))) | AP142: =VLOOKUP(C142,GLAPS정리!$AX$2:$AZ$17,3,0) -> #N/A | AR142: =X142 -> 0 | AX142: =VLOOKUP(L142,GLAPS정리!$V$3:$W$180,2,0) -> #N/A | BM142: =IF(AND(Q142=1,OR(P142="",P142="위험물")), "2210", IF(AND(Q142=1,OR(P142="리퍼",P142="위험물리퍼")), "2230", IF(AND(S142=1,OR(P142="",P142="위험물")), "4510", IF(AND(S142=1,OR(P142="리퍼",P142="위험물리퍼")), "4530", IF(AND(R142=1,OR(P142="",P142="위험물")), "4210", IF(AND(R142=1,P142="리퍼"), "4230", " ")))))) | BN142: =$BN$1 -> 1 | BR142: =IF(OR(P142="리퍼",P142="위험물리퍼"),"Y","") | BS142: =IF(OR(P142="위험물",P142="위험물리퍼"),"Y","") | BV142: =VLOOKUP(O142,GLAPS정리!$BH$2:$BI$94,2,0) -> #N/A | BW142: =IF(OR(Z142="동원",Z142="세방",Z142="한타"),"",IFERROR(INDEX(GLAPS정리!$BI$2:$BI$101,MATCH(Z142,GLAPS정리!$BH$2:$BH$101,0)),"")) | BX142: =IF(Z142="","",IFERROR(VLOOKUP(Z142,GLAPS정리!$AX$2:$AZ$17,3,0),"")) | BZ142: =VLOOKUP(H142,GLAPS정리!$L$3:$O$133,2,0) -> #N/A | CA142: =IF(V142="공휴일", 10, IF(V142="야간", 20, IF(V142="위험물", 30, IF(V142="중량", 40, "")))) | CL142: =VLOOKUP(AI142,GLAPS정리!$BT$3:$BV$26,3,0) -> #N/A
... Q890: =IF(J890="20 FeeT",1,"") | R890: =IF(J890="40 Feet N",1,"") | S890: =IF(J890="40 Feet H",1,"") | AC890: =$AC$1 -> 20 | AD890: =IFERROR(INDEX(GLAPS정리!$D$2:$D$50,MATCH(I890,GLAPS정리!$A$2:$A$50,0)),IFERROR(INDEX(GLAPS정리!$D$2:$D$50,MATCH(I890,GLAPS정리!$B$2:$B$50,0)),"")) | AF890: =$AF$1 -> KR10 | AI890: =VLOOKUP(F890,GLAPS정리!$G$3:$J$114,2,0) -> #N/A | AJ890: =IF(Z890="울산정일","KRONS",IF(Z890="울산신항","KRUSN",IF(OR(Z890="선광종합물류(인천여객)",Z890="인천여객(인천여객)"),"KRINF",IF(OR(Z890="선광인천보세(인천신)",Z890="한진인천(인천신)",Z890="선광인천신항(인천신)",Z890="인천더로지스(인천신)"),"KRINN",IF(OR(Z890="인천진아(인천항)",Z890="인천E1(인천항)",Z890="인천SM경인터미널(인천항)",Z890="인천항(인천항)",Z890="인천우련(인천항)",Z890="인천항8부두(인천항)"),"KRINC",VLOOKUP(K890,GLAPS정리!$BB$2:$BC$33,2,0)))))) -> #N/A | AL890: =$AL$1 -> 5010001 | AN890: =TEXT(B890,"YYYY-MM-DD") -> 1900-01-00 | AO890: =IF(E890="오전", "0800", IF(E890="오후", "1300", IF(E890="잔업", "1800", ""))) | AP890: =VLOOKUP(C890,GLAPS정리!$AX$2:$AZ$17,3,0) -> #N/A | AR890: =X890 -> 0 | AX890: =VLOOKUP(L890,GLAPS정리!$V$3:$W$180,2,0) -> #N/A | BM890: =IF(AND(Q890=1,OR(P890="",P890="위험물")), "2210", IF(AND(Q890=1,OR(P890="리퍼",P890="위험물리퍼")), "2230", IF(AND(S890=1,OR(P890="",P890="위험물")), "4510", IF(AND(S890=1,OR(P890="리퍼",P890="위험물리퍼")), "4530", IF(AND(R890=1,OR(P890="",P890="위험물")), "4210", IF(AND(R890=1,P890="리퍼"), "4230", " ")))))) | BN890: =$BN$1 -> 1 | BR890: =IF(OR(P890="리퍼",P890="위험물리퍼"),"Y","") | BS890: =IF(OR(P890="위험물",P890="위험물리퍼"),"Y","") | BV890: =VLOOKUP(O890,GLAPS정리!$BH$2:$BI$94,2,0) -> #N/A | BW890: =IF(OR(Z890="동원",Z890="세방",Z890="한타"),"",IFERROR(INDEX(GLAPS정리!$BI$2:$BI$101,MATCH(Z890,GLAPS정리!$BH$2:$BH$101,0)),"")) | BX890: =IF(Z890="","",IFERROR(VLOOKUP(Z890,GLAPS정리!$AX$2:$AZ$17,3,0),"")) | BZ890: =VLOOKUP(H890,GLAPS정리!$L$3:$O$133,2,0) -> #N/A | CA890: =IF(V890="공휴일", 10, IF(V890="야간", 20, IF(V890="위험물", 30, IF(V890="중량", 40, "")))) | CL890: =VLOOKUP(AI890,GLAPS정리!$BT$3:$BV$26,3,0) -> #N/A

Sheet GLAPS컨테이너배차관리
A1: ODCY명 | B1: 번호 | C1: 배차 | D1: 운송 | E1: 오더번호(TMS) | F1: 편성번호 | G1: 배차번호 | H1: 진행상태 | I1: 정산상태 | J1: 오더구분 | K1: 작업지(하차지)도착요청일 | L1: 작업지(하차지)도착요청시간 | M1: 픽업부킹번호 | N1: 반입부킹번호 | O1: 선사코드 | P1: 선사명 | Q1: POL | R1: Pod | S1: 최종목적지 | T1: 작업지(하차지)명 | U1: 컨샤이니명 | V1: 선적지 | W1: 화주사 | X1: 컨테이너 번호 | Y1: 컨규격 | Z1: 봉인번호 | AA1: 컨테이너 사진 | AB1: 차량번호 | AC1: 운전원명 | AD1: 기사전화번호 | AE1: 차량아이디 | AF1: ATD | AG1: ETD | AH1: ETA | AI1: 냉동 | AJ1: 온도 | AK1: 위험물 | AL1: 위험물코드 | AM1: 위험물 Free Time | AN1: 공컨반납기한 | AO1: 반납기한초과 | AP1: 철송여부 | AQ1: 오더등급 | AR1: 하차지등급 | AS1: 운송구분 | AT1: 직계약여부 | AU1: 모바일배정 | AV1: 운전원매입금액 | AW1: 운전원배차여부 | AX1: GMMS 등록 | AY1: 운송사코드 | AZ1: 운송사 | BA1: 수기배정사유 | BB1: 수기배정사유내용 | BC1: 판매시장 | BD1: 판매구분 | BE1: 매출구분 | BF1: 직계약 차량 | BG1: 입차영업소 | BH1: 입차일자 | BI1: COPINO | BJ1: COPINO전송일시 | BK1: COPINO응답여부 | BL1: COPINO응답메시지 | BM1: 운송경로코드 | BN1: 운송경로명 | BO1: 운송경로 기준거리(KM) | BP1: 반출가능여부 | BQ1: 반출지 코드 | BR1: 반출지명(출발) | BS1: 반출지 주소 | BT1: 파손컨 여부 | BU1: 파손사진 | BV1: 파손신고일 | BW1: 파손신고시간 | BX1: 반출완료일시 | BY1: 작업지 코드 | BZ1: 작업지(하차지) 주소 | CA1: 작업(하차)완료일시 | CB1: 경유지코드 | CC1: 경유지명 | CD1: 경유지주소 | CE1: 선픽업여부 | CF1: 선픽업정산방식 | CG1: 선픽업창고명 | CH1: 선픽업시작일 | CI1: 선픽업종료일 | CJ1: 선픽업보관일수 | CK1: ODCY 여부 | CL1: ODCY 코드 | CM1: ODCY창고명 | CN1: 보관일수 | CO1: 선픽업 보관일수 | CP1: 반출CY | CQ1: 반출CY일치여부 | CR1: 반출일시 | CS1: 반입CY | CT1: 반입CY일치여부 | CU1: 반입일시 | CV1: 컨테이너 중량 | CW1: VGM | CX1: 화물설명 | CY1: 화주 구분 | CZ1: 산업군 | DA1: 오더일시 | DB1: 배정일시 | DC1: 배차일시 | DD1: 배차취소시간 | DE1: 정산기준일자 | DF1: 통지사항 | DG1: 메모 | DH1: 매입금액 | DI1: 할증1 | DJ1: 할증2 | DK1: 할증3 | DL1: 할증4 | DM1: 할증5 | DN1: 매입할증 합계 | DO1: 선픽업료 | DP1: 공컨상차비여부 | DQ1: 정산정보 | DR1: 오더등록업체 | DS1: 오더등록자명 | DT1: 오더등록자 연락처 | DU1: 오더등록자 이메일 | DV1: 운송서비스 | DW1: 운송서비스코드 | DX1: 공차중량
B2: 193 | E2: W260602-00000423 | F2: X260602-001956 | G2: Y260602-001956 | H2: 배정 | I2: 미생성 | J2: 수출 | K2: 46177 | L2: 18:00 | M2: SELG82813400 | N2: SELG82813400 | O2: ONE | P2: 오션네트워크익스프레스 | S2: USSAV | T2: [GB]아산 2포장장 (오토쎌) | U2: KAGA | V2: 네슬리 | W2: 현대글로비스주식회사 | Y2: 4510 | AK2: N | AP2: N | AQ2: D | AS2: 주선 | AT2: N | AV2: 0 | AX2: N | AY2: 1011 | AZ2: ㈜이엘에스솔루션 | BC2: 수출 | BD2: 반제품 | BE2: 운송료 | BI2: N | BK2: N | BM2: AAAAAAAAA | BN2: 컨테이너 미정의 | BP2: N | BQ2: AAA | BR2: 미정의 | BT2: N | BW2: __:__ | BY2: H000_GB | CK2: N | CQ2: N | CT2: N | CV2: 0 | CY2: 계열 | DA2: 02)16:51 | DB2: 02)16:51 | DH2: 0 | DN2: 0 | DO2: 0 | DP2: N | DS2: 박승기 | DV2: 컨테이너_수출 | DW2: 5010001 | DX2: 0
B3: 192 | E3: W260602-00000422 | F3: X260602-001957 | G3: Y260602-001957 | H3: 배정 | I3: 미생성 | J3: 수출 | K3: 46177 | L3: 13:00 | M3: D713CJ044 | N3: D713CJ044 | O3: MAE | P3: 머스크 | S3: USMOB | T3: [GB]아산 2포장장 (오토쎌) | U3: HMMA | V3: 셔틀 | W3: 현대글로비스주식회사 | Y3: 4510 | AK3: N | AP3: N | AQ3: D | AS3: 주선 | AT3: N | AV3: 0 | AX3: N | AY3: 1011 | AZ3: ㈜이엘에스솔루션 | BC3: 수출 | BD3: 반제품 | BE3: 운송료 | BI3: N | BK3: N | BM3: AAAAAAAAA | BN3: 컨테이너 미정의 | BP3: N | BQ3: AAA | BR3: 미정의 | BT3: N | BW3: __:__ | BY3: H000_GB | CK3: N | CQ3: N | CT3: N | CV3: 0 | CY3: 계열 | DA3: 02)16:51 | DB3: 02)16:51 | DH3: 0 | DN3: 0 | DO3: 0 | DP3: N | DS3: 박승기 | DV3: 컨테이너_수출 | DW3: 5010001 | DX3: 0
B4: 191 | E4: W260602-00000421 | F4: X260602-002072 | G4: Y260602-002072 | H4: 배정 | I4: 미생성 | J4: 수출 | K4: 46177 | L4: 18:00 | M4: D713CJ044 | N4: D713CJ044 | O4: MAE | P4: 머스크 | S4: USMOB | T4: [GB]아산 2포장장 (오토쎌) | U4: HMMA | V4: 대신 | W4: 현대글로비스주식회사 | Y4: 4510 | AK4: N | AP4: N | AQ4: D | AS4: 주선 | AT4: N | AV4: 0 | AX4: N | AY4: 1011 | AZ4: ㈜이엘에스솔루션 | BC4: 수출 | BD4: 반제품 | BE4: 운송료 | BI4: N | BK4: N | BM4: AAAAAAAAA | BN4: 컨테이너 미정의 | BP4: N | BQ4: AAA | BR4: 미정의 | BT4: N | BW4: __:__ | BY4: H000_GB | CK4: N | CQ4: N | CT4: N | CV4: 0 | CY4: 계열 | DA4: 02)17:35 | DB4: 02)17:35 | DH4: 0 | DN4: 0 | DO4: 0 | DP4: N | DS4: 박승기 | DV4: 컨테이너_수출 | DW4: 5010001 | DX4: 0
B5: 190 | E5: W260602-00000421 | F5: X260602-002071 | G5: Y260602-002071 | H5: 배정 | I5: 미생성 | J5: 수출 | K5: 46177 | L5: 19:00 | M5: D713CJ044 | N5: D713CJ044 | O5: MAE | P5: 머스크 | S5: USMOB | T5: [GB]아산 2포장장 (오토쎌) | U5: HMMA | V5: 대신 | W5: 현대글로비스주식회사 | Y5: 4510 | AK5: N | AP5: N | AQ5: D | AS5: 주선 | AT5: N | AV5: 0 | AX5: N | AY5: 1011 | AZ5: ㈜이엘에스솔루션 | BC5: 수출 | BD5: 반제품 | BE5: 운송료 | BI5: N | BK5: N | BM5: AAAAAAAAA | BN5: 컨테이너 미정의 | BP5: N | BQ5: AAA | BR5: 미정의 | BT5: N | BW5: __:__ | BY5: H000_GB | CK5: N | CQ5: N | CT5: N | CV5: 0 | CY5: 계열 | DA5: 02)17:34 | DB5: 02)17:34 | DH5: 0 | DN5: 0 | DO5: 0 | DP5: N | DS5: 박승기 | DV5: 컨테이너_수출 | DW5: 5010001 | DX5: 0
B6: 189 | E6: W260602-00000421 | F6: X260602-002070 | G6: Y260602-002070 | H6: 배정 | I6: 미생성 | J6: 수출 | K6: 46177 | L6: 14:00 | M6: D713CJ044 | N6: D713CJ044 | O6: MAE | P6: 머스크 | S6: USMOB | T6: [GB]아산 2포장장 (오토쎌) | U6: HMMA | V6: 셔틀 | W6: 현대글로비스주식회사 | Y6: 4510 | AK6: N | AP6: N | AQ6: D | AS6: 주선 | AT6: N | AV6: 0 | AX6: N | AY6: 1011 | AZ6: ㈜이엘에스솔루션 | BC6: 수출 | BD6: 반제품 | BE6: 운송료 | BI6: N | BK6: N | BM6: AAAAAAAAA | BN6: 컨테이너 미정의 | BP6: N | BQ6: AAA | BR6: 미정의 | BT6: N | BW6: __:__ | BY6: H000_GB | CK6: N | CQ6: N | CT6: N | CV6: 0 | CY6: 계열 | DA6: 02)17:33 | DB6: 02)17:33 | DH6: 0 | DN6: 0 | DO6: 0 | DP6: N | DS6: 박승기 | DV6: 컨테이너_수출 | DW6: 5010001 | DX6: 0
B7: 188 | E7: W260602-00000421 | F7: X260602-001958 | G7: Y260602-001958 | H7: 배정 | I7: 미생성 | J7: 수출 | K7: 46177 | L7: 19:00 | M7: D713CJ044 | N7: D713CJ044 | O7: MAE | P7: 머스크 | S7: USMOB | T7: [GB]아산 2포장장 (오토쎌) | U7: HMMA | V7: 미배정 | W7: 현대글로비스주식회사 | Y7: 4510 | AK7: N | AP7: N | AQ7: D | AS7: 주선 | AT7: N | AV7: 0 | AX7: N | AY7: 1011 | AZ7: ㈜이엘에스솔루션 | BC7: 수출 | BD7: 반제품 | BE7: 운송료 | BI7: N | BK7: N | BM7: AAAAAAAAA | BN7: 컨테이너 미정의 | BP7: N | BQ7: AAA | BR7: 미정의 | BT7: N | BW7: __:__ | BY7: H000_GB | CK7: N | CQ7: N | CT7: N | CV7: 0 | CY7: 계열 | DA7: 02)16:51 | DB7: 02)16:51 | DH7: 0 | DN7: 0 | DO7: 0 | DP7: N | DS7: 박승기 | DV7: 컨테이너_수출 | DW7: 5010001 | DX7: 0
B8: 187 | E8: W260602-00000417 | F8: X260602-001962 | G8: Y260602-001962 | H8: 배정 | I8: 미생성 | J8: 수출 | K8: 46177 | L8: 15:00 | M8: SELG82813400 | N8: SELG82813400 | O8: ONE | P8: 오션네트워크익스프레스 | S8: USLAX | T8: [GB]아산 2포장장 (오토쎌) | U8: HMMA | V8: 셔틀 | W8: 현대글로비스주식회사 | Y8: 4510 | AK8: N | AP8: N | AQ8: D | AS8: 주선 | AT8: N | AV8: 0 | AX8: N | AY8: 1011 | AZ8: ㈜이엘에스솔루션 | BC8: 수출 | BD8: 반제품 | BE8: 운송료 | BI8: N | BK8: N | BM8: AAAAAAAAA | BN8: 컨테이너 미정의 | BP8: N | BQ8: AAA | BR8: 미정의 | BT8: N | BW8: __:__ | BY8: H000_GB | CK8: N | CQ8: N | CT8: N | CV8: 0 | CY8: 계열 | DA8: 02)16:51 | DB8: 02)16:51 | DH8: 0 | DN8: 0 | DO8: 0 | DP8: N | DS8: 박승기 | DV8: 컨테이너_수출 | DW8: 5010001 | DX8: 0
B9: 186 | E9: W260602-00000416 | F9: X260602-001963 | G9: Y260602-001963 | H9: 배정 | I9: 미생성 | J9: 수출 | K9: 46177 | L9: 09:00 | M9: D713CJ044 | N9: D713CJ044 | O9: MAE | P9: 머스크 | S9: USLAX | T9: [GB]아산 2포장장 (오토쎌) | U9: KAGA | V9: 이지 | W9: 현대글로비스주식회사 | Y9: 4510 | AK9: N | AP9: N | AQ9: D | AS9: 주선 | AT9: N | AV9: 0 | AX9: N | AY9: 1011 | AZ9: ㈜이엘에스솔루션 | BC9: 수출 | BD9: 반제품 | BE9: 운송료 | BI9: N | BK9: N | BM9: AAAAAAAAA | BN9: 컨테이너 미정의 | BP9: N | BQ9: AAA | BR9: 미정의 | BT9: N | BW9: __:__ | BY9: H000_GB | CK9: N | CQ9: N | CT9: N | CV9: 0 | CY9: 계열 | DA9: 02)16:51 | DB9: 02)16:51 | DH9: 0 | DN9: 0 | DO9: 0 | DP9: N | DS9: 박승기 | DV9: 컨테이너_수출 | DW9: 5010001 | DX9: 0
B10: 185 | E10: W260602-00000415 | F10: X260602-001964 | G10: Y260602-001964 | H10: 배정 | I10: 미생성 | J10: 수출 | K10: 46177 | L10: 11:00 | M10: D713CJ044 | N10: D713CJ044 | O10: MAE | P10: 머스크 | S10: USLAX | T10: [GB]아산 2포장장 (오토쎌) | U10: KAGA | V10: 셔틀 | W10: 현대글로비스주식회사 | Y10: 4510 | AK10: N | AP10: N | AQ10: D | AS10: 주선 | AT10: N | AV10: 0 | AX10: N | AY10: 1011 | AZ10: ㈜이엘에스솔루션 | BC10: 수출 | BD10: 반제품 | BE10: 운송료 | BI10: N | BK10: N | BM10: AAAAAAAAA | BN10: 컨테이너 미정의 | BP10: N | BQ10: AAA | BR10: 미정의 | BT10: N | BW10: __:__ | BY10: H000_GB | CK10: N | CQ10: N | CT10: N | CV10: 0 | CY10: 계열 | DA10: 02)16:51 | DB10: 02)16:51 | DH10: 0 | DN10: 0 | DO10: 0 | DP10: N | DS10: 박승기 | DV10: 컨테이너_수출 | DW10: 5010001 | DX10: 0
B11: 184 | E11: W260602-00000414 | F11: X260602-001965 | G11: Y260602-001965 | H11: 배정 | I11: 미생성 | J11: 수출 | K11: 46177 | L11: 16:00 | M11: 005GX17204 | N11: 005GX17204 | O11: WHL | P11: Wanhai라인 | S11: INKAT | T11: [GB]아산 2포장장 (오토쎌) | U11: HMI/HMI PUNE | V11: 대신 | W11: 현대글로비스주식회사 | Y11: 4510 | AK11: N | AP11: N | AQ11: D | AS11: 주선 | AT11: N | AV11: 0 | AX11: N | AY11: 1011 | AZ11: ㈜이엘에스솔루션 | BC11: 수출 | BD11: 반제품 | BE11: 운송료 | BI11: N | BK11: N | BM11: GLC00263 | BN11: 부산신항 [GB]아산 2포장장 부산신항 | BO11: 0 | BP11: N | BQ11: KRBNP | BR11: 부산신항 | BT11: N | BW11: __:__ | BY11: H000_GB | CK11: N | CQ11: N | CT11: N | CV11: 0 | CY11: 계열 | DA11: 02)16:51 | DB11: 02)16:51 | DH11: 1023500 | DN11: 0 | DO11: 0 | DP11: N | DS11: 박승기 | DV11: 컨테이너_수출 | DW11: 5010001 | DX11: 0
B12: 183 | E12: W260602-00000413 | F12: X260602-001966 | G12: Y260602-001966 | H12: 배차확정 | I12: 미생성 | J12: 수출 | K12: 46177 | L12: 08:00 | M12: 005GX17204 | N12: 005GX17204 | O12: WHL | P12: Wanhai라인 | S12: INKAT | T12: [GB]아산 2포장장 (오토쎌) | U12: KIN | V12: 자차 | W12: 현대글로비스주식회사 | X12: WHSU6549777 | Y12: 4510 | Z12: WHA3168605 | AA12: 보기 | AB12: 부산99바7157 | AC12: 현우진 | AD12: 01062228360 | AE12: DSDS7157 | AK12: N | AP12: N | AQ12: D | AS12: 주선 | AT12: N | AV12: 0 | AX12: N | AY12: 1011 | AZ12: ㈜이엘에스솔루션 | BC12: 수출 | BD12: 반제품 | BE12: 운송료 | BF12: N | BI12: N | BK12: N | BM12: GLC00263 | BN12: 부산신항 [GB]아산 2포장장 부산신항 | BO12: 0 | BP12: N | BQ12: KRBNP | BR12: 부산신항 | BT12: N | BW12: __:__ | BX12: 2026-06-02 17:21:28 | BY12: H000_GB | CK12: N | CQ12: N | CT12: N | CV12: 0 | CY12: 계열 | DA12: 02)16:51 | DB12: 02)16:51 | DC12: 02)16:55 | DH12: 1023500 | DN12: 0 | DO12: 0 | DP12: N | DS12: 박승기 | DV12: 컨테이너_수출 | DW12: 5010001 | DX12: 0
B13: 182 | E13: W260602-00000412 | F13: X260602-001967 | G13: Y260602-001967 | H13: 배차확정 | I13: 미생성 | J13: 수출 | K13: 46177 | L13: 09:00 | M13: 005GX17204 | N13: 005GX17204 | O13: WHL | P13: Wanhai라인 | S13: INKAT | T13: [GB]아산 2포장장 (오토쎌) | U13: KIN | V13: 자차 | W13: 현대글로비스주식회사 | X13: WHSU5174357 | Y13: 4510 | Z13: WHA3168615 | AA13: 보기 | AB13: 경북98사1145 | AC13: 김현수 | AD13: 01074705405 | AE13: KDBE1145 | AK13: N | AP13: N | AQ13: D | AS13: 주선 | AT13: N | AV13: 0 | AX13: N | AY13: 1011 | AZ13: ㈜이엘에스솔루션 | BC13: 수출 | BD13: 반제품 | BE13: 운송료 | BF13: N | BI13: N | BK13: N | BM13: GLC00263 | BN13: 부산신항 [GB]아산 2포장장 부산신항 | BO13: 0 | BP13: N | BQ13: KRBNP | BR13: 부산신항 | BT13: N | BW13: __:__ | BX13: 2026-06-02 17:17:11 | BY13: H000_GB | CK13: N | CQ13: N | CT13: N | CV13: 0 | CY13: 계열 | DA13: 02)16:51 | DB13: 02)16:51 | DC13: 02)16:55 | DH13: 1023500 | DN13: 0 | DO13: 0 | DP13: N | DS13: 박승기 | DV13: 컨테이너_수출 | DW13: 5010001 | DX13: 0
B14: 181 | E14: W260602-00000411 | F14: X260602-001968 | G14: Y260602-001968 | H14: 배정 | I14: 미생성 | J14: 수출 | K14: 46177 | L14: 10:00 | M14: 005GX17204 | N14: 005GX17204 | O14: WHL | P14: Wanhai라인 | S14: INKAT | T14: [GB]아산 2포장장 (오토쎌) | U14: KIN | V14: 칸 | W14: 현대글로비스주식회사 | Y14: 4510 | AK14: N | AP14: N | AQ14: D | AS14: 주선 | AT14: N | AV14: 0 | AX14: N | AY14: 1011 | AZ14: ㈜이엘에스솔루션 | BC14: 수출 | BD14: 반제품 | BE14: 운송료 | BI14: N | BK14: N | BM14: GLC00263 | BN14: 부산신항 [GB]아산 2포장장 부산신항 | BO14: 0 | BP14: N | BQ14: KRBNP | BR14: 부산신항 | BT14: N | BW14: __:__ | BY14: H000_GB | CK14: N | CQ14: N | CT14: N | CV14: 0 | CY14: 계열 | DA14: 02)16:51 | DB14: 02)16:51 | DH14: 1023500 | DN14: 0 | DO14: 0 | DP14: N | DS14: 박승기 | DV14: 컨테이너_수출 | DW14: 5010001 | DX14: 0
B15: 180 | E15: W260602-00000410 | F15: X260602-001969 | G15: Y260602-001969 | H15: 배정 | I15: 미생성 | J15: 수출 | K15: 46177 | L15: 16:00 | M15: 005GX17204 | N15: 005GX17204 | O15: WHL | P15: Wanhai라인 | S15: INKAT | T15: [GB]아산 2포장장 (오토쎌) | U15: KIN | V15: 신승 | W15: 현대글로비스주식회사 | Y15: 4510 | AK15: N | AP15: N | AQ15: D | AS15: 주선 | AT15: N | AV15: 0 | AX15: N | AY15: 1011 | AZ15: ㈜이엘에스솔루션 | BC15: 수출 | BD15: 반제품 | BE15: 운송료 | BI15: N | BK15: N | BM15: GLC00263 | BN15: 부산신항 [GB]아산 2포장장 부산신항 | BO15: 0 | BP15: N | BQ15: KRBNP | BR15: 부산신항 | BT15: N | BW15: __:__ | BY15: H000_GB | CK15: N | CQ15: N | CT15: N | CV15: 0 | CY15: 계열 | DA15: 02)16:51 | DB15: 02)16:51 | DH15: 1023500 | DN15: 0 | DO15: 0 | DP15: N | DS15: 박승기 | DV15: 컨테이너_수출 | DW15: 5010001 | DX15: 0
